Workbook

Sheet AD
B1: AÇILIŞ DENETİMİ | I1: ANA MENÜYE DÖNÜŞ | Q1: ANA MENÜYE DÖNÜŞ | X1: ANA MENÜYE DÖNÜŞ | AE1: ANA MENÜYE DÖNÜŞ | AL1: ANA MENÜYE DÖNÜŞ | AS1: ANA MENÜYE DÖNÜŞ | AZ1: ANA MENÜYE DÖNÜŞ | BG1: ANA MENÜYE DÖNÜŞ | BN1: ANA MENÜYE DÖNÜŞ
B2: AÇIKLAMA | D2: Perşembe | E2: Cuma | F2: Cumartesi | G2: Pazar | H2: Pazartesi | I2: Salı | J2: Çarşamba | K2: Perşembe | L2: Cuma | M2: Cumartesi | N2: Pazar | O2: Pazartesi | P2: Salı | Q2: Çarşamba | R2: Perşembe | S2: Cuma | T2: Cumartesi | U2: Pazar | V2: Pazartesi | W2: Salı | X2: Çarşamba | Y2: Perşembe | Z2: Cuma | AA2: Cumartesi | AB2: Pazar | AC2: Pazartesi | AD2: Salı | AE2: Çarşamba | AF2: Perşembe | AG2: Cuma | AH2: Cumartesi | AI2: Pazar | AJ2: Pazartesi | AK2: Salı | AL2: Çarşamba | AM2: Perşembe | AN2: Cuma | AO2: Cumartesi | AP2: Pazar | AQ2: Pazartesi | AR2: Salı | AS2: Çarşamba | AT2: Perşembe | AU2: Cuma | AV2: Cumartesi | AW2: Pazar | AX2: Pazartesi | AY2: Salı | AZ2: Çarşamba | BA2: Perşembe | BB2: Cuma | BC2: Cumartesi | BD2: Pazar | BE2: Pazartesi | BF2: Salı | BG2: Çarşamba | BH2: Perşembe | BI2: Cuma | BJ2: Cumartesi | BK2: Pazar | BL2: Pazartesi | BM2: Salı | BN2: Çarşamba | BO2: Perşembe | BP2: Cuma | BQ2: Cumartesi | BR2: Pazar | BS2: Pazartesi | BT2: Salı | BU2: Çarşamba | BV2: Perşembe | BW2: Cuma | BX2: Cumartesi | BY2: Pazar | BZ2: Pazartesi | CA2: Salı | CB2: Çarşamba | CC2: Perşembe | CD2: Cuma | CE2: Cumartesi | CF2: Pazar | CG2: Pazartesi | CH2: Salı | CI2: Çarşamba | CJ2: Perşembe | CK2: Cuma | CL2: Cumartesi | CM2: Pazar | CN2: Pazartesi | CO2: Salı | CP2: Çarşamba | CQ2: Perşembe | CR2: Cuma | CS2: Cumartesi | CT2: Pazar | CU2: Pazartesi | CV2: Salı | CW2: Çarşamba | CX2: Perşembe | CY2: Cuma | CZ2: Cumartesi | DA2: Pazar | DB2: Pazartesi | DC2: Salı | DD2: Çarşamba | DE2: Perşembe | DF2: Cuma | DG2: Cumartesi | DH2: Pazar | DI2: Pazartesi | DJ2: Salı | DK2: Çarşamba | DL2: Perşembe | DM2: Cuma | DN2: Cumartesi | DO2: Pazar | DP2: Pazartesi | DQ2: Salı | DR2: Çarşamba | DS2: Perşembe | DT2: Cuma | DU2: Cumartesi | DV2: Pazar | DW2: Pazartesi | DX2: Salı | DY2: Çarşamba | DZ2: Perşembe | EA2: Cuma | EB2: Cumartesi | EC2: Pazar | ED2: Pazartesi | EE2: Salı | EF2: Çarşamba | EG2: Perşembe | EH2: Cuma | EI2: Cumartesi | EJ2: Pazar | EK2: Pazartesi | EL2: Salı | EM2: Çarşamba | EN2: Perşembe | EO2: Cuma | EP2: Cumartesi | EQ2: Pazar | ER2: Pazartesi | ES2: Salı | ET2: Çarşamba | EU2: Perşembe | EV2: Cuma | EW2: Cumartesi | EX2: Pazar | EY2: Pazartesi | EZ2: Salı | FA2: Çarşamba | FB2: Perşembe | FC2: Cuma | FD2: Cumartesi | FE2: Pazar | FF2: Pazartesi | FG2: Salı | FH2: Çarşamba | FI2: Perşembe | FJ2: Cuma | FK2: Cumartesi | FL2: Pazar | FM2: Pazartesi | FN2: Salı | FO2: Çarşamba | FP2: Perşembe | FQ2: Cuma | FR2: Cumartesi | FS2: Pazar | FT2: Pazartesi | FU2: Salı | FV2: Çarşamba | FW2: Perşembe | FX2: Cuma | FY2: Cumartesi | FZ2: Pazar | GA2: Pazartesi | GB2: Salı | GC2: Çarşamba | GD2: Perşembe | GE2: Cuma | GF2: Cumartesi | GG2: Pazar | GH2: Pazartesi | GI2: Salı
D3: 39814 | E3: 39815 | F3: 39816 | G3: 39817 | H3: 39818 | I3: 39819 | J3: 39820 | K3: 39821 | L3: 39822 | M3: 39823 | N3: 39824 | O3: 39825 | P3: 39826 | Q3: 39827 | R3: 39828 | S3: 39829 | T3: 39830 | U3: 39831 | V3: 39832 | W3: 39833 | X3: 39834 | Y3: 39835 | Z3: 39836 | AA3: 39837 | AB3: 39838 | AC3: 39839 | AD3: 39840 | AE3: 39841 | AF3: 39842 | AG3: 39843 | AH3: 39844 | AI3: 39845 | AJ3: 39846 | AK3: 39847 | AL3: 39848 | AM3: 39849 | AN3: 39850 | AO3: 39851 | AP3: 39852 | AQ3: 39853 | AR3: 39854 | AS3: 39855 | AT3: 39856 | AU3: 39857 | AV3: 39858 | AW3: 39859 | AX3: 39860 | AY3: 39861 | AZ3: 39862 | BA3: 39863 | BB3: 39864 | BC3: 39865 | BD3: 39866 | BE3: 39867 | BF3: 39868 | BG3: 39869 | BH3: 39870 | BI3: 39871 | BJ3: 39872 | BK3: 39873 | BL3: 39874 | BM3: 39875 | BN3: 39876 | BO3: 39877 | BP3: 39878 | BQ3: 39879 | BR3: 39880 | BS3: 39881 | BT3: 39882 | BU3: 39883 | BV3: 39884 | BW3: 39885 | BX3: 39886 | BY3: 39887 | BZ3: 39888 | CA3: 39889 | CB3: 39890 | CC3: 39891 | CD3: 39892 | CE3: 39893 | CF3: 39894 | CG3: 39895 | CH3: 39896 | CI3: 39897 | CJ3: 39898 | CK3: 39899 | CL3: 39900 | CM3: 39901 | CN3: 39902 | CO3: 39903 | CP3: 39904 | CQ3: 39905 | CR3: 39906 | CS3: 39907 | CT3: 39908 | CU3: 39909 | CV3: 39910 | CW3: 39911 | CX3: 39912 | CY3: 39913 | CZ3: 39914 | DA3: 39915 | DB3: 39916 | DC3: 39917 | DD3: 39918 | DE3: 39919 | DF3: 39920 | DG3: 39921 | DH3: 39922 | DI3: 39923 | DJ3: 39924 | DK3: 39925 | DL3: 39926 | DM3: 39927 | DN3: 39928 | DO3: 39929 | DP3: 39930 | DQ3: 39931 | DR3: 39932 | DS3: 39933 | DT3: 39934 | DU3: 39935 | DV3: 39936 | DW3: 39937 | DX3: 39938 | DY3: 39939 | DZ3: 39940 | EA3: 39941 | EB3: 39942 | EC3: 39943 | ED3: 39944 | EE3: 39945 | EF3: 39946 | EG3: 39947 | EH3: 39948 | EI3: 39949 | EJ3: 39950 | EK3: 39951 | EL3: 39952 | EM3: 39953 | EN3: 39954 | EO3: 39955 | EP3: 39956 | EQ3: 39957 | ER3: 39958 | ES3: 39959 | ET3: 39960 | EU3: 39961 | EV3: 39962 | EW3: 39963 | EX3: 39964 | EY3: 39965 | EZ3: 39966 | FA3: 39967 | FB3: 39968 | FC3: 39969 | FD3: 39970 | FE3: 39971 | FF3: 39972 | FG3: 39973 | FH3: 39974 | FI3: 39975 | FJ3: 39976 | FK3: 39977 | FL3: 39978 | FM3: 39979 | FN3: 39980 | FO3: 39981 | FP3: 39982 | FQ3: 39983 | FR3: 39984 | FS3: 39985 | FT3: 39986 | FU3: 39987 | FV3: 39988 | FW3: 39989 | FX3: 39990 | FY3: 39991 | FZ3: 39992 | GA3: 39993 | GB3: 39994 | GC3: 39995 | GD3: 39996 | GE3: 39997 | GF3: 39998 | GG3: 39999 | GH3: 40000 | GI3: 40001
A4: 2009 | B4: MULTIMEDYA | C4: MULTİMEDYA RAFLARI
C5: Koleksiyon Yerleştirme | E5: OK | F5: OK | G5: OK | H5: OK | I5: OK | J5: OK | K5: OK | L5: OK | N5: OK | O5: OK | P5: OK | Q5: OK | R5: OK | S5: OK | T5: OK | U5: OK | V5: OK | W5: OK | X5: OK | Y5: OK | Z5: OK | AC5: SORUN | AD5: OK | AE5: OK | AF5: OK | AG5: OK | AJ5: OK | AK5: OK | AL5: OK | AM5: OK | AN5: OK | AQ5: OK | AR5: OK | AS5: OK | AT5: OK | AU5: OK | AX5: OK | AY5: OK | AZ5: OK | BA5: OK | BB5: OK | BC5: OK | BD5: OK | BE5: OK | BF5: OK | BG5: OK | BH5: OK | BI5: OK | BK5: OK | BL5: OK | BM5: OK | BN5: OK | BO5: OK | BP5: OK | BR5: OK | BS5: OK | BT5: OK | BU5: OK | BV5: OK | BW5: OK | BY5: OK | BZ5: OK | CA5: OK | CB5: OK | CC5: OK | CD5: OK | CF5: OK | CG5: OK | CH5: OK | CI5: OK | CJ5: OK | CK5: OK | CL5: OK | CM5: OK | CN5: OK | CO5: OK | CP5: OK | CQ5: OK | CR5: OK | CT5: OK | CU5: OK | CV5: OK | CW5: OK | CX5: OK | CY5: OK | DA5: OK | DB5: OK | DC5: OK | DD5: OK | DE5: OK | DF5: OK | DG5: OK | DI5: OK | DJ5: OK | DK5: OK | DL5: 23 Nısan - Tatil | DM5: OK | DN5: OK | DP5: OK | DQ5: OK | DR5: OK | DS5: OK | DT5: 1 Mayıs - Tatil | DV5: OK | DW5: OK | DX5: OK | DY5: OK | DZ5: OK | EA5: OK | EB5: OK | EC5: OK | ED5: OK | EE5: OK | EF5: OK | EG5: OK | EH5: OK | EJ5: OK | EK5: OK | EM5: OK | EN5: OK | EO5: OK | EP5: OK | EQ5: OK | ER5: OK | ES5: OK | ET5: OK | EU5: OK | EV5: OK | EW5: OK | EX5: OK | EY5: OK | EZ5: OK | FA5: OK | FB5: OK | FC5: OK | FD5: OK | FE5: OK | FF5: OK | FG5: OK | FH5: OK | FI5: OK | FJ5: OK | FK5: OK | FM5: OK | FN5: OK | FO5: OK | FP5: OK | FQ5: OK | FT5: OK | FU5: OK | FV5: OK | FW5: OK | FX5: OK | GA5: OK | GB5: OK | GC5: OK | GD5: OK | GE5: OK | GH5: OK | GI5: OK
C6: Koleksiyon Düzen | E6: OK | F6: OK | G6: OK | H6: OK | I6: OK | J6: OK | K6: OK | L6: OK | N6: OK | O6: OK | P6: OK | Q6: OK | R6: OK | S6: OK | T6: OK | U6: OK | V6: OK | W6: OK | X6: OK | Y6: OK | Z6: OK | AC6: OK | AD6: OK | AE6: OK | AF6: OK | AG6: OK | AJ6: OK | AK6: OK | AL6: OK | AM6: OK | AN6: OK | AQ6: OK | AR6: OK | AS6: OK | AT6: OK | AU6: OK | AX6: OK | AY6: OK | AZ6: OK | BA6: OK | BB6: OK | BC6: OK | BD6: OK | BE6: OK | BF6: OK | BG6: OK | BH6: OK | BI6: OK | BK6: OK | BL6: OK | BM6: OK | BN6: OK | BO6: OK | BP6: OK | BR6: OK | BS6: OK | BT6: OK | BU6: OK | BV6: OK | BW6: OK | BY6: OK | BZ6: OK | CA6: OK | CB6: OK | CC6: OK | CD6: OK | CF6: OK | CG6: OK | CH6: OK | CI6: OK | CJ6: OK | CK6: OK | CL6: OK | CM6: OK | CN6: OK | CO6: OK | CP6: OK | CQ6: OK | CR6: OK | CT6: OK | CU6: OK | CV6: OK | CW6: OK | CX6: OK | CY6: OK | DA6: OK | DB6: OK | DC6: OK | DD6: OK | DE6: OK | DF6: OK | DG6: OK | DI6: OK | DJ6: OK | DK6: OK | DM6: OK | DN6: OK | DP6: OK | DQ6: OK | DR6: OK | DS6: OK | DV6: OK | DW6: OK | DX6: OK | DY6: OK | DZ6: OK | EA6: OK | EB6: OK | EC6: OK | ED6: OK | EE6: OK | EF6: OK | EG6: OK | EH6: OK | EJ6: OK | EK6: OK | EM6: OK | EN6: OK | EO6: OK | EP6: OK | EQ6: OK | ER6: OK | ES6: OK | ET6: OK | EU6: OK | EV6: OK | EW6: OK | EX6: OK | EY6: OK | EZ6: OK | FA6: OK | FB6: OK | FC6: OK | FD6: OK | FE6: OK | FF6: OK | FG6: OK | FH6: OK | FI6: OK | FJ6: OK | FK6: OK | FM6: OK | FN6: OK | FO6: OK | FP6: OK | FQ6: OK | FT6: OK | FU6: OK | FV6: OK | FW6: OK | FX6: OK | GA6: OK | GB6: OK | GC6: OK | GD6: OK | GE6: OK | GH6: OK | GI6: OK
C7: Koleksiyon Okunma | E7: OK | F7: OK | G7: OK | H7: OK | I7: OK | J7: OK | K7: OK | L7: OK | N7: OK | O7: OK | P7: OK | Q7: OK | R7: OK | S7: OK | T7: OK | U7: OK | V7: OK | W7: OK | X7: OK | Y7: OK | Z7: OK | AC7: OK | AD7: OK | AE7: OK | AF7: OK | AG7: OK | AJ7: OK | AK7: OK | AL7: OK | AM7: OK | AN7: OK | AQ7: OK | AR7: OK | AS7: OK | AT7: OK | AU7: OK | AX7: OK | AY7: OK | AZ7: OK | BA7: OK | BB7: OK | BC7: OK | BD7: OK | BE7: OK | BF7: OK | BG7: OK | BH7: OK | BI7: OK | BK7: OK | BL7: OK | BM7: OK | BN7: OK | BO7: OK | BP7: OK | BR7: OK | BS7: OK | BT7: OK | BU7: OK | BV7: OK | BW7: OK | BY7: OK | BZ7: OK | CA7: OK | CB7: OK | CC7: OK | CD7: OK | CF7: OK | CG7: OK | CH7: OK | CI7: OK | CJ7: OK | CK7: OK | CL7: OK | CM7: OK | CN7: OK | CO7: OK | CP7: OK | CQ7: OK | CR7: OK | CT7: OK | CU7: OK | CV7: OK | CW7: OK | CX7: OK | CY7: OK | DA7: OK | DB7: OK | DC7: OK | DD7: OK | DE7: OK | DF7: OK | DG7: OK | DI7: OK | DJ7: OK | DK7: OK | DM7: OK | DN7: OK | DP7: OK | DQ7: OK | DR7: OK | DS7: OK | DV7: OK | DW7: OK | DX7: OK | DY7: OK | DZ7: OK | EA7: OK | EB7: OK | EC7: OK | ED7: OK | EE7: OK | EF7: OK | EG7: OK | EH7: OK | EJ7: OK | EK7: OK | EM7: OK | EN7: OK | EO7: OK | EP7: OK | EQ7: OK | ER7: OK | ES7: OK | ET7: OK | EU7: OK | EV7: OK | EW7: OK | EX7: OK | EY7: OK | EZ7: OK | FA7: OK | FB7: OK | FC7: OK | FD7: OK | FE7: OK | FF7: OK | FG7: OK | FH7: OK | FI7: OK | FJ7: OK | FK7: OK | FM7: OK | FN7: OK | FO7: OK | FP7: OK | FQ7: OK | FT7: OK | FU7: OK | FV7: OK | FW7: OK | FX7: OK | GA7: OK | GB7: OK | GC7: OK | GD7: OK | GE7: OK | GH7: OK | GI7: OK
C8: Odalar ve Kareller | E8: OK | F8: OK | G8: OK | H8: OK | I8: OK | J8: OK | K8: SORUN | L8: OK | N8: OK | O8: OK | P8: OK | Q8: OK | R8: OK | S8: OK | T8: OK | U8: SORUN | V8: OK | W8: OK | X8: SORUN | Y8: OK | Z8: OK | AC8: OK | AD8: OK | AE8: OK | AF8: OK | AG8: OK | AJ8: OK | AK8: OK | AL8: OK | AM8: OK | AN8: OK | AQ8: OK | AR8: OK | AS8: OK | AT8: OK | AU8: OK | AX8: OK | AY8: OK | AZ8: OK | BA8: OK | BB8: OK | BC8: OK | BD8: OK | BE8: OK | BF8: OK | BG8: OK | BH8: OK | BI8: OK | BK8: OK | BL8: OK | BM8: OK | BN8: OK | BO8: OK | BP8: OK | BR8: OK | BS8: OK | BT8: OK | BU8: OK | BV8: OK | BW8: OK | BY8: OK | BZ8: OK | CA8: OK | CB8: OK | CC8: OK | CD8: OK | CF8: OK | CG8: OK | CH8: OK | CI8: OK | CJ8: OK | CK8: OK | CL8: OK | CM8: OK | CN8: OK | CO8: OK | CP8: OK | CQ8: OK | CR8: OK | CT8: OK | CU8: OK | CV8: OK | CW8: OK | CX8: OK | CY8: OK | DA8: OK | DB8: OK | DC8: OK | DD8: OK | DE8: OK | DF8: OK | DG8: OK | DI8: OK | DJ8: OK | DK8: OK | DM8: OK | DN8: OK | DP8: OK | DQ8: OK | DR8: OK | DS8: OK | DV8: OK | DW8: OK | DX8: OK | DY8: OK | DZ8: OK | EA8: OK | EB8: OK | EC8: OK | ED8: OK | EE8: OK | EF8: OK | EG8: OK | EH8: OK | EJ8: OK | EK8: OK | EM8: OK | EN8: OK | EO8: OK | EP8: OK | EQ8: OK | ER8: OK | ES8: OK | ET8: OK | EU8: OK | EV8: OK | EW8: OK | EX8: OK | EY8: OK | EZ8: OK | FA8: OK | FB8: OK | FC8: OK | FD8: OK | FE8: OK | FF8: OK | FG8: OK | FH8: OK | FI8: OK | FJ8: OK | FK8: OK | FM8: OK | FN8: OK | FO8: OK | FP8: OK | FQ8: OK | FT8: OK | FU8: OK | FV8: OK | FW8: OK | FX8: OK | GA8: OK | GB8: OK | GC8: OK | GD8: OK | GE8: OK | GH8: OK | GI8: OK
C9: Ekipmanlar tam ve çalışır durumda mı? | E9: OK | F9: OK | G9: OK | H9: OK | I9: OK | J9: OK | K9: OK | L9: OK | N9: OK | O9: OK | P9: OK | Q9: OK | R9: OK | S9: OK | T9: OK | U9: OK | V9: OK | W9: OK | X9: OK | Y9: OK | Z9: OK | AC9: OK | AD9: OK | AE9: OK | AF9: OK | AG9: OK | AJ9: OK | AK9: OK | AL9: OK | AM9: OK | AN9: OK | AQ9: OK | AR9: OK | AS9: OK | AT9: OK | AU9: OK | AX9: OK | AY9: OK | AZ9: OK | BA9: OK | BB9: OK | BC9: OK | BD9: OK | BE9: OK | BF9: OK | BG9: OK | BH9: OK | BI9: OK | BK9: OK | BL9: OK | BM9: OK | BN9: OK | BO9: OK | BP9: OK | BR9: OK | BS9: OK | BT9: OK | BU9: OK | BV9: OK | BW9: OK | BY9: OK | BZ9: OK | CA9: OK | CB9: OK | CC9: OK | CD9: OK | CF9: OK | CG9: OK | CH9: OK | CI9: OK | CJ9: OK | CK9: OK | CL9: OK | CM9: OK | CN9: OK | CO9: OK | CP9: OK | CQ9: OK | CR9: OK | CT9: OK | CU9: OK | CV9: OK | CW9: OK | CX9: OK | CY9: OK | DA9: OK | DB9: OK | DC9: OK | DD9: OK | DE9: OK | DF9: OK | DG9: OK | DI9: OK | DJ9: OK | DK9: OK | DM9: OK | DN9: OK | DP9: OK | DQ9: OK | DR9: OK | DS9: OK | DV9: OK | DW9: OK | DX9: OK | DY9: OK | DZ9: OK | EA9: OK | EB9: OK | EC9: OK | ED9: OK | EE9: OK | EF9: OK | EG9: OK | EH9: OK | EJ9: OK | EK9: OK | EM9: OK | EN9: OK | EO9: OK | EP9: OK | EQ9: OK | ER9: OK | ES9: OK | ET9: OK | EU9: OK | EV9: OK | EW9: OK | EX9: OK | EY9: OK | EZ9: OK | FA9: OK | FB9: OK | FC9: OK | FD9: OK | FE9: OK | FF9: OK | FG9: OK | FH9: OK | FI9: OK | FJ9: OK | FK9: OK | FM9: OK | FN9: OK | FO9: OK | FP9: OK | FQ9: OK | FT9: OK | FU9: OK | FV9: OK | FW9: OK | FX9: OK | GA9: OK | GB9: OK | GC9: OK | GD9: OK | GE9: OK | GH9: OK | GI9: OK
C10: Koltuk ve sandalyeler olması gereken yerlerde mi? | E10: OK | F10: OK | G10: OK | H10: OK | I10: OK | J10: OK | K10: OK | L10: OK | N10: OK | O10: OK | P10: OK | Q10: OK | R10: OK | S10: OK | T10: OK | U10: OK | V10: OK | W10: OK | X10: OK | Y10: OK | Z10: OK | AC10: OK | AD10: OK | AE10: OK | AF10: OK | AG10: OK | AJ10: OK | AK10: OK | AL10: OK | AM10: OK | AN10: OK | AQ10: OK | AR10: OK | AS10: OK | AT10: OK | AU10: OK | AX10: OK | AY10: OK | AZ10: OK | BA10: OK | BB10: OK | BC10: OK | BD10: OK | BE10: OK | BF10: OK | BG10: OK | BH10: OK | BI10: OK | BK10: OK | BL10: OK | BM10: OK | BN10: OK | BO10: OK | BP10: OK | BR10: OK | BS10: OK | BT10: OK | BU10: OK | BV10: OK | BW10: OK | BY10: OK | BZ10: OK | CA10: OK | CB10: OK | CC10: OK | CD10: OK | CF10: OK | CG10: OK | CH10: OK | CI10: OK | CJ10: OK | CK10: OK | CL10: OK | CM10: OK | CN10: OK | CO10: OK | CP10: OK | CQ10: OK | CR10: OK | CT10: OK | CU10: OK | CV10: OK | CW10: OK | CX10: OK | CY10: OK | DA10: OK | DB10: OK | DC10: OK | DD10: OK | DE10: OK | DF10: OK | DG10: OK | DI10: OK | DJ10: OK | DK10: OK | DM10: OK | DN10: OK | DP10: OK | DQ10: OK | DR10: OK | DS10: OK | DV10: OK | DW10: OK | DX10: OK | DY10: OK | DZ10: OK | EA10: OK | EB10: OK | EC10: OK | ED10: OK | EE10: OK | EF10: OK | EG10: OK | EH10: OK | EJ10: OK | EK10: OK | EM10: OK | EN10: OK | EO10: OK | EP10: OK | EQ10: OK | ER10: OK | ES10: OK | ET10: OK | EU10: OK | EV10: OK | EW10: OK | EX10: OK | EY10: OK | EZ10: OK | FA10: OK | FB10: OK | FC10: OK | FD10: OK | FE10: OK | FF10: OK | FG10: OK | FH10: OK | FI10: OK | FJ10: OK | FK10: OK | FM10: OK | FN10: OK | FO10: OK | FP10: OK | FQ10: OK | FT10: OK | FU10: OK | FV10: OK | FW10: OK | FX10: OK | GA10: OK | GB10: OK | GC10: OK | GD10: OK | GE10: OK | GH10: OK | GI10: OK
C11: Oda temizlenmiş mi? | E11: OK | F11: OK | G11: OK | H11: OK | I11: OK | J11: OK | K11: OK | L11: OK | N11: OK | O11: OK | P11: OK | Q11: OK | R11: OK | S11: OK | T11: OK | U11: OK | V11: OK | W11: OK | X11: OK | Y11: OK | Z11: OK | AC11: OK | AD11: OK | AE11: OK | AF11: OK | AG11: OK | AJ11: OK | AK11: OK | AL11: OK | AM11: OK | AN11: OK | AQ11: OK | AR11: OK | AS11: OK | AT11: OK | AU11: OK | AX11: OK | AY11: OK | AZ11: OK | BA11: OK | BB11: OK | BC11: OK | BD11: OK | BE11: OK | BF11: OK | BG11: OK | BH11: OK | BI11: OK | BK11: OK | BL11: OK | BM11: OK | BN11: OK | BO11: OK | BP11: OK | BR11: OK | BS11: OK | BT11: OK | BU11: OK | BV11: OK | BW11: OK | BY11: OK | BZ11: OK | CA11: OK | CB11: OK | CC11: OK | CD11: OK | CF11: OK | CG11: OK | CH11: OK | CI11: OK | CJ11: OK | CK11: OK | CL11: OK | CM11: OK | CN11: OK | CO11: OK | CP11: OK | CQ11: OK | CR11: OK | CT11: OK | CU11: OK | CV11: OK | CW11: OK | CX11: OK | CY11: OK | DA11: OK | DB11: OK | DC11: OK | DD11: OK | DE11: OK | DF11: OK | DG11: OK | DI11: OK | DJ11: OK | DK11: OK | DM11: OK | DN11: OK | DP11: OK | DQ11: OK | DR11: OK | DS11: OK | DV11: OK | DW11: OK | DX11: OK | DY11: OK | DZ11: OK | EA11: OK | EB11: OK | EC11: OK | ED11: OK | EE11: OK | EF11: OK | EG11: OK | EH11: OK | EJ11: OK | EK11: OK | EM11: OK | EN11: OK | EO11: OK | EP11: OK | EQ11: OK | ER11: OK | ES11: OK | ET11: OK | EU11: OK | EV11: OK | EW11: OK | EX11: OK | EY11: OK | EZ11: OK | FA11: OK | FB11: OK | FC11: OK | FD11: OK | FE11: OK | FF11: OK | FG11: OK | FH11: OK | FI11: OK | FJ11: OK | FK11: OK | FM11: OK | FN11: OK | FO11: OK | FP11: OK | FQ11: OK | FT11: OK | FU11: OK | FV11: OK | FW11: OK | FX11: OK | GA11: OK | GB11: OK | GC11: OK | GD11: OK | GE11: OK | GH11: OK | GI11: OK
C12: Aydınlatma | E12: OK | F12: OK | G12: OK | H12: OK | I12: OK | J12: OK | K12: OK | L12: OK | N12: OK | O12: OK | P12: OK | Q12: OK | R12: OK | S12: OK | T12: OK | U12: OK | V12: OK | W12: OK | X12: OK | Y12: OK | Z12: OK | AC12: OK | AD12: OK | AE12: OK | AF12: OK | AG12: OK | AJ12: OK | AK12: OK | AL12: OK | AM12: OK | AN12: OK | AQ12: OK | AR12: OK | AS12: OK | AT12: OK | AU12: OK | AX12: OK | AY12: OK | AZ12: OK | BA12: OK | BB12: OK | BC12: OK | BD12: OK | BE12: OK | BF12: OK | BG12: OK | BH12: OK | BI12: OK | BK12: OK | BL12: OK | BM12: OK | BN12: OK | BO12: OK | BP12: OK | BR12: OK | BS12: OK | BT12: OK | BU12: OK | BV12: OK | BW12: OK | BY12: OK | BZ12: OK | CA12: OK | CB12: OK | CC12: OK | CD12: OK | CF12: OK | CG12: OK | CH12: OK | CI12: OK | CJ12: OK | CK12: OK | CL12: OK | CM12: OK | CN12: OK | CO12: OK | CP12: OK | CQ12: OK | CR12: OK | CT12: OK | CU12: OK | CV12: OK | CW12: OK | CX12: OK | CY12: OK | DA12: OK | DB12: OK | DC12: OK | DD12: OK | DE12: OK | DF12: OK | DG12: OK | DI12: OK | DJ12: OK | DK12: OK | DM12: OK | DN12: OK | DP12: OK | DQ12: OK | DR12: OK | DS12: OK | DV12: OK | DW12: OK | DX12: OK | DY12: OK | DZ12: OK | EA12: OK | EB12: OK | EC12: OK | ED12: OK | EE12: OK | EF12: OK | EG12: OK | EH12: OK | EJ12: OK | EK12: OK | EM12: OK | EN12: OK | EO12: OK | EP12: OK | EQ12: OK | ER12: OK | ES12: OK | ET12: OK | EU12: OK | EV12: OK | EW12: OK | EX12: OK | EY12: OK | EZ12: OK | FA12: OK | FB12: OK | FC12: OK | FD12: OK | FE12: OK | FF12: OK | FG12: OK | FH12: OK | FI12: OK | FJ12: OK | FK12: OK | FM12: OK | FN12: OK | FO12: OK | FP12: OK | FQ12: OK | FT12: OK | FU12: OK | FV12: OK | FW12: OK | FX12: OK | GA12: OK | GB12: OK | GC12: OK | GD12: OK | GE12: OK | GH12: OK | GI12: OK
B13: BİNA | C13: GENEL KULLANIM ALANLARI
C14: Acil Çıkış Kapıları Güvenlik Plastik | E14: SORUN | F14: OK | G14: OK | H14: OK | I14: OK | J14: OK | K14: OK | L14: OK | N14: OK | O14: OK | P14: OK | Q14: OK | R14: OK | S14: OK | T14: OK | U14: OK | V14: OK | W14: OK | X14: OK | Y14: OK | Z14: OK | AC14: OK | AD14: OK | AE14: OK | AF14: OK | AG14: OK | AJ14: OK | AK14: OK | AL14: OK | AM14: OK | AN14: OK | AQ14: OK | AR14: OK | AS14: OK | AT14: OK | AU14: OK | AX14: OK | AY14: OK | AZ14: OK | BA14: OK | BB14: OK | BC14: OK | BD14: OK | BE14: OK | BF14: OK | BG14: OK | BH14: OK | BI14: OK | BK14: OK | BL14: OK | BM14: OK | BN14: OK | BO14: OK | BP14: OK | BR14: OK | BS14: OK | BT14: OK | BU14: OK | BV14: OK | BW14: OK | BY14: OK | BZ14: OK | CA14: OK | CB14: OK | CC14: OK | CD14: OK | CF14: OK | CG14: OK | CH14: OK | CI14: OK | CJ14: OK | CK14: OK | CL14: OK | CM14: OK | CN14: OK | CO14: OK | CP14: OK | CQ14: OK | CR14: OK | CT14: OK | CU14: OK | CV14: OK | CW14: OK | CX14: OK | CY14: OK | DA14: OK | DB14: OK | DC14: OK | DD14: OK | DE14: OK | DF14: OK | DG14: OK | DI14: OK | DJ14: OK | DK14: OK | DM14: OK | DN14: OK | DP14: OK | DQ14: OK | DR14: OK | DS14: OK | DV14: OK | DW14: OK | DX14: OK | DY14: OK | DZ14: OK | EA14: OK | EB14: OK | EC14: OK | ED14: OK | EE14: OK | EF14: OK | EG14: OK | EH14: OK | EJ14: OK | EK14: OK | EM14: OK | EN14: OK | EO14: OK | EP14: OK | EQ14: OK | ER14: OK | ES14: OK | ET14: OK | EU14: OK | EV14: OK | EW14: OK | EX14: OK | EY14: OK | EZ14: OK | FA14: OK | FB14: OK | FC14: OK | FD14: OK | FE14: OK | FF14: OK | FG14: OK | FH14: OK | FI14: OK | FJ14: OK | FK14: OK | FM14: OK | FN14: OK | FO14: OK | FP14: OK | FQ14: OK | FT14: OK | FU14: OK | FV14: OK | FW14: OK | FX14: OK | GA14: OK | GB14: OK | GC14: OK | GD14: OK | GE14: OK | GH14: OK | GI14: OK
C15: Genel Isıtma | E15: OK | F15: OK | G15: OK | H15: OK | I15: OK | J15: OK | K15: OK | L15: OK | N15: OK | O15: OK | P15: OK | Q15: OK | R15: OK | S15: OK | T15: OK | U15: OK | V15: OK | W15: OK | X15: OK | Y15: OK | Z15: OK | AC15: OK | AD15: OK | AE15: OK | AF15: OK | AG15: OK | AJ15: OK | AK15: OK | AL15: OK | AM15: OK | AN15: OK | AQ15: OK | AR15: OK | AS15: OK | AT15: OK | AU15: OK | AX15: OK | AY15: OK | AZ15: OK | BA15: OK | BB15: OK | BC15: OK | BD15: OK | BE15: OK | BF15: OK | BG15: OK | BH15: OK | BI15: OK | BK15: OK | BL15: OK | BM15: OK | BN15: OK | BO15: OK | BP15: OK | BR15: OK | BS15: OK | BT15: OK | BU15: OK | BV15: OK | BW15: OK | BY15: OK | BZ15: OK | CA15: OK | CB15: OK | CC15: OK | CD15: OK | CF15: OK | CG15: OK | CH15: OK | CI15: OK | CJ15: OK | CK15: OK | CL15: OK | CM15: OK | CN15: OK | CO15: OK | CP15: OK | CQ15: OK | CR15: OK | CT15: OK | CU15: OK | CV15: OK | CW15: OK | CX15: OK | CY15: OK | DA15: OK | DB15: OK | DC15: OK | DD15: OK | DE15: OK | DF15: OK | DG15: OK | DI15: OK | DJ15: OK | DK15: OK | DM15: OK | DN15: OK | DP15: OK | DQ15: OK | DR15: OK | DS15: OK | DV15: OK | DW15: OK | DX15: OK | DY15: OK | DZ15: OK | EA15: OK | EB15: OK | EC15: OK | ED15: OK | EE15: OK | EF15: OK | EG15: OK | EH15: OK | EJ15: OK | EK15: OK | EM15: OK | EN15: OK | EO15: OK | EP15: OK | EQ15: OK | ER15: OK | ES15: OK | ET15: OK | EU15: OK | EV15: OK | EW15: OK | EX15: OK | EY15: OK | EZ15: OK | FA15: OK | FB15: OK | FC15: OK | FD15: OK | FE15: OK | FF15: OK | FG15: OK | FH15: OK | FI15: OK | FJ15: OK | FK15: OK | FM15: OK | FN15: OK | FO15: OK | FP15: OK | FQ15: OK | FT15: OK | FU15: OK | FV15: OK | FW15: OK | FX15: OK | GA15: OK | GB15: OK | GC15: OK | GD15: OK | GE15: OK | GH15: OK | GI15: OK
C16: Genel Aydınlatma | E16: OK | F16: OK | G16: OK | H16: OK | I16: OK | J16: OK | K16: OK | L16: SORUN | N16: OK | O16: OK | P16: OK | Q16: OK | R16: OK | S16: OK | T16: OK | U16: OK | V16: OK | W16: OK | X16: OK | Y16: OK | Z16: OK | AC16: OK | AD16: OK | AE16: OK | AF16: OK | AG16: OK | AJ16: OK | AK16: OK | AL16: OK | AM16: OK | AN16: OK | AQ16: OK | AR16: OK | AS16: OK | AT16: OK | AU16: OK | AX16: OK | AY16: OK | AZ16: OK | BA16: OK | BB16: OK | BC16: OK | BD16: OK | BE16: OK | BF16: OK | BG16: OK | BH16: OK | BI16: OK | BK16: OK | BL16: OK | BM16: OK | BN16: OK | BO16: OK | BP16: OK | BR16: OK | BS16: OK | BT16: OK | BU16: OK | BV16: OK | BW16: OK | BY16: OK | BZ16: OK | CA16: OK | CB16: OK | CC16: OK | CD16: OK | CF16: OK | CG16: OK | CH16: OK | CI16: OK | CJ16: OK | CK16: OK | CL16: OK | CM16: OK | CN16: OK | CO16: OK | CP16: OK | CQ16: OK | CR16: OK | CT16: OK | CU16: OK | CV16: OK | CW16: OK | CX16: OK | CY16: OK | DA16: OK | DB16: OK | DC16: OK | DD16: OK | DE16: OK | DF16: OK | DG16: OK | DI16: OK | DJ16: OK | DK16: OK | DM16: OK | DN16: OK | DP16: OK | DQ16: OK | DR16: OK | DS16: OK | DV16: OK | DW16: OK | DX16: OK | DY16: OK | DZ16: OK | EA16: OK | EB16: OK | EC16: OK | ED16: OK | EE16: OK | EF16: OK | EG16: OK | EH16: OK | EJ16: OK | EK16: OK | EM16: OK | EN16: OK | EO16: OK | EP16: OK | EQ16: OK | ER16: OK | ES16: OK | ET16: OK | EU16: OK | EV16: OK | EW16: OK | EX16: OK | EY16: OK | EZ16: OK | FA16: OK | FB16: OK | FC16: OK | FD16: OK | FE16: OK | FF16: OK | FG16: OK | FH16: OK | FI16: OK | FJ16: OK | FK16: OK | FM16: OK | FN16: OK | FO16: OK | FP16: OK | FQ16: OK | FT16: OK | FU16: OK | FV16: OK | FW16: OK | FX16: OK | GA16: OK | GB16: OK | GC16: OK | GD16: OK | GE16: OK | GH16: OK | GI16: OK
C17: Tuvaletler: Temizlik, sabun | E17: OK | F17: OK | G17: OK | H17: OK | I17: OK | J17: OK | K17: OK | L17: OK | N17: OK | O17: OK | P17: OK | Q17: OK | R17: OK | S17: OK | T17: SORUN | U17: OK | V17: OK | W17: OK | X17: OK | Y17: OK | Z17: OK | AC17: OK | AD17: OK | AE17: OK | AF17: OK | AG17: OK | AJ17: OK | AK17: OK | AL17: OK | AM17: OK | AN17: OK | AQ17: OK | AR17: OK | AS17: OK | AT17: OK | AU17: OK | AX17: OK | AY17: OK | AZ17: OK | BA17: OK | BB17: OK | BC17: OK | BD17: OK | BE17: OK | BF17: OK | BG17: OK | BH17: OK | BI17: OK | BK17: OK | BL17: OK | BM17: OK | BN17: OK | BO17: OK | BP17: OK | BR17: OK | BS17: OK | BT17: OK | BU17: OK | BV17: OK | BW17: OK | BY17: OK | BZ17: OK | CA17: OK | CB17: OK | CC17: OK | CD17: OK | CF17: OK | CG17: OK | CH17: OK | CI17: OK | CJ17: OK | CK17: OK | CL17: OK | CM17: OK | CN17: OK | CO17: OK | CP17: OK | CQ17: OK | CR17: OK | CT17: OK | CU17: OK | CV17: OK | CW17: OK | CX17: OK | CY17: OK | DA17: OK | DB17: OK | DC17: OK | DD17: OK | DE17: OK | DF17: OK | DG17: OK | DI17: OK | DJ17: OK | DK17: OK | DM17: OK | DN17: OK | DP17: OK | DQ17: OK | DR17: OK | DS17: OK | DV17: OK | DW17: OK | DX17: OK | DY17: OK | DZ17: OK | EA17: OK | EB17: OK | EC17: OK | ED17: OK | EE17: OK | EF17: OK | EG17: OK | EH17: OK | EJ17: OK | EK17: OK | EM17: OK | EN17: OK | EO17: OK | EP17: OK | EQ17: OK | ER17: OK | ES17: OK | ET17: OK | EU17: OK | EV17: OK | EW17: OK | EX17: OK | EY17: OK | EZ17: OK | FA17: OK | FB17: OK | FC17: OK | FD17: OK | FE17: OK | FF17: OK | FG17: OK | FH17: OK | FI17: OK | FJ17: OK | FK17: OK | FM17: OK | FN17: OK | FO17: OK | FP17: OK | FQ17: OK | FT17: OK | FU17: OK | FV17: OK | FW17: OK | FX17: OK | GA17: OK | GB17: OK | GC17: OK | GD17: OK | GE17: OK | GH17: OK | GI17: OK
C18: Masa ve rafların toz durumu | E18: OK | F18: OK | G18: OK | H18: OK | I18: OK | J18: OK | K18: OK | L18: OK | N18: OK | O18: OK | P18: OK | Q18: OK | R18: OK | S18: OK | T18: SORUN | U18: OK | V18: OK | W18: OK | X18: OK | Y18: OK | Z18: OK | AC18: OK | AD18: OK | AE18: OK | AF18: OK | AG18: OK | AJ18: OK | AK18: OK | AL18: OK | AM18: OK | AN18: OK | AQ18: OK | AR18: OK | AS18: OK | AT18: OK | AU18: OK | AX18: OK | AY18: OK | AZ18: OK | BA18: OK | BB18: OK | BC18: OK | BD18: OK | BE18: OK | BF18: OK | BG18: OK | BH18: OK | BI18: OK | BK18: OK | BL18: OK | BM18: OK | BN18: OK | BO18: OK | BP18: OK | BR18: OK | BS18: OK | BT18: OK | BU18: OK | BV18: OK | BW18: OK | BY18: OK | BZ18: OK | CA18: OK | CB18: OK | CC18: OK | CD18: OK | CF18: OK | CG18: OK | CH18: OK | CI18: OK | CJ18: OK | CK18: OK | CL18: OK | CM18: OK | CN18: OK | CO18: OK | CP18: OK | CQ18: OK | CR18: OK | CT18: OK | CU18: OK | CV18: OK | CW18: OK | CX18: OK | CY18: OK | DA18: OK | DB18: OK | DC18: OK | DD18: OK | DE18: OK | DF18: OK | DG18: OK | DI18: OK | DJ18: OK | DK18: OK | DM18: OK | DN18: OK | DP18: OK | DQ18: OK | DR18: OK | DS18: OK | DV18: OK | DW18: OK | DX18: OK | DY18: OK | DZ18: OK | EA18: OK | EB18: OK | EC18: OK | ED18: OK | EE18: OK | EF18: OK | EG18: OK | EH18: OK | EJ18: OK | EK18: OK | EM18: OK | EN18: OK | EO18: OK | EP18: OK | EQ18: OK | ER18: OK | ES18: OK | ET18: OK | EU18: OK | EV18: OK | EW18: OK | EX18: OK | EY18: OK | EZ18: OK | FA18: OK | FB18: OK | FC18: OK | FD18: OK | FE18: OK | FF18: OK | FG18: OK | FH18: OK | FI18: OK | FJ18: OK | FK18: OK | FM18: OK | FN18: OK | FO18: OK | FP18: OK | FQ18: OK | FT18: OK | FU18: OK | FV18: OK | FW18: OK | FX18: OK | GA18: OK | GB18: OK | GC18: OK | GD18: OK | GE18: OK | GH18: OK | GI18: OK
C19: Tarama terminalleri: Kağıt, kalem | E19: OK | F19: OK | G19: OK | H19: OK | I19: OK | J19: OK | K19: OK | L19: OK | N19: OK | O19: OK | P19: OK | Q19: OK | R19: OK | S19: OK | T19: OK | U19: OK | V19: OK | W19: OK | X19: OK | Y19: OK | Z19: OK | AC19: OK | AD19: OK | AE19: OK | AF19: OK | AG19: OK | AJ19: OK | AK19: OK | AL19: OK | AM19: OK | AN19: OK | AQ19: OK | AR19: OK | AS19: OK | AT19: OK | AU19: OK | AX19: OK | AY19: OK | AZ19: OK | BA19: OK | BB19: OK | BC19: OK | BD19: OK | BE19: OK | BF19: OK | BG19: OK | BH19: OK | BI19: OK | BK19: OK | BL19: OK | BM19: OK | BN19: OK | BO19: OK | BP19: OK | BR19: OK | BS19: OK | BT19: OK | BU19: OK | BV19: OK | BW19: OK | BY19: OK | BZ19: OK | CA19: OK | CB19: OK | CC19: OK | CD19: OK | CF19: OK | CG19: OK | CH19: OK | CI19: OK | CJ19: OK | CK19: OK | CL19: OK | CM19: OK | CN19: OK | CO19: OK | CP19: OK | CQ19: OK | CR19: OK | CT19: OK | CU19: OK | CV19: OK | CW19: OK | CX19: OK | CY19: OK | DA19: OK | DB19: OK | DC19: OK | DD19: OK | DE19: OK | DF19: OK | DG19: OK | DI19: OK | DJ19: OK | DK19: OK | DM19: OK | DN19: OK | DP19: OK | DQ19: OK | DR19: OK | DS19: OK | DV19: OK | DW19: OK | DX19: OK | DY19: OK | DZ19: OK | EA19: OK | EB19: OK | EC19: OK | ED19: OK | EE19: OK | EF19: OK | EG19: OK | EH19: OK | EJ19: OK | EK19: OK | EM19: OK | EN19: OK | EO19: OK | EP19: OK | EQ19: OK | ER19: OK | ES19: OK | ET19: OK | EU19: OK | EV19: OK | EW19: OK | EX19: OK | EY19: OK | EZ19: OK | FA19: OK | FB19: OK | FC19: OK | FD19: OK | FE19: OK | FF19: OK | FG19: OK | FH19: OK | FI19: OK | FJ19: OK | FK19: OK | FM19: OK | FN19: OK | FO19: OK | FP19: OK | FQ19: OK | FT19: OK | FU19: OK | FV19: OK | FW19: OK | FX19: OK | GA19: OK | GB19: OK | GC19: OK | GD19: OK | GE19: OK | GH19: OK | GI19: OK
C20: Güvenlik Kapıları | E20: OK | F20: OK | G20: OK | H20: OK | I20: OK | J20: OK | K20: OK | L20: OK | N20: OK | O20: OK | P20: OK | Q20: OK | R20: OK | S20: OK | T20: OK | U20: OK | V20: OK | W20: OK | X20: OK | Y20: OK | Z20: OK | AC20: OK | AD20: OK | AE20: OK | AF20: OK | AG20: OK | AJ20: OK | AK20: OK | AL20: OK | AM20: OK | AN20: OK | AQ20: OK | AR20: OK | AS20: OK | AT20: OK | AU20: OK | AX20: OK | AY20: OK | AZ20: OK | BA20: OK | BB20: OK | BC20: OK | BD20: OK | BE20: OK | BF20: OK | BG20: OK | BH20: OK | BI20: OK | BK20: OK | BL20: OK | BM20: OK | BN20: OK | BO20: OK | BP20: OK | BR20: OK | BS20: OK | BT20: OK | BU20: OK | BV20: OK | BW20: OK | BY20: OK | BZ20: OK | CA20: OK | CB20: OK | CC20: OK | CD20: OK | CF20: OK | CG20: OK | CH20: OK | CI20: OK | CJ20: OK | CK20: OK | CL20: OK | CM20: OK | CN20: OK | CO20: OK | CP20: OK | CQ20: OK | CR20: OK | CT20: OK | CU20: OK | CV20: OK | CW20: OK | CX20: OK | CY20: OK | DA20: OK | DB20: OK | DC20: OK | DD20: OK | DE20: OK | DF20: OK | DG20: OK | DI20: OK | DJ20: OK | DK20: OK | DM20: OK | DN20: OK | DP20: OK | DQ20: OK | DR20: OK | DS20: OK | DV20: OK | DW20: OK | DX20: OK | DY20: OK | DZ20: OK | EA20: OK | EB20: OK | EC20: OK | ED20: OK | EE20: OK | EF20: OK | EG20: OK | EH20: OK | EJ20: OK | EK20: OK | EM20: OK | EN20: OK | EO20: OK | EP20: OK | EQ20: OK | ER20: OK | ES20: OK | ET20: OK | EU20: OK | EV20: OK | EW20: OK | EX20: OK | EY20: OK | EZ20: OK | FA20: OK | FB20: OK | FC20: OK | FD20: OK | FE20: OK | FF20: OK | FG20: OK | FH20: OK | FI20: OK | FJ20: OK | FK20: OK | FM20: OK | FN20: OK | FO20: OK | FP20: OK | FQ20: OK | FT20: OK | FU20: OK | FV20: OK | FW20: OK | FX20: OK | GA20: OK | GB20: OK | GC20: OK | GD20: OK | GE20: OK | GH20: OK | GI20: OK
C21: Pencereler | E21: SORUN | F21: OK | G21: OK | H21: OK | I21: OK | J21: OK | K21: SORUN | L21: OK | N21: OK | O21: OK | P21: OK | Q21: OK | R21: OK | S21: OK | T21: OK | U21: OK | V21: OK | W21: OK | X21: SORUN | Y21: SORUN | Z21: OK | AC21: OK | AD21: OK | AE21: OK | AF21: OK | AG21: OK | AJ21: OK | AK21: OK | AL21: OK | AM21: OK | AN21: OK | AQ21: OK | AR21: OK | AS21: OK | AT21: OK | AU21: OK | AX21: OK | AY21: OK | AZ21: OK | BA21: OK | BB21: OK | BC21: OK | BD21: OK | BE21: OK | BF21: OK | BG21: OK | BH21: OK | BI21: OK | BK21: OK | BL21: OK | BM21: OK | BN21: OK | BO21: OK | BP21: OK | BR21: OK | BS21: OK | BT21: OK | BU21: OK | BV21: OK | BW21: OK | BY21: OK | BZ21: OK | CA21: OK | CB21: OK | CC21: OK | CD21: OK | CF21: OK | CG21: OK | CH21: OK | CI21: OK | CJ21: OK | CK21: OK | CL21: OK | CM21: OK | CN21: OK | CO21: OK | CP21: OK | CQ21: OK | CR21: OK | CT21: OK | CU21: OK | CV21: OK | CW21: OK | CX21: OK | CY21: OK | DA21: OK | DB21: OK | DC21: OK | DD21: OK | DE21: OK | DF21: OK | DG21: OK | DI21: OK | DJ21: OK | DK21: OK | DM21: OK | DN21: OK | DP21: OK | DQ21: OK | DR21: OK | DS21: OK | DV21: OK | DW21: OK | DX21: OK | DY21: OK | DZ21: OK | EA21: OK | EB21: OK | EC21: OK | ED21: OK | EE21: OK | EF21: OK | EG21: OK | EH21: OK | EJ21: OK | EK21: OK | EM21: OK | EN21: OK | EO21: OK | EP21: OK | EQ21: OK | ER21: OK | ES21: OK | ET21: OK | EU21: OK | EV21: OK | EW21: OK | EX21: OK | EY21: OK | EZ21: OK | FA21: OK | FB21: OK | FC21: OK | FD21: OK | FE21: OK | FF21: OK | FG21: OK | FH21: OK | FI21: OK | FJ21: OK | FK21: OK | FM21: OK | FN21: OK | FO21: OK | FP21: OK | FQ21: OK | FT21: OK | FU21: OK | FV21: OK | FW21: OK | FX21: OK | GA21: OK | GB21: OK | GC21: OK | GD21: OK | GE21: OK | GH21: OK | GI21: OK
C22: Genel temizlik: halı, mermer mekanlar, merdivenler | E22: OK | F22: OK | G22: OK | H22: OK | I22: OK | J22: OK | K22: OK | L22: OK | N22: OK | O22: OK | P22: OK | Q22: OK | R22: OK | S22: OK | T22: SORUN | U22: OK | V22: OK | W22: OK | X22: OK | Y22: SORUN | Z22: OK | AC22: OK | AD22: OK | AE22: OK | AF22: OK | AG22: OK | AJ22: OK | AK22: OK | AL22: OK | AM22: OK | AN22: OK | AQ22: OK | AR22: OK | AS22: OK | AT22: OK | AU22: OK | AX22: OK | AY22: OK | AZ22: OK | BA22: OK | BB22: OK | BC22: OK | BD22: OK | BE22: OK | BF22: OK | BG22: OK | BH22: OK | BI22: OK | BK22: OK | BL22: OK | BM22: OK | BN22: OK | BO22: OK | BP22: OK | BR22: OK | BS22: OK | BT22: OK | BU22: OK | BV22: OK | BW22: OK | BY22: OK | BZ22: OK | CA22: OK | CB22: OK | CC22: OK | CD22: OK | CF22: OK | CG22: OK | CH22: OK | CI22: OK | CJ22: OK | CK22: OK | CL22: OK | CM22: OK | CN22: OK | CO22: OK | CP22: OK | CQ22: OK | CR22: OK | CT22: OK | CU22: OK | CV22: OK | CW22: OK | CX22: OK | CY22: OK | DA22: OK | DB22: OK | DC22: OK | DD22: OK | DE22: OK | DF22: OK | DG22: OK | DI22: OK | DJ22: OK | DK22: OK | DM22: OK | DN22: OK | DP22: OK | DQ22: OK | DR22: OK | DS22: OK | DV22: OK | DW22: OK | DX22: OK | DY22: OK | DZ22: OK | EA22: OK | EB22: OK | EC22: OK | ED22: OK | EE22: OK | EF22: OK | EG22: OK | EH22: OK | EJ22: OK | EK22: OK | EM22: OK | EN22: OK | EO22: OK | EP22: OK | EQ22: OK | ER22: OK | ES22: OK | ET22: OK | EU22: OK | EV22: OK | EW22: OK | EX22: OK | EY22: OK | EZ22: OK | FA22: OK | FB22: OK | FC22: OK | FD22: OK | FE22: OK | FF22: OK | FG22: OK | FH22: OK | FI22: OK | FJ22: OK | FK22: OK | FM22: OK | FN22: OK | FO22: OK | FP22: OK | FQ22: OK | FT22: OK | FU22: OK | FV22: OK | FW22: OK | FX22: OK | GA22: OK | GB22: OK | GC22: OK | GD22: OK | GE22: OK | GH22: OK | GI22: OK
C23: Su sebillerinde su ve bardak var mı? | E23: OK | F23: OK | G23: OK | H23: OK | I23: OK | J23: OK | K23: OK | L23: OK | N23: OK | O23: OK | P23: OK | Q23: OK | R23: OK | S23: OK | T23: OK | U23: OK | V23: OK | W23: OK | X23: OK | Y23: OK | Z23: OK | AC23: OK | AD23: OK | AE23: OK | AF23: OK | AG23: OK | AJ23: OK | AK23: OK | AL23: OK | AM23: OK | AN23: OK | AQ23: OK | AR23: OK | AS23: OK | AT23: OK | AU23: OK | AX23: OK | AY23: OK | AZ23: OK | BA23: OK | BB23: OK | BC23: OK | BD23: OK | BE23: OK | BF23: OK | BG23: OK | BH23: OK | BI23: OK | BK23: OK | BL23: OK | BM23: OK | BN23: OK | BO23: OK | BP23: OK | BR23: OK | BS23: OK | BT23: OK | BU23: OK | BV23: OK | BW23: OK | BY23: OK | BZ23: OK | CA23: OK | CB23: OK | CC23: OK | CD23: OK | CF23: OK | CG23: OK | CH23: OK | CI23: OK | CJ23: OK | CK23: OK | CL23: OK | CM23: OK | CN23: OK | CO23: OK | CP23: OK | CQ23: OK | CR23: OK | CT23: OK | CU23: OK | CV23: OK | CW23: OK | CX23: OK | CY23: OK | DA23: OK | DB23: OK | DC23: OK | DD23: OK | DE23: OK | DF23: OK | DG23: OK | DI23: OK | DJ23: OK | DK23: OK | DM23: OK | DN23: OK | DP23: OK | DQ23: OK | DR23: OK | DS23: OK | DV23: OK | DW23: OK | DX23: OK | DY23: OK | DZ23: OK | EA23: OK | EB23: OK | EC23: OK | ED23: OK | EE23: OK | EF23: OK | EG23: OK | EH23: OK | EJ23: OK | EK23: OK | EM23: OK | EN23: OK | EO23: OK | EP23: OK | EQ23: OK | ER23: OK | ES23: OK | ET23: OK | EU23: OK | EV23: OK | EW23: OK | EX23: OK | EY23: OK | EZ23: OK | FA23: OK | FB23: OK | FC23: OK | FD23: OK | FE23: OK | FF23: OK | FG23: OK | FH23: OK | FI23: OK | FJ23: OK | FK23: OK | FM23: OK | FN23: OK | FO23: OK | FP23: OK | FQ23: OK | FT23: OK | FU23: OK | FV23: OK | FW23: OK | FX23: OK | GA23: OK | GB23: OK | GC23: OK | GD23: OK | GE23: OK | GH23: OK | GI23: OK
C24: Plastik ve kağıt geri dönüşümlerin durumu | E24: OK | F24: OK | G24: OK | H24: OK | I24: OK | J24: OK | K24: OK | L24: OK | N24: OK | O24: OK | P24: OK | Q24: OK | R24: OK | S24: OK | T24: OK | U24: OK | V24: OK | W24: OK | X24: OK | Y24: OK | Z24: OK | AC24: OK | AD24: OK | AE24: OK | AF24: OK | AG24: OK | AJ24: OK | AK24: OK | AL24: OK | AM24: OK | AN24: OK | AQ24: OK | AR24: OK | AS24: OK | AT24: OK | AU24: OK | AX24: OK | AY24: OK | AZ24: OK | BA24: OK | BB24: OK | BC24: OK | BD24: OK | BE24: OK | BF24: OK | BG24: OK | BH24: OK | BI24: OK | BK24: OK | BL24: OK | BM24: SORUN | BN24: OK | BO24: OK | BP24: OK | BR24: OK | BS24: OK | BT24: OK | BU24: OK | BV24: OK | BW24: OK | BY24: OK | BZ24: OK | CA24: OK | CB24: OK | CC24: OK | CD24: OK | CF24: OK | CG24: OK | CH24: OK | CI24: OK | CJ24: OK | CK24: OK | CL24: OK | CM24: OK | CN24: OK | CO24: OK | CP24: OK | CQ24: OK | CR24: OK | CT24: OK | CU24: OK | CV24: OK | CW24: OK | CX24: OK | CY24: OK | DA24: OK | DB24: OK | DC24: OK | DD24: OK | DE24: OK | DF24: OK | DG24: OK | DI24: OK | DJ24: OK | DK24: OK | DM24: OK | DN24: OK | DP24: OK | DQ24: OK | DR24: OK | DS24: OK | DV24: OK | DW24: OK | DX24: OK | DY24: OK | DZ24: OK | EA24: OK | EB24: OK | EC24: OK | ED24: OK | EE24: OK | EF24: OK | EG24: OK | EH24: OK | EJ24: OK | EK24: OK | EM24: OK | EN24: OK | EO24: OK | EP24: OK | EQ24: OK | ER24: OK | ES24: OK | ET24: OK | EU24: OK | EV24: OK | EW24: OK | EX24: OK | EY24: OK | EZ24: OK | FA24: OK | FB24: OK | FC24: OK | FD24: OK | FE24: OK | FF24: OK | FG24: OK | FH24: OK | FI24: OK | FJ24: OK | FK24: OK | FM24: OK | FN24: OK | FO24: OK | FP24: OK | FQ24: OK | FT24: OK | FU24: OK | FV24: OK | FW24: OK | FX24: OK | GA24: OK | GB24: OK | GC24: OK | GD24: OK | GE24: OK | GH24: OK | GI24: OK
C25: Toplanlari Odaları (2025, ...) | E25: OK | F25: OK | G25: SORUN | H25: OK | I25: OK | J25: OK | K25: OK | L25: OK | N25: OK | O25: OK | P25: OK | Q25: OK | R25: OK | S25: OK | T25: OK | U25: OK | V25: OK | W25: OK | X25: OK | Y25: OK | Z25: OK | AC25: OK | AD25: OK | AE25: OK | AF25: OK | AG25: OK | AJ25: OK | AK25: OK | AL25: OK | AM25: OK | AN25: OK | AQ25: OK | AR25: OK | AS25: OK | AT25: OK | AU25: OK | AX25: OK | AY25: OK | AZ25: OK | BA25: OK | BB25: OK | BC25: OK | BD25: OK | BE25: OK | BF25: OK | BG25: OK | BH25: OK | BI25: OK | BK25: OK | BL25: OK | BM25: OK | BN25: OK | BO25: OK | BP25: OK | BR25: OK | BS25: OK | BT25: OK | BU25: OK | BV25: OK | BW25: OK | BY25: OK | BZ25: OK | CA25: OK | CB25: OK | CC25: OK | CD25: OK | CF25: OK | CG25: OK | CH25: OK | CI25: OK | CJ25: OK | CK25: OK | CL25: OK | CM25: OK | CN25: OK | CO25: OK | CP25: OK | CQ25: OK | CR25: OK | CT25: OK | CU25: OK | CV25: OK | CW25: OK | CX25: OK | CY25: OK | DA25: OK | DB25: OK | DC25: OK | DD25: OK | DE25: OK | DF25: OK | DG25: OK | DI25: OK | DJ25: OK | DK25: OK | DM25: OK | DN25: OK | DP25: OK | DQ25: OK | DR25: OK | DS25: OK | DV25: OK | DW25: OK | DX25: OK | DY25: OK | DZ25: OK | EA25: OK | EB25: OK | EC25: OK | ED25: OK | EE25: OK | EF25: OK | EG25: OK | EH25: OK | EJ25: OK | EK25: OK | EM25: OK | EN25: OK | EO25: OK | EP25: OK | EQ25: OK | ER25: OK | ES25: OK | ET25: OK | EU25: OK | EV25: OK | EW25: OK | EX25: OK | EY25: OK | EZ25: OK | FA25: OK | FB25: OK | FC25: OK | FD25: OK | FE25: OK | FF25: OK | FG25: OK | FH25: OK | FI25: OK | FJ25: OK | FK25: OK | FM25: OK | FN25: OK | FO25: OK | FP25: OK | FQ25: OK | FT25: OK | FU25: OK | FV25: OK | FW25: OK | FX25: OK | GA25: OK | GB25: OK | GC25: OK | GD25: OK | GE25: OK | GH25: OK | GI25: OK
... C27: Diğer | E27: OK | F27: OK | G27: OK | H27: OK | I27: OK | J27: OK | K27: OK | L27: OK | N27: OK | O27: OK | P27: OK | Q27: OK | R27: OK | S27: OK | T27: OK | U27: OK | V27: OK | W27: OK | X27: OK | Y27: OK | Z27: OK | AC27: OK | AD27: OK | AE27: OK | AF27: OK | AG27: OK | AJ27: OK | AK27: OK | AL27: OK | AM27: OK | AN27: OK | AQ27: OK | AR27: OK | AS27: OK | AT27: OK | AU27: OK | AX27: OK | AY27: OK | AZ27: OK | BA27: OK | BB27: OK | BC27: OK | BD27: OK | BE27: OK | BF27: OK | BG27: OK | BH27: OK | BI27: OK | BK27: OK | BL27: OK | BM27: OK | BN27: OK | BO27: OK | BP27: OK | BR27: OK | BS27: OK | BT27: OK | BU27: OK | BV27: OK | BW27: OK | BY27: OK | BZ27: OK | CA27: OK | CB27: OK | CC27: OK | CD27: OK | CF27: OK | CG27: OK | CH27: OK | CI27: OK | CJ27: OK | CK27: OK | CL27: OK | CM27: OK | CN27: OK | CO27: OK | CP27: OK | CQ27: OK | CR27: OK | CT27: OK | CU27: OK | CV27: OK | CW27: OK | CX27: OK | CY27: OK | DA27: OK | DB27: OK | DC27: OK | DD27: OK | DE27: OK | DF27: OK | DG27: OK | DI27: OK | DJ27: OK | DK27: OK | DM27: OK | DN27: OK | DP27: OK | DQ27: OK | DR27: OK | DS27: OK | DV27: OK | DW27: OK | DX27: OK | DY27: OK | DZ27: OK | EA27: OK | EB27: OK | EC27: OK | ED27: OK | EE27: OK | EF27: OK | EG27: OK | EH27: OK | EJ27: OK | EK27: OK | EM27: OK | EN27: OK | EO27: OK | EP27: OK | EQ27: OK | ER27: OK | ES27: OK | ET27: OK | EU27: OK | EV27: OK | EW27: OK | EX27: OK | EY27: OK | EZ27: OK | FA27: OK | FB27: OK | FC27: OK | FD27: OK | FE27: OK | FF27: OK | FG27: OK | FH27: OK | FI27: OK | FJ27: OK | FK27: OK | FM27: OK | FN27: OK | FO27: OK | FP27: OK | FQ27: OK | FT27: OK | FU27: OK | FV27: OK | FW27: OK | FX27: OK | GA27: OK | GB27: OK | GC27: OK | GD27: OK | GE27: OK | GH27: OK | GI27: OK
B28: KOLEKSİYON | C28: KOLEKSİYON
C29: Koleksiyon Yerleştirme | E29: OK | F29: OK | G29: OK | H29: OK | I29: OK | J29: OK | K29: OK | L29: OK | N29: OK | O29: OK | P29: OK | Q29: OK | R29: OK | S29: OK | T29: OK | U29: OK | V29: OK | W29: OK | X29: OK | Y29: OK | Z29: OK | AC29: SORUN | AD29: OK | AE29: OK | AF29: OK | AG29: OK | AJ29: OK | AK29: OK | AL29: OK | AM29: OK | AN29: OK | AQ29: OK | AR29: OK | AS29: OK | AT29: OK | AU29: OK | AX29: OK | AY29: OK | AZ29: OK | BA29: OK | BB29: OK | BC29: OK | BD29: OK | BE29: OK | BF29: OK | BG29: OK | BH29: OK | BI29: OK | BK29: OK | BL29: OK | BM29: OK | BN29: OK | BO29: OK | BP29: OK | BR29: OK | BS29: OK | BT29: OK | BU29: OK | BV29: OK | BW29: OK | BY29: OK | BZ29: OK | CA29: OK | CB29: OK | CC29: OK | CD29: OK | CF29: OK | CG29: OK | CH29: OK | CI29: OK | CJ29: OK | CK29: OK | CL29: OK | CM29: OK | CN29: OK | CO29: OK | CP29: OK | CQ29: OK | CR29: OK | CT29: OK | CU29: OK | CV29: OK | CW29: OK | CX29: OK | CY29: OK | DA29: OK | DB29: OK | DC29: OK | DD29: OK | DE29: OK | DF29: OK | DG29: OK | DI29: OK | DJ29: OK | DK29: OK | DM29: OK | DN29: OK | DP29: OK | DQ29: OK | DR29: OK | DS29: OK | DV29: OK | DW29: OK | DX29: OK | DY29: OK | DZ29: OK | EA29: OK | EB29: OK | EC29: OK | ED29: OK | EE29: OK | EF29: OK | EG29: OK | EH29: OK | EJ29: OK | EK29: OK | EM29: OK | EN29: OK | EO29: OK | EP29: OK | EQ29: OK | ER29: OK | ES29: OK | ET29: OK | EU29: OK | EV29: OK | EW29: OK | EX29: OK | EY29: OK | EZ29: OK | FA29: OK | FB29: OK | FC29: OK | FD29: OK | FE29: OK | FF29: OK | FG29: OK | FH29: OK | FI29: OK | FJ29: OK | FK29: OK | FM29: OK | FN29: OK | FO29: OK | FP29: OK | FQ29: OK | FT29: OK | FU29: OK | FV29: OK | FW29: OK | FX29: OK | GA29: OK | GB29: OK | GC29: OK | GD29: OK | GE29: OK | GH29: OK | GI29: OK
C30: Koleksiyon Düzen | E30: SORUN | F30: OK | G30: OK | H30: OK | I30: OK | J30: OK | K30: OK | L30: OK | N30: OK | O30: OK | P30: OK | Q30: OK | R30: OK | S30: OK | T30: OK | U30: OK | V30: OK | W30: OK | X30: OK | Y30: OK | Z30: OK | AC30: OK | AD30: OK | AE30: OK | AF30: OK | AG30: OK | AJ30: OK | AK30: OK | AL30: OK | AM30: OK | AN30: OK | AQ30: OK | AR30: OK | AS30: OK | AT30: OK | AU30: OK | AX30: OK | AY30: OK | AZ30: OK | BA30: OK | BB30: OK | BC30: OK | BD30: OK | BE30: OK | BF30: OK | BG30: OK | BH30: OK | BI30: OK | BK30: OK | BL30: OK | BM30: OK | BN30: OK | BO30: OK | BP30: OK | BR30: OK | BS30: OK | BT30: OK | BU30: OK | BV30: OK | BW30: OK | BY30: OK | BZ30: OK | CA30: OK | CB30: OK | CC30: OK | CD30: OK | CF30: OK | CG30: OK | CH30: OK | CI30: OK | CJ30: OK | CK30: OK | CL30: OK | CM30: OK | CN30: OK | CO30: OK | CP30: OK | CQ30: OK | CR30: OK | CT30: OK | CU30: OK | CV30: OK | CW30: OK | CX30: OK | CY30: OK | DA30: OK | DB30: OK | DC30: OK | DD30: OK | DE30: OK | DF30: OK | DG30: OK | DI30: OK | DJ30: OK | DK30: OK | DM30: OK | DN30: OK | DP30: OK | DQ30: OK | DR30: OK | DS30: OK | DV30: OK | DW30: OK | DX30: OK | DY30: OK | DZ30: OK | EA30: OK | EB30: OK | EC30: OK | ED30: OK | EE30: OK | EF30: OK | EG30: OK | EH30: OK | EJ30: OK | EK30: OK | EM30: OK | EN30: OK | EO30: OK | EP30: OK | EQ30: OK | ER30: OK | ES30: OK | ET30: OK | EU30: OK | EV30: OK | EW30: OK | EX30: OK | EY30: OK | EZ30: OK | FA30: OK | FB30: OK | FC30: OK | FD30: OK | FE30: OK | FF30: OK | FG30: OK | FH30: OK | FI30: OK | FJ30: OK | FK30: OK | FM30: OK | FN30: OK | FO30: OK | FP30: OK | FQ30: OK | FT30: OK | FU30: OK | FV30: OK | FW30: OK | FX30: OK | GA30: OK | GB30: OK | GC30: OK | GD30: OK | GE30: OK | GH30: OK | GI30: OK
C31: Koleksiyon Okunma | E31: OK | F31: OK | G31: OK | H31: OK | I31: OK | J31: OK | K31: OK | L31: OK | N31: OK | O31: OK | P31: OK | Q31: OK | R31: OK | S31: OK | T31: OK | U31: OK | V31: OK | W31: OK | X31: OK | Y31: OK | Z31: OK | AC31: OK | AD31: OK | AE31: OK | AF31: OK | AG31: OK | AJ31: OK | AK31: OK | AL31: OK | AM31: OK | AN31: OK | AQ31: OK | AR31: OK | AS31: OK | AT31: OK | AU31: OK | AX31: OK | AY31: OK | AZ31: OK | BA31: OK | BB31: OK | BC31: OK | BD31: OK | BE31: OK | BF31: OK | BG31: OK | BH31: OK | BI31: OK | BK31: OK | BL31: OK | BM31: OK | BN31: OK | BO31: OK | BP31: OK | BR31: OK | BS31: OK | BT31: OK | BU31: OK | BV31: OK | BW31: OK | BY31: OK | BZ31: OK | CA31: OK | CB31: OK | CC31: OK | CD31: OK | CF31: OK | CG31: OK | CH31: OK | CI31: OK | CJ31: OK | CK31: OK | CL31: OK | CM31: OK | CN31: OK | CO31: OK | CP31: OK | CQ31: OK | CR31: OK | CT31: OK | CU31: OK | CV31: OK | CW31: OK | CX31: OK | CY31: OK | DA31: OK | DB31: OK | DC31: OK | DD31: OK | DE31: OK | DF31: OK | DG31: OK | DI31: OK | DJ31: OK | DK31: OK | DM31: OK | DN31: OK | DP31: OK | DQ31: OK | DR31: OK | DS31: OK | DV31: OK | DW31: OK | DX31: OK | DY31: OK | DZ31: OK | EA31: OK | EB31: OK | EC31: OK | ED31: OK | EE31: OK | EF31: OK | EG31: OK | EH31: OK | EJ31: OK | EK31: OK | EM31: OK | EN31: OK | EO31: OK | EP31: OK | EQ31: OK | ER31: OK | ES31: OK | ET31: OK | EU31: OK | EV31: OK | EW31: OK | EX31: OK | EY31: OK | EZ31: OK | FA31: OK | FB31: OK | FC31: OK | FD31: OK | FE31: OK | FF31: OK | FG31: OK | FH31: OK | FI31: OK | FJ31: OK | FK31: OK | FM31: OK | FN31: OK | FO31: OK | FP31: OK | FQ31: OK | FT31: OK | FU31: OK | FV31: OK | FW31: OK | FX31: OK | GA31: OK | GB31: OK | GC31: OK | GD31: OK | GE31: OK | GH31: OK | GI31: OK
C32: Koleksiyon Aydınlatma | E32: OK | F32: OK | G32: OK | H32: OK | I32: OK | J32: OK | K32: OK | L32: OK | N32: OK | O32: OK | P32: OK | Q32: OK | R32: OK | S32: OK | T32: OK | U32: OK | V32: OK | W32: OK | X32: OK | Y32: OK | Z32: OK | AC32: OK | AD32: OK | AE32: OK | AF32: OK | AG32: OK | AJ32: OK | AK32: OK | AL32: OK | AM32: OK | AN32: OK | AQ32: OK | AR32: OK | AS32: OK | AT32: OK | AU32: OK | AX32: OK | AY32: OK | AZ32: OK | BA32: OK | BB32: OK | BC32: OK | BD32: OK | BE32: OK | BF32: OK | BG32: OK | BH32: OK | BI32: OK | BK32: OK | BL32: OK | BM32: OK | BN32: OK | BO32: OK | BP32: OK | BR32: OK | BS32: OK | BT32: OK | BU32: OK | BV32: OK | BW32: OK | BY32: OK | BZ32: OK | CA32: OK | CB32: OK | CC32: OK | CD32: OK | CF32: OK | CG32: OK | CH32: OK | CI32: OK | CJ32: OK | CK32: SORUN | CL32: OK | CM32: OK | CN32: OK | CO32: OK | CP32: OK | CQ32: OK | CR32: OK | CT32: OK | CU32: OK | CV32: OK | CW32: OK | CX32: OK | CY32: OK | DA32: OK | DB32: OK | DC32: OK | DD32: OK | DE32: OK | DF32: OK | DG32: OK | DI32: OK | DJ32: OK | DK32: OK | DM32: OK | DN32: OK | DP32: OK | DQ32: OK | DR32: OK | DS32: OK | DV32: OK | DW32: OK | DX32: OK | DY32: OK | DZ32: OK | EA32: OK | EB32: OK | EC32: OK | ED32: OK | EE32: OK | EF32: OK | EG32: OK | EH32: OK | EJ32: OK | EK32: OK | EM32: OK | EN32: OK | EO32: OK | EP32: OK | EQ32: OK | ER32: OK | ES32: OK | ET32: OK | EU32: OK | EV32: OK | EW32: OK | EX32: OK | EY32: OK | EZ32: OK | FA32: OK | FB32: OK | FC32: OK | FD32: OK | FE32: OK | FF32: OK | FG32: OK | FH32: OK | FI32: OK | FJ32: OK | FK32: OK | FM32: OK | FN32: OK | FO32: OK | FP32: OK | FQ32: OK | FT32: OK | FU32: OK | FV32: OK | FW32: OK | FX32: OK | GA32: OK | GB32: OK | GC32: OK | GD32: OK | GE32: OK | GH32: OK | GI32: OK
C33: Temizlik | E33: OK | F33: OK | G33: OK | H33: OK | I33: OK | J33: OK | K33: OK | L33: OK | N33: OK | O33: OK | P33: OK | Q33: OK | R33: OK | S33: OK | T33: OK | U33: OK | V33: OK | W33: OK | X33: OK | Y33: OK | Z33: OK | AC33: OK | AD33: OK | AE33: OK | AF33: OK | AG33: OK | AJ33: OK | AK33: OK | AL33: OK | AM33: OK | AN33: OK | AQ33: OK | AR33: OK | AS33: OK | AT33: OK | AU33: OK | AX33: OK | AY33: OK | AZ33: OK | BA33: OK | BB33: OK | BC33: OK | BD33: OK | BE33: OK | BF33: OK | BG33: OK | BH33: OK | BI33: OK | BK33: OK | BL33: OK | BM33: OK | BN33: OK | BO33: OK | BP33: OK | BR33: OK | BS33: OK | BT33: OK | BU33: OK | BV33: OK | BW33: OK | BY33: OK | BZ33: OK | CA33: OK | CB33: OK | CC33: OK | CD33: OK | CF33: OK | CG33: OK | CH33: OK | CI33: OK | CJ33: OK | CK33: OK | CL33: OK | CM33: OK | CN33: OK | CO33: OK | CP33: OK | CQ33: OK | CR33: OK | CT33: OK | CU33: OK | CV33: OK | CW33: OK | CX33: OK | CY33: OK | DA33: OK | DB33: OK | DC33: OK | DD33: OK | DE33: OK | DF33: OK | DG33: OK | DI33: OK | DJ33: OK | DK33: OK | DM33: OK | DN33: OK | DP33: OK | DQ33: OK | DR33: OK | DS33: OK | DV33: OK | DW33: OK | DX33: OK | DY33: OK | DZ33: OK | EA33: OK | EB33: OK | EC33: OK | ED33: OK | EE33: OK | EF33: OK | EG33: OK | EH33: OK | EJ33: OK | EK33: OK | EM33: OK | EN33: OK | EO33: OK | EP33: OK | EQ33: OK | ER33: OK | ES33: OK | ET33: OK | EU33: OK | EV33: OK | EW33: OK | EX33: OK | EY33: OK | EZ33: OK | FA33: OK | FB33: OK | FC33: OK | FD33: OK | FE33: OK | FF33: OK | FG33: OK | FH33: OK | FI33: OK | FJ33: OK | FK33: OK | FM33: OK | FN33: OK | FO33: OK | FP33: OK | FQ33: OK | FT33: OK | FU33: OK | FV33: OK | FW33: OK | FX33: OK | GA33: OK | GB33: OK | GC33: OK | GD33: OK | GE33: OK | GH33: OK | GI33: OK
A35: Açılış denetiminin 08:45'den önce tamamlanması gerekmektedir.
A37: SORUN ifadesi yazan bölümlerin mevcut sorunlarını görmek için lütfen ÇAĞRI İZLEME tabına bakınız
AO61: 14
AO62: 26

Sheet Açılış Denetimi
A1: Açılış Denetimi | C1: 40910 | D1: 40911 | E1: 40912 | F1: 40913 | G1: 40914 | H1: 40915 | I1: 40916 | J1: 40917 | K1: 40918 | L1: 40919 | M1: 40920 | N1: 40921 | O1: 40922 | P1: 40923 | Q1: 40924 | R1: 40925 | S1: 40926 | T1: 40927 | U1: 40928 | V1: 40929 | W1: 40930 | X1: 40931 | Y1: 40932 | Z1: 40933 | AA1: 40934 | AB1: 40935 | AC1: 40936 | AD1: 40937 | AE1: 40938 | AF1: 40939 | AG1: 40940 | AH1: 40941 | AI1: 40942 | AJ1: 40943 | AK1: 40944 | AL1: 40945 | AM1: 40946 | AN1: 40947 | AO1: 40948 | AP1: 40949 | AQ1: 40950 | AR1: 40951 | AS1: 40952 | AT1: 40953 | AU1: 40954 | AV1: 40955 | AW1: 40956 | AX1: 40957 | AY1: 40958 | AZ1: 40959 | BA1: 40960 | BB1: 40961 | BC1: 40962 | BD1: 40963 | BE1: 40964 | BF1: 40965 | BG1: 40966 | BH1: 40967 | BI1: 40968 | BJ1: 40969 | BK1: 40970 | BL1: 40971 | BM1: 40972 | BN1: 40973 | BO1: 40974 | BP1: 40975 | BQ1: 40976 | BR1: 40977 | BS1: 40978 | BT1: 40979 | BU1: 40980 | BV1: 40981 | BW1: 40982 | BX1: 40983 | BY1: 40984 | BZ1: 40985 | CA1: 40986 | CB1: 40987 | CC1: 40988 | CD1: 40989 | CE1: 40990 | CF1: 40991 | CG1: 40992 | CH1: 40993 | CI1: 40994 | CJ1: 40995 | CK1: 40996 | CL1: 40997 | CM1: 40998 | CN1: 40999 | CO1: 41000 | CP1: 41001 | CQ1: 41002 | CR1: 41003 | CS1: 41004 | CT1: 41005 | CU1: 41006 | CV1: 41007 | CW1: 41008 | CX1: 41009 | CY1: 41010 | CZ1: 41011 | DA1: 41012 | DB1: 41013 | DC1: 41014 | DD1: 41015 | DE1: 41016 | DF1: 41017 | DG1: 41018 | DH1: 41019 | DI1: 41020 | DJ1: 41021 | DK1: 41022 | DL1: 41023 | DM1: 41024 | DN1: 41025 | DO1: 41026 | DP1: 41027 | DQ1: 41028 | DR1: 41029 | DS1: 41030 | DT1: 41031 | DU1: 41032 | DV1: 41033 | DW1: 41034 | DX1: 41035 | DY1: 41036 | DZ1: 41037 | EA1: 41038 | EB1: 41039 | EC1: 41040 | ED1: 41041 | EE1: 41042 | EF1: 41043 | EG1: 41044 | EH1: 41045 | EI1: 41046 | EJ1: 41047 | EK1: 41048 | EL1: 41049 | EM1: 41050 | EN1: 41051 | EO1: 41052 | EP1: 41053 | EQ1: 41054 | ER1: 41055 | ES1: 41056 | ET1: 41057 | EU1: 41058 | EV1: 41059 | EW1: 41060 | EX1: 41061 | EY1: 41062 | EZ1: 41063 | FA1: 41064 | FB1: 41065 | FC1: 41066 | FD1: 41067 | FE1: 41068 | FF1: 41069 | FG1: 41070 | FH1: 41071 | FI1: 41072 | FJ1: 41073 | FK1: 41074 | FL1: 41075 | FM1: 41076 | FN1: 41077 | FO1: 41078 | FP1: 41079 | FQ1: 41080 | FR1: 41081 | FS1: 41082 | FT1: 41083 | FU1: 41084 | FV1: 41085 | FW1: 41086 | FX1: 41087 | FY1: 41088 | FZ1: 41089 | GA1: 41090 | GB1: 41091 | GC1: 41092 | GD1: 41093 | GE1: 41094 | GF1: 41095 | GG1: 41096 | GH1: 41097 | GI1: 41098 | GJ1: 41099 | GK1: 41100 | GL1: 41101 | GM1: 41102 | GN1: 41103 | GO1: 41104 | GP1: 41105 | GQ1: 41106 | GR1: 41107 | GS1: 41108 | GT1: 41109 | GU1: 41110 | GV1: 41111 | GW1: 41112 | GX1: 41113 | GY1: 41114 | GZ1: 41115 | HA1: 41116 | HB1: 41117 | HC1: 41118 | HD1: 41119 | HE1: 41120 | HF1: 41121 | HG1: 41122 | HH1: 41123 | HI1: 41124 | HJ1: 41125 | HK1: 41126 | HL1: 41127 | HM1: 41128 | HN1: 41129 | HO1: 41130 | HP1: 41131 | HQ1: 41132 | HR1: 41133 | HS1: 41134 | HT1: 41135 | HU1: 41136 | HV1: 41137 | HW1: 41138 | HX1: 41139 | HY1: 41140 | HZ1: 41141 | IA1: 41142 | IB1: 41143 | IC1: 41144 | ID1: 41145 | IE1: 41146 | IF1: 41147 | IG1: 41148 | IH1: 41149 | II1: 41150 | IJ1: 41151 | IK1: 41152 | IL1: 41153 | IM1: 41154 | IN1: 41155 | IO1: 41156 | IP1: 41157 | IQ1: 41158 | IR1: 41159 | IS1: 41160 | IT1: 41161 | IU1: 41162 | IV1: 41163 | IW1: 41164 | IX1: 41165 | IY1: 41166 | IZ1: 41167 | JA1: 41168 | JB1: 41169 | JC1: 41170 | JD1: 41171 | JE1: 41172 | JF1: 41173 | JG1: 41174 | JH1: 41175 | JI1: 41176 | JJ1: 41177 | JK1: 41178 | JL1: 41179 | JM1: 41180 | JN1: 41181 | JO1: 41182 | JP1: 41183 | JQ1: 41184 | JR1: 41185 | JS1: 41186 | JT1: 41187 | JU1: 41188 | JV1: 41189 | JW1: 41190 | JX1: 41191 | JY1: 41192 | JZ1: 41193 | KA1: 41194 | KB1: 41195 | KC1: 41196 | KD1: 41197 | KE1: 41198 | KF1: 41199 | KG1: 41200 | KH1: 41201 | KI1: 41202 | KJ1: 41203 | KK1: 41204 | KL1: 41205 | KM1: 41206 | KN1: 41207 | KO1: 41208 | KP1: 41209 | KQ1: 41210 | KR1: 41211 | KS1: 41212 | KT1: 41213 | KU1: 41214 | KV1: 41215 | KW1: 41216 | KX1: 41217 | KY1: 41218 | KZ1: 41219 | LA1: 41220 | LB1: 41221 | LC1: 41222 | LD1: 41223 | LE1: 41224 | LF1: 41225 | LG1: 41226 | LH1: 41227 | LI1: 41228 | LJ1: 41229 | LK1: 41230 | LL1: 41231 | LM1: 41232 | LN1: 41233 | LO1: 41234 | LP1: 41235 | LQ1: 41236 | LR1: 41237 | LS1: 41238 | LT1: 41239 | LU1: 41240 | LV1: 41241 | LW1: 41242 | LX1: 41243 | LY1: 41244 | LZ1: 41245 | MA1: 41246 | MB1: 41247 | MC1: 41248 | MD1: 41249 | ME1: 41250 | MF1: 41251 | MG1: 41252 | MH1: 41253 | MI1: 41254 | MJ1: 41255 | MK1: 41256 | ML1: 41257 | MM1: 41258 | MN1: 41259 | MO1: 41260 | MP1: 41261 | MQ1: 41262 | MR1: 41263 | MS1: 41264 | MT1: 41265 | MU1: 41266 | MV1: 41267 | MW1: 41268 | MX1: 41269 | MY1: 41270 | MZ1: 41271 | NA1: 41272 | NB1: 41273 | NC1: 41274 | ND1: Sorun Sayısı
A2: Genel Kontrol | B2: 3M Güvenlik Kapıları | ND2: =COUNTIF(C4:NC4,"SORUN") -> 0
B3: Acil Çıkış Kapıları ve Plastikleri | ND3: =COUNTIF(C5:NC5,"SORUN") -> 0
B4: Fotokopi Cihazları | ND4: =COUNTIF(C6:NC6,"SORUN") -> 0
B5: Tuvaletler Sabun ve Kağıt Havlu Durumu | ND5: =COUNTIF(C7:NC7,"SORUN") -> 0
B6: Tarama Terminalleri | ND6: =COUNTIF(C8:NC8,"SORUN") -> 0
B7: Su Sebilleri Bardak-Su Durumu | ND7: =COUNTIF(C9:NC9,"SORUN") -> 0
B8: Diğer | ND8: =COUNTIF(C10:NC10,"SORUN") -> 0
A9: Düzen | B9: Havuza Bakan Koltuklar | ND9: =COUNTIF(C11:NC11,"SORUN") -> 0
B10: Çalışma Masaları Sandalyeleri | ND10: =COUNTIF(C12:NC12,"SORUN") -> 0
B11: Grup Çalışma Odaları | ND11: =COUNTIF(C13:NC13,"SORUN") -> 0
B12: Grup Projeksiyon Odaları | ND12: =COUNTIF(C14:NC14,"SORUN") -> 0
B13: Bireysel Çalışma Karelleri | ND13: =COUNTIF(C15:NC15,"SORUN") -> 0
B14: Gazete Koltukları ve Sehpaları | ND14: =COUNTIF(C16:NC16,"SORUN") -> 0
B15: 7-24 Okuma Salonu | ND15: =COUNTIF(C17:NC17,"SORUN") -> 0
B16: Kitap ve Multimedya Koleksiyonu | ND16: =COUNTIF(C18:NC18,"SORUN") -> 0
B17: Diğer | ND17: =COUNTIF(C19:NC19,"SORUN") -> 0
A18: Temizlik | B18: Grup Odaları Kapı Camları | ND18: =COUNTIF(C20:NC20,"SORUN") -> 0
B19: Çalışma Masaları | ND19: =COUNTIF(C21:NC21,"SORUN") -> 0
B20: Pencereler | ND20: =COUNTIF(C22:NC22,"SORUN") -> 0
B21: Halı ve Mermer Zeminler | ND21: =COUNTIF(C23:NC23,"SORUN") -> 0
B22: Olmuksa ve Geri Dönüşüm Kutuları | ND22: =COUNTIF(C24:NC24,"SORUN") -> 0
B23: Bireysel Çalışma Karelleri | ND23: =COUNTIF(C25:NC25,"SORUN") -> 0
B24: Kitap ve Multimedya Koleksiyonu | ND24: =COUNTIF(C26:NC26,"SORUN") -> 0
B25: 7-24 Okuma Salonu | ND25: =COUNTIF(C27:NC27,"SORUN") -> 0
B26: Toplantı Odaları | ND26: =COUNTIF(C28:NC28,"SORUN") -> 0
B27: Asansör | ND27: =COUNTIF(C29:NC29,"SORUN") -> 0
B28: Diğer | ND28: =COUNTIF(C30:NC30,"SORUN") -> 0
A29: Elektrik-Isıtma-Boyama | B29: Aplik, Floresan, Spot vb. | ND29: =COUNTIF(C31:NC31,"SORUN") -> 0
B30: Prizler ve Elektrik Anahtarları | ND30: =COUNTIF(C32:NC32,"SORUN") -> 0
B31: Havalandırma | ND31: =COUNTIF(C33:NC33,"SORUN") -> 0
B32: Petekler | ND32: =COUNTIF(C34:NC34,"SORUN") -> 0
B33: Boya-Badana İhtiyacı | ND33: =COUNTIF(C35:NC35,"SORUN") -> 0
B34: Diğer | ND34: =COUNTIF(C36:NC36,"SORUN") -> 0

Sheet Kapanış Denetimi
