Workbook

Sheet General information
A1: Calculation of productive hours
A3: Days in a year | B3: 365
A4: Weekends | B4: =-104 -> -104
A5: Annual Holidays | B5: -22
A6: National Holidays | B6: -16
A7: Illness/Others | B7: -7
A8: Workable days in a year | B8: =SUM(B3:B7) -> 216
A9: workable hours per day | B9: 8
A10: total hours in a year | B10: =B8*B9 -> 1728 | C10: => please respect this total in your timesheet
A13: General information
A14: 1. All the activities are listed in the timesheet
A15: 2. Timerecording is only requested for EU projects but the other activities are also listed because all time need to be recorded
A16: 3. Weekends and holidays are marked
A17: 4. Every month is a different sheet and there is one sheet with an overview of the year
A20: Guidelines for completing the timesheets
A21: 1.Fill out your name (top and bottom of the timesheet) and the name of the person who need to sign your timsesheet
A22: 2. The timesheet need to be signed by the PI
A23: 3. The signature date need to be the end of the corresponding month or latest the beginning of the next month
A24: 4. For each working day you need to record 8 hours except the marked days (weekends and holidays)
A25: 5. Don't fill out any hours in the weekends or holidays unless a meeting took place at that time
A26: 6. Make sure that the days you are abroad for a meeting are completed correctly in the timesheets e.g.
... A32: The reporting of personnel cost need to be done in PM.
A35: The calculation of a PM= | B35: Total numbers completed during a reporting period for a project
D36: 144
A40: Sorular
A41: 1. Productive hours hesaplaması günde 8 saat ile yapılıyor ve bu haftalık 40 saat oluyor, sözleşmelerde 45 saat yazıyor, bunun açıklaması nasıl yapılabilir?
A42: 2. PI timesheet doldurduğu zaman onay imzasını kim atmalı? DEKAN
A43: 3. Burslu öğrenciler kaç saat ve nasıl timesheet doldurması gerekiyor, proje dişindaki saatleri doldurmaları gerekiyormu? Bununla ilgili bir yönerge varmı?
A44: 4. Tübitak projelerinide toplu olarak other projects kısmına ekledim, bu gereklimi? Santez, Aselsan, …. başka projelerinde eklenmesi gerekiyormu?
A45: 5. Ders dışında bir prof projeler'e ne kadar zaman harcayabilir? En fazla ne kadar proje geliri elde edebilir?
A46: 6. Raporlama dönemi genelde 1 ocak - 31 aralık olmuyor, bu durumlarda hourly rate nasıl belirlenecek?
A47: 7. Timesheetlerde günde 8 saatten fazla yazılmasına izin verecekmiyiz?

Sheet TOTAL
A1: Organisation: | B1: Sabancı University
A2: Person :
C6: January | D6: February | E6: March | F6: April | G6: May | H6: June | I6: July | J6: August | K6: September | L6: October | M6: November | N6: December | O6: Total
A7: EU-Projects
A8: Project X | C8: ='1'!AH10 -> 0 | D8: ='2'!AE10 -> 0 | E8: ='3'!AH10 -> 0 | F8: ='4'!AG10 -> 0 | G8: ='5'!AH10 -> 0 | H8: ='6'!AG10 -> 0 | I8: ='7'!AH10 -> 0 | J8: ='8'!AH10 -> 0 | K8: ='9'!AG10 -> 0 | L8: ='10'!AH10 -> 0 | M8: ='11'!AG10 -> 0 | N8: ='12'!AH10 -> 0 | O8: =SUM(C8:N8) -> 0
A9: RTD | B9: WP1 | C9: ='1'!AH11 -> 0 | D9: ='2'!AE11 -> 0 | E9: ='3'!AH11 -> 0 | F9: ='4'!AG11 -> 0 | G9: ='5'!AH11 -> 0 | H9: ='6'!AG11 -> 0 | I9: ='7'!AH11 -> 0 | J9: ='8'!AH11 -> 0 | K9: ='9'!AG11 -> 0 | L9: ='10'!AH11 -> 0 | M9: ='11'!AG11 -> 0 | N9: ='12'!AH11 -> 0 | O9: =SUM(C9:N9) -> 0
A10: RTD | B10: WP2 | C10: ='1'!AH12 -> 0 | D10: ='2'!AE12 -> 0 | E10: ='3'!AH12 -> 0 | F10: ='4'!AG12 -> 0 | G10: ='5'!AH12 -> 0 | H10: ='6'!AG12 -> 0 | I10: ='7'!AH12 -> 0 | J10: ='8'!AH12 -> 0 | K10: ='9'!AG12 -> 0 | L10: ='10'!AH12 -> 0 | M10: ='11'!AG12 -> 0 | N10: ='12'!AH12 -> 0 | O10: =SUM(C10:N10) -> 0
A11: RTD | B11: WP3 | C11: ='1'!AH13 -> 0 | D11: ='2'!AE13 -> 0 | E11: ='3'!AH13 -> 0 | F11: ='4'!AG13 -> 0 | G11: ='5'!AH13 -> 0 | H11: ='6'!AG13 -> 0 | I11: ='7'!AH13 -> 0 | J11: ='8'!AH13 -> 0 | K11: ='9'!AG13 -> 0 | L11: ='10'!AH13 -> 0 | M11: ='11'!AG13 -> 0 | N11: ='12'!AH13 -> 0 | O11: =SUM(C11:N11) -> 0
A12: RTD | B12: WP6 | C12: ='1'!AH14 -> 0 | D12: ='2'!AE14 -> 0 | E12: ='3'!AH14 -> 0 | F12: ='4'!AG14 -> 0 | G12: ='5'!AH14 -> 0 | H12: ='6'!AG14 -> 0 | I12: ='7'!AH14 -> 0 | J12: ='8'!AH14 -> 0 | K12: ='9'!AG14 -> 0 | L12: ='10'!AH14 -> 0 | M12: ='11'!AG14 -> 0 | N12: ='12'!AH14 -> 0 | O12: =SUM(C12:N12) -> 0
A13: OTH | B13: WP9 | C13: ='1'!AH15 -> 0 | D13: ='2'!AE15 -> 0 | E13: ='3'!AH15 -> 0 | F13: ='4'!AG15 -> 0 | G13: ='5'!AH15 -> 0 | H13: ='6'!AG15 -> 0 | I13: ='7'!AH15 -> 0 | J13: ='8'!AH15 -> 0 | K13: ='9'!AG15 -> 0 | L13: ='10'!AH15 -> 0 | M13: ='11'!AG15 -> 0 | N13: ='12'!AH15 -> 0 | O13: =SUM(C13:N13) -> 0
A14: MNGT | B14: WP11 | C14: ='1'!AH16 -> 0 | D14: ='2'!AE16 -> 0 | E14: ='3'!AH16 -> 0 | F14: ='4'!AG16 -> 0 | G14: ='5'!AH16 -> 0 | H14: ='6'!AG16 -> 0 | I14: ='7'!AH16 -> 0 | J14: ='8'!AH16 -> 0 | K14: ='9'!AG16 -> 0 | L14: ='10'!AH16 -> 0 | M14: ='11'!AG16 -> 0 | N14: ='12'!AH16 -> 0 | O14: =SUM(C14:N14) -> 0
A15: Project Y | C15: ='1'!AH17 -> 0 | D15: ='2'!AE17 -> 0 | E15: ='3'!AH17 -> 0 | F15: ='4'!AG17 -> 0 | G15: ='5'!AH17 -> 0 | H15: ='6'!AG17 -> 0 | I15: ='7'!AH17 -> 0 | J15: ='8'!AH17 -> 0 | K15: ='9'!AG17 -> 0 | L15: ='10'!AH17 -> 0 | M15: ='11'!AG17 -> 0 | N15: ='12'!AH17 -> 0 | O15: =SUM(C15:N15) -> 0
A16: RTD | B16: WP1 | C16: ='1'!AH18 -> 0 | D16: ='2'!AE18 -> 0 | E16: ='3'!AH18 -> 0 | F16: ='4'!AG18 -> 0 | G16: ='5'!AH18 -> 0 | H16: ='6'!AG18 -> 0 | I16: ='7'!AH18 -> 0 | J16: ='8'!AH18 -> 0 | K16: ='9'!AG18 -> 0 | L16: ='10'!AH18 -> 0 | M16: ='11'!AG18 -> 0 | N16: ='12'!AH18 -> 0 | O16: =SUM(C16:N16) -> 0
A17: RTD | B17: WP2 | C17: ='1'!AH19 -> 0 | D17: ='2'!AE19 -> 0 | E17: ='3'!AH19 -> 0 | F17: ='4'!AG19 -> 0 | G17: ='5'!AH19 -> 0 | H17: ='6'!AG19 -> 0 | I17: ='7'!AH19 -> 0 | J17: ='8'!AH19 -> 0 | K17: ='9'!AG19 -> 0 | L17: ='10'!AH19 -> 0 | M17: ='11'!AG19 -> 0 | N17: ='12'!AH19 -> 0 | O17: =SUM(C17:N17) -> 0
A18: RTD | B18: WP3 | C18: ='1'!AH20 -> 0 | D18: ='2'!AE20 -> 0 | E18: ='3'!AH20 -> 0 | F18: ='4'!AG20 -> 0 | G18: ='5'!AH20 -> 0 | H18: ='6'!AG20 -> 0 | I18: ='7'!AH20 -> 0 | J18: ='8'!AH20 -> 0 | K18: ='9'!AG20 -> 0 | L18: ='10'!AH20 -> 0 | M18: ='11'!AG20 -> 0 | N18: ='12'!AH20 -> 0 | O18: =SUM(C18:N18) -> 0
A19: RTD | B19: WP4 | C19: ='1'!AH21 -> 0 | D19: ='2'!AE21 -> 0 | E19: ='3'!AH21 -> 0 | F19: ='4'!AG21 -> 0 | G19: ='5'!AH21 -> 0 | H19: ='6'!AG21 -> 0 | I19: ='7'!AH21 -> 0 | J19: ='8'!AH21 -> 0 | K19: ='9'!AG21 -> 0 | L19: ='10'!AH21 -> 0 | M19: ='11'!AG21 -> 0 | N19: ='12'!AH21 -> 0 | O19: =SUM(C19:N19) -> 0
A20: RTD | B20: WP6 | C20: ='1'!AH22 -> 0 | D20: ='2'!AE22 -> 0 | E20: ='3'!AH22 -> 0 | F20: ='4'!AG22 -> 0 | G20: ='5'!AH22 -> 0 | H20: ='6'!AG22 -> 0 | I20: ='7'!AH22 -> 0 | J20: ='8'!AH22 -> 0 | K20: ='9'!AG22 -> 0 | L20: ='10'!AH22 -> 0 | M20: ='11'!AG22 -> 0 | N20: ='12'!AH22 -> 0 | O20: =SUM(C20:N20) -> 0
A21: OTH | B21: WP7 | C21: ='1'!AH23 -> 0 | D21: ='2'!AE23 -> 0 | E21: ='3'!AH23 -> 0 | F21: ='4'!AG23 -> 0 | G21: ='5'!AH23 -> 0 | H21: ='6'!AG23 -> 0 | I21: ='7'!AH23 -> 0 | J21: ='8'!AH23 -> 0 | K21: ='9'!AG23 -> 0 | L21: ='10'!AH23 -> 0 | M21: ='11'!AG23 -> 0 | N21: ='12'!AH23 -> 0 | O21: =SUM(C21:N21) -> 0
A22: MNGT | B22: WP8 | C22: ='1'!AH24 -> 0 | D22: ='2'!AE24 -> 0 | E22: ='3'!AH24 -> 0 | F22: ='4'!AG24 -> 0 | G22: ='5'!AH24 -> 0 | H22: ='6'!AG24 -> 0 | I22: ='7'!AH24 -> 0 | J22: ='8'!AH24 -> 0 | K22: ='9'!AG24 -> 0 | L22: ='10'!AH24 -> 0 | M22: ='11'!AG24 -> 0 | N22: ='12'!AH24 -> 0 | O22: =SUM(C22:N22) -> 0
A23: Total EU Projects | C23: ='1'!AH25 -> 0 | D23: ='2'!AE25 -> 0 | E23: ='3'!AH25 -> 0 | F23: ='4'!AG25 -> 0 | G23: ='5'!AH25 -> 0 | H23: ='6'!AG25 -> 0 | I23: ='7'!AH25 -> 0 | J23: ='8'!AH25 -> 0 | K23: ='9'!AG25 -> 0 | L23: ='10'!AH25 -> 0 | M23: ='11'!AG25 -> 0 | N23: ='12'!AH25 -> 0 | O23: =SUM(C23:N23) -> 0
C24: ='1'!AH26 -> 0 | D24: ='2'!AE26 -> 0 | E24: ='3'!AH26 -> 0 | F24: ='4'!AG26 -> 0 | G24: ='5'!AH26 -> 0 | H24: ='6'!AG26 -> 0 | I24: ='7'!AH26 -> 0 | J24: ='8'!AH26 -> 0 | K24: ='9'!AG26 -> 0 | L24: ='10'!AH26 -> 0 | M24: ='11'!AG26 -> 0 | N24: ='12'!AH26 -> 0 | O24: =SUM(C24:N24) -> 0
A25: Other Productive Hours | O25: =SUM(C25:N25) -> 0
A26: Other projects | C26: ='1'!AH28 -> 0 | D26: ='2'!AE28 -> 0 | E26: ='3'!AH28 -> 0 | F26: ='4'!AG28 -> 0 | G26: ='5'!AH28 -> 0 | H26: ='6'!AG28 -> 0 | I26: ='7'!AH28 -> 0 | J26: ='8'!AH28 -> 0 | K26: ='9'!AG28 -> 0 | L26: ='10'!AH28 -> 0 | M26: ='11'!AG28 -> 0 | N26: ='12'!AH28 -> 0 | O26: =SUM(C26:N26) -> 0
A27: Teaching | C27: ='1'!AH29 -> 0 | D27: ='2'!AE29 -> 0 | E27: ='3'!AH29 -> 0 | F27: ='4'!AG29 -> 0 | G27: ='5'!AH29 -> 0 | H27: ='6'!AG29 -> 0 | I27: ='7'!AH29 -> 0 | J27: ='8'!AH29 -> 0 | K27: ='9'!AG29 -> 0 | L27: ='10'!AH29 -> 0 | M27: ='11'!AG29 -> 0 | N27: ='12'!AH29 -> 0 | O27: =SUM(C27:N27) -> 0
A28: xxxxx | C28: ='1'!AH30 -> 0 | D28: ='2'!AE30 -> 0 | E28: ='3'!AH30 -> 0 | F28: ='4'!AG30 -> 0 | G28: ='5'!AH30 -> 0 | H28: ='6'!AG30 -> 0 | I28: ='7'!AH30 -> 0 | J28: ='8'!AH30 -> 0 | K28: ='9'!AG30 -> 0 | L28: ='10'!AH30 -> 0 | M28: ='11'!AG30 -> 0 | N28: ='12'!AH30 -> 0 | O28: =SUM(C28:N28) -> 0
A29: yyyyy | C29: ='1'!AH31 -> 0 | D29: ='2'!AE31 -> 0 | E29: ='3'!AH31 -> 0 | F29: ='4'!AG31 -> 0 | G29: ='5'!AH31 -> 0 | H29: ='6'!AG31 -> 0 | I29: ='7'!AH31 -> 0 | J29: ='8'!AH31 -> 0 | K29: ='9'!AG31 -> 0 | L29: ='10'!AH31 -> 0 | M29: ='11'!AG31 -> 0 | N29: ='12'!AH31 -> 0 | O29: =SUM(C29:N29) -> 0
A30: zzzzz | C30: ='1'!AH32 -> 0 | D30: ='2'!AE32 -> 0 | E30: ='3'!AH32 -> 0 | F30: ='4'!AG32 -> 0 | G30: ='5'!AH32 -> 0 | H30: ='6'!AG32 -> 0 | I30: ='7'!AH32 -> 0 | J30: ='8'!AH32 -> 0 | K30: ='9'!AG32 -> 0 | L30: ='10'!AH32 -> 0 | M30: ='11'!AG32 -> 0 | N30: ='12'!AH32 -> 0 | O30: =SUM(C30:N30) -> 0
A31: Total Other Productive Hours | C31: ='1'!AH33 -> 0 | D31: ='2'!AE33 -> 0 | E31: ='3'!AH33 -> 0 | F31: ='4'!AG33 -> 0 | G31: ='5'!AH33 -> 0 | H31: ='6'!AG33 -> 0 | I31: ='7'!AH33 -> 0 | J31: ='8'!AH33 -> 0 | K31: ='9'!AG33 -> 0 | L31: ='10'!AH33 -> 0 | M31: ='11'!AG33 -> 0 | N31: ='12'!AH33 -> 0 | O31: =SUM(C31:N31) -> 0
C32: ='1'!AH34 -> 0 | D32: ='2'!AE34 -> 0 | E32: ='3'!AH34 -> 0 | F32: ='4'!AG34 -> 0 | G32: ='5'!AH34 -> 0 | H32: ='6'!AG34 -> 0 | I32: ='7'!AH34 -> 0 | J32: ='8'!AH34 -> 0 | K32: ='9'!AG34 -> 0 | L32: ='10'!AH34 -> 0 | M32: ='11'!AG34 -> 0 | N32: ='12'!AH34 -> 0 | O32: =SUM(C32:N32) -> 0
A33: Total Productive Hours | C33: ='1'!AH35 -> 0 | D33: ='2'!AE35 -> 0 | E33: ='3'!AH35 -> 0 | F33: ='4'!AG35 -> 0 | G33: ='5'!AH35 -> 0 | H33: ='6'!AG35 -> 0 | I33: ='7'!AH35 -> 0 | J33: ='8'!AH35 -> 0 | K33: ='9'!AG35 -> 0 | L33: ='10'!AH35 -> 0 | M33: ='11'!AG35 -> 0 | N33: ='12'!AH35 -> 0 | O33: =SUM(C33:N33) -> 0
C34: ='1'!AH36 -> 0 | D34: ='2'!AE36 -> 0 | E34: ='3'!AH36 -> 0 | F34: ='4'!AG36 -> 0 | G34: ='5'!AH36 -> 0 | H34: ='6'!AG36 -> 0 | I34: ='7'!AH36 -> 0 | J34: ='8'!AH36 -> 0 | K34: ='9'!AG36 -> 0 | L34: ='10'!AH36 -> 0 | M34: ='11'!AG36 -> 0 | N34: ='12'!AH36 -> 0 | O34: =SUM(C34:N34) -> 0
A35: Non Productive Hours | O35: =SUM(C35:N35) -> 0
A36: Annual Leave | C36: ='1'!AH38 -> 0 | D36: ='2'!AE38 -> 0 | E36: ='3'!AH38 -> 0 | F36: ='4'!AG38 -> 0 | G36: ='5'!AH38 -> 0 | H36: ='6'!AG38 -> 0 | I36: ='7'!AH38 -> 0 | J36: ='8'!AH38 -> 0 | K36: ='9'!AG38 -> 0 | L36: ='10'!AH38 -> 0 | M36: ='11'!AG38 -> 0 | N36: ='12'!AH38 -> 0 | O36: =SUM(C36:N36) -> 0
A37: Special Leave | C37: ='1'!AH39 -> 0 | D37: ='2'!AE39 -> 0 | E37: ='3'!AH39 -> 0 | F37: ='4'!AG39 -> 0 | G37: ='5'!AH39 -> 0 | H37: ='6'!AG39 -> 0 | I37: ='7'!AH39 -> 0 | J37: ='8'!AH39 -> 0 | K37: ='9'!AG39 -> 0 | L37: ='10'!AH39 -> 0 | M37: ='11'!AG39 -> 0 | N37: ='12'!AH39 -> 0 | O37: =SUM(C37:N37) -> 0
A38: Illness | C38: ='1'!AH40 -> 0 | D38: ='2'!AE40 -> 0 | E38: ='3'!AH40 -> 0 | F38: ='4'!AG40 -> 0 | G38: ='5'!AH40 -> 0 | H38: ='6'!AG40 -> 0 | I38: ='7'!AH40 -> 0 | J38: ='8'!AH40 -> 0 | K38: ='9'!AG40 -> 0 | L38: ='10'!AH40 -> 0 | M38: ='11'!AG40 -> 0 | N38: ='12'!AH40 -> 0 | O38: =SUM(C38:N38) -> 0
A39: Training / internal meetings | C39: ='1'!AH41 -> 0 | D39: ='2'!AE41 -> 0 | E39: ='3'!AH41 -> 0 | F39: ='4'!AG41 -> 0 | G39: ='5'!AH41 -> 0 | H39: ='6'!AG41 -> 0 | I39: ='7'!AH41 -> 0 | J39: ='8'!AH41 -> 0 | K39: ='9'!AG41 -> 0 | L39: ='10'!AH41 -> 0 | M39: ='11'!AG41 -> 0 | N39: ='12'!AH41 -> 0 | O39: =SUM(C39:N39) -> 0
A40: Total Non-Productive Hours | C40: ='1'!AH42 -> 0 | D40: ='2'!AE42 -> 0 | E40: ='3'!AH42 -> 0 | F40: ='4'!AG42 -> 0 | G40: ='5'!AH42 -> 0 | H40: ='6'!AG42 -> 0 | I40: ='7'!AH42 -> 0 | J40: ='8'!AH42 -> 0 | K40: ='9'!AG42 -> 0 | L40: ='10'!AH42 -> 0 | M40: ='11'!AG42 -> 0 | N40: ='12'!AH42 -> 0 | O40: =SUM(C40:N40) -> 0
C41: ='1'!AH43 -> 0 | D41: ='2'!AE43 -> 0 | E41: ='3'!AH43 -> 0 | F41: ='4'!AG43 -> 0 | G41: ='5'!AH43 -> 0 | H41: ='6'!AG43 -> 0 | I41: ='7'!AH43 -> 0 | J41: ='8'!AH43 -> 0 | K41: ='9'!AG43 -> 0 | L41: ='10'!AH43 -> 0 | M41: ='11'!AG43 -> 0 | N41: ='12'!AH43 -> 0 | O41: =SUM(C41:N41) -> 0
A42: Total Hours (Productive + Non Productive) | C42: ='1'!AH44 -> 0 | D42: ='2'!AE44 -> 0 | E42: ='3'!AH44 -> 0 | F42: ='4'!AG44 -> 0 | G42: ='5'!AH44 -> 0 | H42: ='6'!AG44 -> 0 | I42: ='7'!AH44 -> 0 | J42: ='8'!AH44 -> 0 | K42: ='9'!AG44 -> 0 | L42: ='10'!AH44 -> 0 | M42: ='11'!AG44 -> 0 | N42: ='12'!AH44 -> 0 | O42: =SUM(C42:N42) -> 0
A44: Signed: | C44: Date and Signature
...

Sheet 1
A1: Organisation: | B1: Sabancı University
A2: Person : | B2: =TOTAL!B2 -> 0
A4: Month | B4: January 2017
A6: Date | C6: 1 | D6: 2 | E6: 3 | F6: 4 | G6: 5 | H6: 6 | I6: 7 | J6: 8 | K6: 9 | L6: 10 | M6: 11 | N6: 12 | O6: 13 | P6: 14 | Q6: 15 | R6: 16 | S6: 17 | T6: 18 | U6: 19 | V6: 20 | W6: 21 | X6: 22 | Y6: 23 | Z6: 24 | AA6: 25 | AB6: 26 | AC6: 27 | AD6: 28 | AE6: 29 | AF6: 30 | AG6: 31 | AH6: Total
A7: Day | C7: Su | D7: Mo | E7: Tu | F7: W | G7: Th | H7: F | I7: Sa | J7: Su | K7: Mo | L7: Tu | M7: W | N7: Th | O7: F | P7: Sa | Q7: Su | R7: Mo | S7: Tu | T7: W | U7: Th | V7: F | W7: Sa | X7: Su | Y7: Mo | Z7: Tu | AA7: W | AB7: Th | AC7: F | AD7: Sa | AE7: Su | AF7: Mo | AG7: Tu
A9: EU-Projects
A10: Project X | C10: =SUM(C11:C16) -> 0 | D10: =SUM(D11:D16) -> 0 | E10: =SUM(E11:E16) -> 0 | F10: =SUM(F11:F16) -> 0 | G10: =SUM(G11:G16) -> 0 | H10: =SUM(H11:H16) -> 0 | I10: =SUM(I11:I16) -> 0 | J10: =SUM(J11:J16) -> 0 | ... AH10: =SUM(AH11:AH16) -> 0
A11: RTD | B11: WP1 | AH11: =SUM(C11:AG11) -> 0
A12: RTD | B12: WP2 | AH12: =SUM(C12:AG12) -> 0
A13: RTD | B13: WP3 | AH13: =SUM(C13:AG13) -> 0
A14: RTD | B14: WP6 | AH14: =SUM(C14:AG14) -> 0
A15: OTH | B15: WP9 | AH15: =SUM(C15:AG15) -> 0
A16: MNGT | B16: WP11 | AH16: =SUM(C16:AG16) -> 0
A17: Project Y | C17: =SUM(C18:C24) -> 0 | D17: =SUM(D18:D24) -> 0 | E17: =SUM(E18:E24) -> 0 | F17: =SUM(F18:F24) -> 0 | G17: =SUM(G18:G24) -> 0 | H17: =SUM(H18:H24) -> 0 | I17: =SUM(I18:I24) -> 0 | J17: =SUM(J18:J24) -> 0 | ... AH17: =SUM(AH18:AH24) -> 0
A18: RTD | B18: WP1 | AH18: =SUM(C18:AG18) -> 0
A19: RTD | B19: WP2 | AH19: =SUM(C19:AG19) -> 0
A20: RTD | B20: WP3 | AH20: =SUM(C20:AG20) -> 0
A21: RTD | B21: WP4 | AH21: =SUM(C21:AG21) -> 0
A22: RTD | B22: WP6 | AH22: =SUM(C22:AG22) -> 0
A23: OTH | B23: WP7 | AH23: =SUM(C23:AG23) -> 0
A24: MNGT | B24: WP8 | AH24: =SUM(C24:AG24) -> 0
A25: Total EU Projects | C25: =C10+C17 -> 0 | D25: =D10+D17 -> 0 | E25: =E10+E17 -> 0 | F25: =F10+F17 -> 0 | G25: =G10+G17 -> 0 | H25: =H10+H17 -> 0 | I25: =I10+I17 -> 0 | J25: =J10+J17 -> 0 | ... AH25: =AH10+AH17 -> 0
A27: Other Productive Hours
A28: Other projects | AH28: =SUM(C28:AG28) -> 0
A29: Teaching | AH29: =SUM(C29:AG29) -> 0
A30: xxxxx | AH30: =SUM(C30:AG30) -> 0
A31: yyyyy | AH31: =SUM(C31:AG31) -> 0
A32: zzzzz | AH32: =SUM(C32:AG32) -> 0
A33: Total Other Productive Hours | C33: =SUM(C28:C32) -> 0 | D33: =SUM(D28:D32) -> 0 | E33: =SUM(E28:E32) -> 0 | F33: =SUM(F28:F32) -> 0 | G33: =SUM(G28:G32) -> 0 | H33: =SUM(H28:H32) -> 0 | I33: =SUM(I28:I32) -> 0 | J33: =SUM(J28:J32) -> 0 | ... AH33: =SUM(AH28:AH32) -> 0
A35: Total Productive Hours | C35: =C25+C33 -> 0 | D35: =D25+D33 -> 0 | E35: =E25+E33 -> 0 | F35: =F25+F33 -> 0 | G35: =G25+G33 -> 0 | H35: =H25+H33 -> 0 | I35: =I25+I33 -> 0 | J35: =J25+J33 -> 0 | ... AH35: =AH25+AH33 -> 0
A37: Non Productive Hours
A38: Annual Leave | AH38: =SUM(C38:AG38) -> 0
A39: Special Leave | AH39: =SUM(C39:AG39) -> 0
A40: Illness | AH40: =SUM(C40:AG40) -> 0
A41: Training / internal meetings | AH41: =SUM(C41:AG41) -> 0
A42: Total Non-Productive Hours | C42: =SUM(C38:C41) -> 0 | D42: =SUM(D38:D41) -> 0 | E42: =SUM(E38:E41) -> 0 | F42: =SUM(F38:F41) -> 0 | G42: =SUM(G38:G41) -> 0 | H42: =SUM(H38:H41) -> 0 | I42: =SUM(I38:I41) -> 0 | J42: =SUM(J38:J41) -> 0 | ... AH42: =SUM(AH38:AH41) -> 0
AH43: =SUM(C43:AG43) -> 0
A44: Total Hours (Productive + Non Productive) | C44: =C35+C42 -> 0 | D44: =D35+D42 -> 0 | E44: =E35+E42 -> 0 | F44: =F35+F42 -> 0 | G44: =G35+G42 -> 0 | H44: =H35+H42 -> 0 | I44: =I35+I42 -> 0 | J44: =J35+J42 -> 0 | ... AH44: =AH35+AH42 -> 0
A46: Signed: | C46: Date and Signature
A47: =TOTAL!A45 -> 0 | C47: 31.01.2017
...

Sheet 2
A1: Organisation: | B1: Sabancı University
A2: Person : | B2: =TOTAL!B2 -> 0
A4: Month | B4: February 2017
A6: Date | C6: 1 | D6: 2 | E6: 3 | F6: 4 | G6: 5 | H6: 6 | I6: 7 | J6: 8 | K6: 9 | L6: 10 | M6: 11 | N6: 12 | O6: 13 | P6: 14 | Q6: 15 | R6: 16 | S6: 17 | T6: 18 | U6: 19 | V6: 20 | W6: 21 | X6: 22 | Y6: 23 | Z6: 24 | AA6: 25 | AB6: 26 | AC6: 27 | AD6: 28 | AE6: Total
A7: Day | C7: W | D7: Th | E7: F | F7: Sa | G7: Su | H7: Mo | I7: Tu | J7: W | K7: Th | L7: F | M7: Sa | N7: Su | O7: Mo | P7: Tu | Q7: W | R7: Th | S7: F | T7: Sa | U7: Su | V7: Mo | W7: Tu | X7: W | Y7: Th | Z7: F | AA7: Sa | AB7: Su | AC7: Mo | AD7: Tu
A9: EU-Projects
A10: Project X | C10: =SUM(C11:C16) -> 0 | D10: =SUM(D11:D16) -> 0 | E10: =SUM(E11:E16) -> 0 | F10: =SUM(F11:F16) -> 0 | G10: =SUM(G11:G16) -> 0 | H10: =SUM(H11:H16) -> 0 | I10: =SUM(I11:I16) -> 0 | J10: =SUM(J11:J16) -> 0 | ... AE10: =SUM(AE11:AE16) -> 0
A11: RTD | B11: WP1 | AE11: =SUM(C11:AD11) -> 0
A12: RTD | B12: WP2 | AE12: =SUM(C12:AD12) -> 0
A13: RTD | B13: WP3 | AE13: =SUM(C13:AD13) -> 0
A14: RTD | B14: WP6 | AE14: =SUM(C14:AD14) -> 0
A15: OTH | B15: WP9 | AE15: =SUM(C15:AD15) -> 0
A16: MNGT | B16: WP11 | AE16: =SUM(C16:AD16) -> 0
A17: Project Y | C17: =SUM(C18:C24) -> 0 | D17: =SUM(D18:D24) -> 0 | E17: =SUM(E18:E24) -> 0 | F17: =SUM(F18:F24) -> 0 | G17: =SUM(G18:G24) -> 0 | H17: =SUM(H18:H24) -> 0 | I17: =SUM(I18:I24) -> 0 | J17: =SUM(J18:J24) -> 0 | ... AD17: =SUM(AD18:AD24) -> 0 | AE17: =SUM(C17:AD17) -> 0
A18: RTD | B18: WP1 | AE18: =SUM(C18:AD18) -> 0
A19: RTD | B19: WP2 | AE19: =SUM(C19:AD19) -> 0
A20: RTD | B20: WP3 | AE20: =SUM(C20:AD20) -> 0
A21: RTD | B21: WP4 | AE21: =SUM(C21:AD21) -> 0
A22: RTD | B22: WP6 | AE22: =SUM(C22:AD22) -> 0
A23: OTH | B23: WP7 | AE23: =SUM(C23:AD23) -> 0
A24: MNGT | B24: WP8 | AE24: =SUM(C24:AD24) -> 0
A25: Total EU Projects | C25: =C10+C17 -> 0 | D25: =D10+D17 -> 0 | E25: =E10+E17 -> 0 | F25: =F10+F17 -> 0 | G25: =G10+G17 -> 0 | H25: =H10+H17 -> 0 | I25: =I10+I17 -> 0 | J25: =J10+J17 -> 0 | ... AD25: =AD10+AD17 -> 0 | AE25: =SUM(C25:AD25) -> 0
AE26: =SUM(C26:AD26) -> 0
A27: Other Productive Hours | AE27: =SUM(C27:AD27) -> 0
A28: Other projects | AE28: =SUM(C28:AD28) -> 0
A29: Teaching | AE29: =SUM(C29:AD29) -> 0
A30: xxxxx | AE30: =SUM(C30:AD30) -> 0
A31: yyyyy | AE31: =SUM(C31:AD31) -> 0
A32: zzzzz | AE32: =SUM(C32:AD32) -> 0
A33: Total Other Productive Hours | C33: =SUM(C28:C32) -> 0 | D33: =SUM(D28:D32) -> 0 | E33: =SUM(E28:E32) -> 0 | F33: =SUM(F28:F32) -> 0 | G33: =SUM(G28:G32) -> 0 | H33: =SUM(H28:H32) -> 0 | I33: =SUM(I28:I32) -> 0 | J33: =SUM(J28:J32) -> 0 | ... AD33: =SUM(AD28:AD32) -> 0 | AE33: =SUM(C33:AD33) -> 0
AE34: =SUM(C34:AD34) -> 0
A35: Total Productive Hours | C35: =C25+C33 -> 0 | D35: =D25+D33 -> 0 | E35: =E25+E33 -> 0 | F35: =F25+F33 -> 0 | G35: =G25+G33 -> 0 | H35: =H25+H33 -> 0 | I35: =I25+I33 -> 0 | J35: =J25+J33 -> 0 | ... AD35: =AD25+AD33 -> 0 | AE35: =SUM(C35:AD35) -> 0
AE36: =SUM(C36:AD36) -> 0
A37: Non Productive Hours | AE37: =SUM(C37:AD37) -> 0
A38: Annual Leave | AE38: =SUM(C38:AD38) -> 0
A39: Special Leave | AE39: =SUM(C39:AD39) -> 0
A40: Illness | AE40: =SUM(C40:AD40) -> 0
A41: Training / internal meetings | AE41: =SUM(C41:AD41) -> 0
A42: Total Non-Productive Hours | C42: =SUM(C38:C41) -> 0 | D42: =SUM(D38:D41) -> 0 | E42: =SUM(E38:E41) -> 0 | F42: =SUM(F38:F41) -> 0 | G42: =SUM(G38:G41) -> 0 | H42: =SUM(H38:H41) -> 0 | I42: =SUM(I38:I41) -> 0 | J42: =SUM(J38:J41) -> 0 | ... AD42: =SUM(AD38:AD41) -> 0 | AE42: =SUM(C42:AD42) -> 0
AE43: =SUM(C43:AD43) -> 0
...

Sheet 3
A1: Organisation: | B1: Sabancı University
A2: Person : | B2: =TOTAL!B2 -> 0
A4: Month | B4: March 2017
A6: Date | C6: 1 | D6: 2 | E6: 3 | F6: 4 | G6: 5 | H6: 6 | I6: 7 | J6: 8 | K6: 9 | L6: 10 | M6: 11 | N6: 12 | O6: 13 | P6: 14 | Q6: 15 | R6: 16 | S6: 17 | T6: 18 | U6: 19 | V6: 20 | W6: 21 | X6: 22 | Y6: 23 | Z6: 24 | AA6: 25 | AB6: 26 | AC6: 27 | AD6: 28 | AE6: 29 | AF6: 30 | AG6: 31 | AH6: Total
A7: Day | C7: W | D7: Th | E7: F | F7: Sa | G7: Su | H7: Mo | I7: Tu | J7: W | K7: Th | L7: F | M7: Sa | N7: Su | O7: Mo | P7: Tu | Q7: W | R7: Th | S7: F | T7: Sa | U7: Su | V7: Mo | W7: Tu | X7: W | Y7: Th | Z7: F | AA7: Sa | AB7: Su | AC7: Mo | AD7: Tu | AE7: We | AF7: Th | AG7: F
A9: EU-Projects
A10: Project X | C10: =SUM(C11:C16) -> 0 | D10: =SUM(D11:D16) -> 0 | E10: =SUM(E11:E16) -> 0 | F10: =SUM(F11:F16) -> 0 | G10: =SUM(G11:G16) -> 0 | H10: =SUM(H11:H16) -> 0 | I10: =SUM(I11:I16) -> 0 | J10: =SUM(J11:J16) -> 0 | ... AH10: =SUM(AH11:AH16) -> 0
A11: RTD | B11: WP1 | AH11: =SUM(C11:AG11) -> 0
A12: RTD | B12: WP2 | AH12: =SUM(C12:AG12) -> 0
A13: RTD | B13: WP3 | AH13: =SUM(C13:AG13) -> 0
A14: RTD | B14: WP6 | AH14: =SUM(C14:AG14) -> 0
A15: OTH | B15: WP9 | AH15: =SUM(C15:AG15) -> 0
A16: MNGT | B16: WP11 | AH16: =SUM(C16:AG16) -> 0
A17: Project Y | C17: =SUM(C18:C24) -> 0 | D17: =SUM(D18:D24) -> 0 | E17: =SUM(E18:E24) -> 0 | F17: =SUM(F18:F24) -> 0 | G17: =SUM(G18:G24) -> 0 | H17: =SUM(H18:H24) -> 0 | I17: =SUM(I18:I24) -> 0 | J17: =SUM(J18:J24) -> 0 | ... AH17: =SUM(AH18:AH24) -> 0
A18: RTD | B18: WP1 | AH18: =SUM(C18:AG18) -> 0
A19: RTD | B19: WP2 | AH19: =SUM(C19:AG19) -> 0
A20: RTD | B20: WP3 | AH20: =SUM(C20:AG20) -> 0
A21: RTD | B21: WP4 | AH21: =SUM(C21:AG21) -> 0
A22: RTD | B22: WP6 | AH22: =SUM(C22:AG22) -> 0
A23: OTH | B23: WP7 | AH23: =SUM(C23:AG23) -> 0
A24: MNGT | B24: WP8 | AH24: =SUM(C24:AG24) -> 0
A25: Total EU Projects | C25: =C10+C17 -> 0 | D25: =D10+D17 -> 0 | E25: =E10+E17 -> 0 | F25: =F10+F17 -> 0 | G25: =G10+G17 -> 0 | H25: =H10+H17 -> 0 | I25: =I10+I17 -> 0 | J25: =J10+J17 -> 0 | ... AH25: =AH10+AH17 -> 0
A27: Other Productive Hours
A28: Other projects | AH28: =SUM(C28:AG28) -> 0
A29: Teaching | AH29: =SUM(C29:AG29) -> 0
A30: xxxxx | AH30: =SUM(C30:AG30) -> 0
A31: yyyyy | AH31: =SUM(C31:AG31) -> 0
A32: zzzzz | AH32: =SUM(C32:AG32) -> 0
A33: Total Other Productive Hours | C33: =SUM(C28:C32) -> 0 | D33: =SUM(D28:D32) -> 0 | E33: =SUM(E28:E32) -> 0 | F33: =SUM(F28:F32) -> 0 | G33: =SUM(G28:G32) -> 0 | H33: =SUM(H28:H32) -> 0 | I33: =SUM(I28:I32) -> 0 | J33: =SUM(J28:J32) -> 0 | ... AH33: =SUM(AH28:AH32) -> 0
A35: Total Productive Hours | C35: =C25+C33 -> 0 | D35: =D25+D33 -> 0 | E35: =E25+E33 -> 0 | F35: =F25+F33 -> 0 | G35: =G25+G33 -> 0 | H35: =H25+H33 -> 0 | I35: =I25+I33 -> 0 | J35: =J25+J33 -> 0 | ... AH35: =AH25+AH33 -> 0
A37: Non Productive Hours
A38: Annual Leave | AH38: =SUM(C38:AG38) -> 0
A39: Special Leave | AH39: =SUM(C39:AG39) -> 0
A40: Illness | AH40: =SUM(C40:AG40) -> 0
A41: Training / internal meetings | AH41: =SUM(C41:AG41) -> 0
A42: Total Non-Productive Hours | C42: =SUM(C38:C41) -> 0 | D42: =SUM(D38:D41) -> 0 | E42: =SUM(E38:E41) -> 0 | F42: =SUM(F38:F41) -> 0 | G42: =SUM(G38:G41) -> 0 | H42: =SUM(H38:H41) -> 0 | I42: =SUM(I38:I41) -> 0 | J42: =SUM(J38:J41) -> 0 | ... AH42: =SUM(AH38:AH41) -> 0
AH43: =SUM(C43:AG43) -> 0
A44: Total Hours (Productive + Non Productive) | C44: =C35+C42 -> 0 | D44: =D35+D42 -> 0 | E44: =E35+E42 -> 0 | F44: =F35+F42 -> 0 | G44: =G35+G42 -> 0 | H44: =H35+H42 -> 0 | I44: =I35+I42 -> 0 | J44: =J35+J42 -> 0 | ... AH44: =AH35+AH42 -> 0
A46: Signed: | C46: Date and Signature
A47: ='1'!A47 -> 0 | C47: 31.03.2017
...

Sheet 4
A1: Organisation: | B1: Sabancı University
A2: Person : | B2: =TOTAL!B2 -> 0
A4: Month | B4: April 2017
A6: Date | C6: 1 | D6: 2 | E6: 3 | F6: 4 | G6: 5 | H6: 6 | I6: 7 | J6: 8 | K6: 9 | L6: 10 | M6: 11 | N6: 12 | O6: 13 | P6: 14 | Q6: 15 | R6: 16 | S6: 17 | T6: 18 | U6: 19 | V6: 20 | W6: 21 | X6: 22 | Y6: 23 | Z6: 24 | AA6: 25 | AB6: 26 | AC6: 27 | AD6: 28 | AE6: 29 | AF6: 30 | AG6: Total
A7: Day | C7: Sa | D7: Su | E7: Mo | F7: Tu | G7: W | H7: Th | I7: F | J7: Sa | K7: Su | L7: Mo | M7: Tu | N7: W | O7: Th | P7: F | Q7: Sa | R7: Su | S7: Mo | T7: Tu | U7: W | V7: Th | W7: F | X7: Sa | Y7: Su | Z7: Mo | AA7: Tu | AB7: W | AC7: Th | AD7: F | AE7: Sa | AF7: Su
A9: EU-Projects
A10: Project X | C10: =SUM(C11:C16) -> 0 | D10: =SUM(D11:D16) -> 0 | E10: =SUM(E11:E16) -> 0 | F10: =SUM(F11:F16) -> 0 | G10: =SUM(G11:G16) -> 0 | H10: =SUM(H11:H16) -> 0 | I10: =SUM(I11:I16) -> 0 | J10: =SUM(J11:J16) -> 0 | ... AG10: =SUM(AG11:AG16) -> 0
A11: RTD | B11: WP1 | AG11: =SUM(C11:AF11) -> 0
A12: RTD | B12: WP2 | AG12: =SUM(C12:AF12) -> 0
A13: RTD | B13: WP3 | AG13: =SUM(C13:AF13) -> 0
A14: RTD | B14: WP6 | AG14: =SUM(C14:AF14) -> 0
A15: OTH | B15: WP9 | AG15: =SUM(C15:AF15) -> 0
A16: MNGT | B16: WP11 | AG16: =SUM(C16:AF16) -> 0
A17: Project Y | C17: =SUM(C18:C24) -> 0 | D17: =SUM(D18:D24) -> 0 | E17: =SUM(E18:E24) -> 0 | F17: =SUM(F18:F24) -> 0 | G17: =SUM(G18:G24) -> 0 | H17: =SUM(H18:H24) -> 0 | I17: =SUM(I18:I24) -> 0 | J17: =SUM(J18:J24) -> 0 | ... AG17: =SUM(AG18:AG24) -> 0
A18: RTD | B18: WP1 | AG18: =SUM(C18:AF18) -> 0
A19: RTD | B19: WP2 | AG19: =SUM(C19:AF19) -> 0
A20: RTD | B20: WP3 | AG20: =SUM(C20:AF20) -> 0
A21: RTD | B21: WP4 | AG21: =SUM(C21:AF21) -> 0
A22: RTD | B22: WP6 | AG22: =SUM(C22:AF22) -> 0
A23: OTH | B23: WP7 | AG23: =SUM(C23:AF23) -> 0
A24: MNGT | B24: WP8 | AG24: =SUM(C24:AF24) -> 0
A25: Total EU Projects | C25: =C10+C17 -> 0 | D25: =D10+D17 -> 0 | E25: =E10+E17 -> 0 | F25: =F10+F17 -> 0 | G25: =G10+G17 -> 0 | H25: =H10+H17 -> 0 | I25: =I10+I17 -> 0 | J25: =J10+J17 -> 0 | ... AG25: =AG10+AG17 -> 0
A27: Other Productive Hours
A28: Other projects | AG28: =SUM(C28:AF28) -> 0
A29: Teaching | AG29: =SUM(C29:AF29) -> 0
A30: xxxxx | AG30: =SUM(C30:AF30) -> 0
A31: yyyyy | AG31: =SUM(C31:AF31) -> 0
A32: zzzzz | AG32: =SUM(C32:AF32) -> 0
A33: Total Other Productive Hours | C33: =SUM(C28:C32) -> 0 | D33: =SUM(D28:D32) -> 0 | E33: =SUM(E28:E32) -> 0 | F33: =SUM(F28:F32) -> 0 | G33: =SUM(G28:G32) -> 0 | H33: =SUM(H28:H32) -> 0 | I33: =SUM(I28:I32) -> 0 | J33: =SUM(J28:J32) -> 0 | ... AG33: =SUM(AG28:AG32) -> 0
A35: Total Productive Hours | C35: =C25+C33 -> 0 | D35: =D25+D33 -> 0 | E35: =E25+E33 -> 0 | F35: =F25+F33 -> 0 | G35: =G25+G33 -> 0 | H35: =H25+H33 -> 0 | I35: =I25+I33 -> 0 | J35: =J25+J33 -> 0 | ... AG35: =AG25+AG33 -> 0
A37: Non Productive Hours
A38: Annual Leave | AG38: =SUM(C38:AF38) -> 0
A39: Special Leave | AG39: =SUM(C39:AF39) -> 0
A40: Illness | AG40: =SUM(C40:AF40) -> 0
A41: Training / internal meetings | AG41: =SUM(C41:AF41) -> 0
A42: Total Non-Productive Hours | C42: =SUM(C38:C41) -> 0 | D42: =SUM(D38:D41) -> 0 | E42: =SUM(E38:E41) -> 0 | F42: =SUM(F38:F41) -> 0 | G42: =SUM(G38:G41) -> 0 | H42: =SUM(H38:H41) -> 0 | I42: =SUM(I38:I41) -> 0 | J42: =SUM(J38:J41) -> 0 | ... AG42: =SUM(AG38:AG41) -> 0
AG43: =SUM(C43:AF43) -> 0
A44: Total Hours (Productive + Non Productive) | C44: =C35+C42 -> 0 | D44: =D35+D42 -> 0 | E44: =E35+E42 -> 0 | F44: =F35+F42 -> 0 | G44: =G35+G42 -> 0 | H44: =H35+H42 -> 0 | I44: =I35+I42 -> 0 | J44: =J35+J42 -> 0 | ... AG44: =AG35+AG42 -> 0
A46: Signed: | C46: Date and Signature
A47: ='1'!A47 -> 0 | C47: 28.04.2017
...

Sheet 5
A1: Organisation: | B1: Sabancı University
A2: Person : | B2: =TOTAL!B2 -> 0
A4: Month | B4: 42856
A6: Date | C6: 1 | D6: 2 | E6: 3 | F6: 4 | G6: 5 | H6: 6 | I6: 7 | J6: 8 | K6: 9 | L6: 10 | M6: 11 | N6: 12 | O6: 13 | P6: 14 | Q6: 15 | R6: 16 | S6: 17 | T6: 18 | U6: 19 | V6: 20 | W6: 21 | X6: 22 | Y6: 23 | Z6: 24 | AA6: 25 | AB6: 26 | AC6: 27 | AD6: 28 | AE6: 29 | AF6: 30 | AG6: 31 | AH6: Total
A7: Day | C7: Mo | D7: Tu | E7: W | F7: Th | G7: F | H7: Sa | I7: Su | J7: Mo | K7: Tu | L7: W | M7: Th | N7: F | O7: Sa | P7: Su | Q7: Mo | R7: Tu | S7: W | T7: Th | U7: F | V7: Sa | W7: Su | X7: Mo | Y7: Tu | Z7: W | AA7: Th | AB7: F | AC7: Sa | AD7: Su | AE7: Mo | AF7: Tu | AG7: W
A9: EU-Projects
A10: Project X | C10: =SUM(C11:C16) -> 0 | D10: =SUM(D11:D16) -> 0 | E10: =SUM(E11:E16) -> 0 | F10: =SUM(F11:F16) -> 0 | G10: =SUM(G11:G16) -> 0 | H10: =SUM(H11:H16) -> 0 | I10: =SUM(I11:I16) -> 0 | J10: =SUM(J11:J16) -> 0 | ... AH10: =SUM(AH11:AH16) -> 0
A11: RTD | B11: WP1 | AH11: =SUM(C11:AG11) -> 0
A12: RTD | B12: WP2 | AH12: =SUM(C12:AG12) -> 0
A13: RTD | B13: WP3 | AH13: =SUM(C13:AG13) -> 0
A14: RTD | B14: WP6 | AH14: =SUM(C14:AG14) -> 0
A15: OTH | B15: WP9 | AH15: =SUM(C15:AG15) -> 0
A16: MNGT | B16: WP11 | AH16: =SUM(C16:AG16) -> 0
A17: Project Y | C17: =SUM(C18:C24) -> 0 | D17: =SUM(D18:D24) -> 0 | E17: =SUM(E18:E24) -> 0 | F17: =SUM(F18:F24) -> 0 | G17: =SUM(G18:G24) -> 0 | H17: =SUM(H18:H24) -> 0 | I17: =SUM(I18:I24) -> 0 | J17: =SUM(J18:J24) -> 0 | ... AH17: =SUM(AH18:AH24) -> 0
A18: RTD | B18: WP1 | AH18: =SUM(C18:AG18) -> 0
A19: RTD | B19: WP2 | AH19: =SUM(C19:AG19) -> 0
A20: RTD | B20: WP3 | AH20: =SUM(C20:AG20) -> 0
A21: RTD | B21: WP4 | AH21: =SUM(C21:AG21) -> 0
A22: RTD | B22: WP6 | AH22: =SUM(C22:AG22) -> 0
A23: OTH | B23: WP7 | AH23: =SUM(C23:AG23) -> 0
A24: MNGT | B24: WP8 | AH24: =SUM(C24:AG24) -> 0
A25: Total EU Projects | C25: =C10+C17 -> 0 | D25: =D10+D17 -> 0 | E25: =E10+E17 -> 0 | F25: =F10+F17 -> 0 | G25: =G10+G17 -> 0 | H25: =H10+H17 -> 0 | I25: =I10+I17 -> 0 | J25: =J10+J17 -> 0 | ... AH25: =AH10+AH17 -> 0
A27: Other Productive Hours
A28: Other projects | AH28: =SUM(C28:AG28) -> 0
A29: Teaching | AH29: =SUM(C29:AG29) -> 0
A30: xxxxx | AH30: =SUM(C30:AG30) -> 0
A31: yyyyy | AH31: =SUM(C31:AG31) -> 0
A32: zzzzz | AH32: =SUM(C32:AG32) -> 0
A33: Total Other Productive Hours | C33: =SUM(C28:C32) -> 0 | D33: =SUM(D28:D32) -> 0 | E33: =SUM(E28:E32) -> 0 | F33: =SUM(F28:F32) -> 0 | G33: =SUM(G28:G32) -> 0 | H33: =SUM(H28:H32) -> 0 | I33: =SUM(I28:I32) -> 0 | J33: =SUM(J28:J32) -> 0 | ... AH33: =SUM(AH28:AH32) -> 0
A35: Total Productive Hours | C35: =C25+C33 -> 0 | D35: =D25+D33 -> 0 | E35: =E25+E33 -> 0 | F35: =F25+F33 -> 0 | G35: =G25+G33 -> 0 | H35: =H25+H33 -> 0 | I35: =I25+I33 -> 0 | J35: =J25+J33 -> 0 | ... AH35: =AH25+AH33 -> 0
A37: Non Productive Hours
A38: Annual Leave | AH38: =SUM(C38:AG38) -> 0
A39: Special Leave | AH39: =SUM(C39:AG39) -> 0
A40: Illness | AH40: =SUM(C40:AG40) -> 0
A41: Training / internal meetings | AH41: =SUM(C41:AG41) -> 0
A42: Total Non-Productive Hours | C42: =SUM(C38:C41) -> 0 | D42: =SUM(D38:D41) -> 0 | E42: =SUM(E38:E41) -> 0 | F42: =SUM(F38:F41) -> 0 | G42: =SUM(G38:G41) -> 0 | H42: =SUM(H38:H41) -> 0 | I42: =SUM(I38:I41) -> 0 | J42: =SUM(J38:J41) -> 0 | ... AH42: =SUM(AH38:AH41) -> 0
AH43: =SUM(C43:AG43) -> 0
A44: Total Hours (Productive + Non Productive) | C44: =C35+C42 -> 0 | D44: =D35+D42 -> 0 | E44: =E35+E42 -> 0 | F44: =F35+F42 -> 0 | G44: =G35+G42 -> 0 | H44: =H35+H42 -> 0 | I44: =I35+I42 -> 0 | J44: =J35+J42 -> 0 | ... AH44: =AH35+AH42 -> 0
A46: Signed: | C46: Date and Signature
A47: ='1'!A47 -> 0 | C47: 31/05/2017
...

Sheet 6
A1: Organisation: | B1: Sabancı University
A2: Person : | B2: =TOTAL!B2 -> 0
A4: Month | B4: June 2017
A6: Date | C6: 1 | D6: 2 | E6: 3 | F6: 4 | G6: 5 | H6: 6 | I6: 7 | J6: 8 | K6: 9 | L6: 10 | M6: 11 | N6: 12 | O6: 13 | P6: 14 | Q6: 15 | R6: 16 | S6: 17 | T6: 18 | U6: 19 | V6: 20 | W6: 21 | X6: 22 | Y6: 23 | Z6: 24 | AA6: 25 | AB6: 26 | AC6: 27 | AD6: 28 | AE6: 29 | AF6: 30 | AG6: Total
A7: Day | C7: Th | D7: F | E7: Sa | F7: Su | G7: Mo | H7: Tu | I7: W | J7: Th | K7: F | L7: Sa | M7: Su | N7: Mo | O7: Tu | P7: W | Q7: Th | R7: F | S7: Sa | T7: Su | U7: Mo | V7: Tu | W7: W | X7: Th | Y7: F | Z7: Sa | AA7: Su | AB7: Mo | AC7: Tu | AD7: We | AE7: Th | AF7: Fr
A9: EU-Projects
A10: Project X | C10: =SUM(C11:C16) -> 0 | D10: =SUM(D11:D16) -> 0 | E10: =SUM(E11:E16) -> 0 | F10: =SUM(F11:F16) -> 0 | G10: =SUM(G11:G16) -> 0 | H10: =SUM(H11:H16) -> 0 | I10: =SUM(I11:I16) -> 0 | J10: =SUM(J11:J16) -> 0 | ... AG10: =SUM(AG11:AG16) -> 0
A11: RTD | B11: WP1 | AG11: =SUM(C11:AF11) -> 0
A12: RTD | B12: WP2 | AG12: =SUM(C12:AF12) -> 0
A13: RTD | B13: WP3 | AG13: =SUM(C13:AF13) -> 0
A14: RTD | B14: WP6 | AG14: =SUM(C14:AF14) -> 0
A15: OTH | B15: WP9 | AG15: =SUM(C15:AF15) -> 0
A16: MNGT | B16: WP11 | AG16: =SUM(C16:AF16) -> 0
A17: Project Y | C17: =SUM(C18:C24) -> 0 | D17: =SUM(D18:D24) -> 0 | E17: =SUM(E18:E24) -> 0 | F17: =SUM(F18:F24) -> 0 | G17: =SUM(G18:G24) -> 0 | H17: =SUM(H18:H24) -> 0 | I17: =SUM(I18:I24) -> 0 | J17: =SUM(J18:J24) -> 0 | ... AG17: =SUM(AG18:AG24) -> 0
A18: RTD | B18: WP1 | AG18: =SUM(C18:AF18) -> 0
A19: RTD | B19: WP2 | AG19: =SUM(C19:AF19) -> 0
A20: RTD | B20: WP3 | AG20: =SUM(C20:AF20) -> 0
A21: RTD | B21: WP4 | AG21: =SUM(C21:AF21) -> 0
A22: RTD | B22: WP6 | AG22: =SUM(C22:AF22) -> 0
A23: OTH | B23: WP7 | AG23: =SUM(C23:AF23) -> 0
A24: MNGT | B24: WP8 | AG24: =SUM(C24:AF24) -> 0
A25: Total EU Projects | C25: =C10+C17 -> 0 | D25: =D10+D17 -> 0 | E25: =E10+E17 -> 0 | F25: =F10+F17 -> 0 | G25: =G10+G17 -> 0 | H25: =H10+H17 -> 0 | I25: =I10+I17 -> 0 | J25: =J10+J17 -> 0 | ... AG25: =AG10+AG17 -> 0
A27: Other Productive Hours
A28: Other projects | AG28: =SUM(C28:AF28) -> 0
A29: Teaching | AG29: =SUM(C29:AF29) -> 0
A30: xxxxx | AG30: =SUM(C30:AF30) -> 0
A31: yyyyy | AG31: =SUM(C31:AF31) -> 0
A32: zzzzz | AG32: =SUM(C32:AF32) -> 0
A33: Total Other Productive Hours | C33: =SUM(C28:C32) -> 0 | D33: =SUM(D28:D32) -> 0 | E33: =SUM(E28:E32) -> 0 | F33: =SUM(F28:F32) -> 0 | G33: =SUM(G28:G32) -> 0 | H33: =SUM(H28:H32) -> 0 | I33: =SUM(I28:I32) -> 0 | J33: =SUM(J28:J32) -> 0 | ... AG33: =SUM(AG28:AG32) -> 0
A35: Total Productive Hours | C35: =C25+C33 -> 0 | D35: =D25+D33 -> 0 | E35: =E25+E33 -> 0 | F35: =F25+F33 -> 0 | G35: =G25+G33 -> 0 | H35: =H25+H33 -> 0 | I35: =I25+I33 -> 0 | J35: =J25+J33 -> 0 | ... AG35: =AG25+AG33 -> 0
A37: Non Productive Hours
A38: Annual Leave | AG38: =SUM(C38:AF38) -> 0
A39: Special Leave | AG39: =SUM(C39:AF39) -> 0
A40: Illness | AG40: =SUM(C40:AF40) -> 0
A41: Training / internal meetings | AG41: =SUM(C41:AF41) -> 0
A42: Total Non-Productive Hours | C42: =SUM(C38:C41) -> 0 | D42: =SUM(D38:D41) -> 0 | E42: =SUM(E38:E41) -> 0 | F42: =SUM(F38:F41) -> 0 | G42: =SUM(G38:G41) -> 0 | H42: =SUM(H38:H41) -> 0 | I42: =SUM(I38:I41) -> 0 | J42: =SUM(J38:J41) -> 0 | ... AG42: =SUM(AG38:AG41) -> 0
AG43: =SUM(C43:AF43) -> 0
A44: Total Hours (Productive + Non Productive) | C44: =C35+C42 -> 0 | D44: =D35+D42 -> 0 | E44: =E35+E42 -> 0 | F44: =F35+F42 -> 0 | G44: =G35+G42 -> 0 | H44: =H35+H42 -> 0 | I44: =I35+I42 -> 0 | J44: =J35+J42 -> 0 | ... AG44: =AG35+AG42 -> 0
A46: Signed: | C46: Date and Signature
A47: ='1'!A47 -> 0 | C47: 30.06.2017
...

Sheet 7
A1: Organisation: | B1: Sabancı University
A2: Person : | B2: =TOTAL!B2 -> 0
A4: Month | B4: July 2017
A6: Date | C6: 1 | D6: 2 | E6: 3 | F6: 4 | G6: 5 | H6: 6 | I6: 7 | J6: 8 | K6: 9 | L6: 10 | M6: 11 | N6: 12 | O6: 13 | P6: 14 | Q6: 15 | R6: 16 | S6: 17 | T6: 18 | U6: 19 | V6: 20 | W6: 21 | X6: 22 | Y6: 23 | Z6: 24 | AA6: 25 | AB6: 26 | AC6: 27 | AD6: 28 | AE6: 29 | AF6: 30 | AG6: 31 | AH6: Total
A7: Day | C7: Sa | D7: Su | E7: Mo | F7: Tu | G7: W | H7: Th | I7: F | J7: Sa | K7: Su | L7: Mo | M7: Tu | N7: W | O7: Th | P7: F | Q7: Sa | R7: Su | S7: Mo | T7: Tu | U7: W | V7: Th | W7: F | X7: Sa | Y7: Su | Z7: Mo | AA7: Tu | AB7: W | AC7: Th | AD7: Fr | AE7: Sa | AF7: Su | AG7: Mo
A9: EU-Projects
A10: Project X | C10: =SUM(C11:C16) -> 0 | D10: =SUM(D11:D16) -> 0 | E10: =SUM(E11:E16) -> 0 | F10: =SUM(F11:F16) -> 0 | G10: =SUM(G11:G16) -> 0 | H10: =SUM(H11:H16) -> 0 | I10: =SUM(I11:I16) -> 0 | J10: =SUM(J11:J16) -> 0 | ... AH10: =SUM(AH11:AH16) -> 0
A11: RTD | B11: WP1 | AH11: =SUM(C11:AG11) -> 0
A12: RTD | B12: WP2 | AH12: =SUM(C12:AG12) -> 0
A13: RTD | B13: WP3 | AH13: =SUM(C13:AG13) -> 0
A14: RTD | B14: WP6 | AH14: =SUM(C14:AG14) -> 0
A15: OTH | B15: WP9 | AH15: =SUM(C15:AG15) -> 0
A16: MNGT | B16: WP11 | AH16: =SUM(C16:AG16) -> 0
A17: Project Y | C17: =SUM(C18:C24) -> 0 | D17: =SUM(D18:D24) -> 0 | E17: =SUM(E18:E24) -> 0 | F17: =SUM(F18:F24) -> 0 | G17: =SUM(G18:G24) -> 0 | H17: =SUM(H18:H24) -> 0 | I17: =SUM(I18:I24) -> 0 | J17: =SUM(J18:J24) -> 0 | ... AH17: =SUM(AH18:AH24) -> 0
A18: RTD | B18: WP1 | AH18: =SUM(C18:AG18) -> 0
A19: RTD | B19: WP2 | AH19: =SUM(C19:AG19) -> 0
A20: RTD | B20: WP3 | AH20: =SUM(C20:AG20) -> 0
A21: RTD | B21: WP4 | AH21: =SUM(C21:AG21) -> 0
A22: RTD | B22: WP6 | AH22: =SUM(C22:AG22) -> 0
A23: OTH | B23: WP7 | AH23: =SUM(C23:AG23) -> 0
A24: MNGT | B24: WP8 | AH24: =SUM(C24:AG24) -> 0
A25: Total EU Projects | C25: =C10+C17 -> 0 | D25: =D10+D17 -> 0 | E25: =E10+E17 -> 0 | F25: =F10+F17 -> 0 | G25: =G10+G17 -> 0 | H25: =H10+H17 -> 0 | I25: =I10+I17 -> 0 | J25: =J10+J17 -> 0 | ... AH25: =AH10+AH17 -> 0
A27: Other Productive Hours
A28: Other projects | AH28: =SUM(C28:AG28) -> 0
A29: Teaching | AH29: =SUM(C29:AG29) -> 0
A30: xxxxx | AH30: =SUM(C30:AG30) -> 0
A31: yyyyy | AH31: =SUM(C31:AG31) -> 0
A32: zzzzz | AH32: =SUM(C32:AG32) -> 0
A33: Total Other Productive Hours | C33: =SUM(C28:C32) -> 0 | D33: =SUM(D28:D32) -> 0 | E33: =SUM(E28:E32) -> 0 | F33: =SUM(F28:F32) -> 0 | G33: =SUM(G28:G32) -> 0 | H33: =SUM(H28:H32) -> 0 | I33: =SUM(I28:I32) -> 0 | J33: =SUM(J28:J32) -> 0 | ... AH33: =SUM(AH28:AH32) -> 0
A35: Total Productive Hours | C35: =C25+C33 -> 0 | D35: =D25+D33 -> 0 | E35: =E25+E33 -> 0 | F35: =F25+F33 -> 0 | G35: =G25+G33 -> 0 | H35: =H25+H33 -> 0 | I35: =I25+I33 -> 0 | J35: =J25+J33 -> 0 | ... AH35: =AH25+AH33 -> 0
A37: Non Productive Hours
A38: Annual Leave | AH38: =SUM(C38:AG38) -> 0
A39: Special Leave | AH39: =SUM(C39:AG39) -> 0
A40: Illness | AH40: =SUM(C40:AG40) -> 0
A41: Training / internal meetings | AH41: =SUM(C41:AG41) -> 0
A42: Total Non-Productive Hours | C42: =SUM(C38:C41) -> 0 | D42: =SUM(D38:D41) -> 0 | E42: =SUM(E38:E41) -> 0 | F42: =SUM(F38:F41) -> 0 | G42: =SUM(G38:G41) -> 0 | H42: =SUM(H38:H41) -> 0 | I42: =SUM(I38:I41) -> 0 | J42: =SUM(J38:J41) -> 0 | ... AH42: =SUM(AH38:AH41) -> 0
AH43: =SUM(C43:AG43) -> 0
A44: Total Hours (Productive + Non Productive) | C44: =C35+C42 -> 0 | D44: =D35+D42 -> 0 | E44: =E35+E42 -> 0 | F44: =F35+F42 -> 0 | G44: =G35+G42 -> 0 | H44: =H35+H42 -> 0 | I44: =I35+I42 -> 0 | J44: =J35+J42 -> 0 | ... AH44: =AH35+AH42 -> 0
A46: Signed: | C46: Date and Signature
A47: ='1'!A47 -> 0 | C47: 31/07/2017
...

Sheet 8
A1: Organisation: | B1: Sabancı University
A2: Person : | B2: =TOTAL!B2 -> 0
A4: Month | B4: August 2017
A6: Date | C6: 1 | D6: 2 | E6: 3 | F6: 4 | G6: 5 | H6: 6 | I6: 7 | J6: 8 | K6: 9 | L6: 10 | M6: 11 | N6: 12 | O6: 13 | P6: 14 | Q6: 15 | R6: 16 | S6: 17 | T6: 18 | U6: 19 | V6: 20 | W6: 21 | X6: 22 | Y6: 23 | Z6: 24 | AA6: 25 | AB6: 26 | AC6: 27 | AD6: 28 | AE6: 29 | AF6: 30 | AG6: 31 | AH6: Total
A7: Day | C7: Tu | D7: W | E7: Th | F7: F | G7: Sa | H7: Su | I7: Mo | J7: Tu | K7: W | L7: Th | M7: F | N7: Sa | O7: Su | P7: Mo | Q7: Tu | R7: W | S7: Th | T7: F | U7: Sa | V7: Su | W7: Mo | X7: Tu | Y7: W | Z7: Th | AA7: F | AB7: Sa | AC7: Su | AD7: Mo | AE7: Tu | AF7: We | AG7: Th
A9: EU-Projects
A10: Project X | C10: =SUM(C11:C16) -> 0 | D10: =SUM(D11:D16) -> 0 | E10: =SUM(E11:E16) -> 0 | F10: =SUM(F11:F16) -> 0 | G10: =SUM(G11:G16) -> 0 | H10: =SUM(H11:H16) -> 0 | I10: =SUM(I11:I16) -> 0 | J10: =SUM(J11:J16) -> 0 | ... AH10: =SUM(AH11:AH16) -> 0
A11: RTD | B11: WP1 | AH11: =SUM(C11:AG11) -> 0
A12: RTD | B12: WP2 | AH12: =SUM(C12:AG12) -> 0
A13: RTD | B13: WP3 | AH13: =SUM(C13:AG13) -> 0
A14: RTD | B14: WP6 | AH14: =SUM(C14:AG14) -> 0
A15: OTH | B15: WP9 | AH15: =SUM(C15:AG15) -> 0
A16: MNGT | B16: WP11 | AH16: =SUM(C16:AG16) -> 0
A17: Project Y | C17: =SUM(C18:C24) -> 0 | D17: =SUM(D18:D24) -> 0 | E17: =SUM(E18:E24) -> 0 | F17: =SUM(F18:F24) -> 0 | G17: =SUM(G18:G24) -> 0 | H17: =SUM(H18:H24) -> 0 | I17: =SUM(I18:I24) -> 0 | J17: =SUM(J18:J24) -> 0 | ... AH17: =SUM(AH18:AH24) -> 0
A18: RTD | B18: WP1 | AH18: =SUM(C18:AG18) -> 0
A19: RTD | B19: WP2 | AH19: =SUM(C19:AG19) -> 0
A20: RTD | B20: WP3 | AH20: =SUM(C20:AG20) -> 0
A21: RTD | B21: WP4 | AH21: =SUM(C21:AG21) -> 0
A22: RTD | B22: WP6 | AH22: =SUM(C22:AG22) -> 0
A23: OTH | B23: WP7 | AH23: =SUM(C23:AG23) -> 0
A24: MNGT | B24: WP8 | AH24: =SUM(C24:AG24) -> 0
A25: Total EU Projects | C25: =C10+C17 -> 0 | D25: =D10+D17 -> 0 | E25: =E10+E17 -> 0 | F25: =F10+F17 -> 0 | G25: =G10+G17 -> 0 | H25: =H10+H17 -> 0 | I25: =I10+I17 -> 0 | J25: =J10+J17 -> 0 | ... AH25: =AH10+AH17 -> 0
A27: Other Productive Hours
A28: Other projects | AH28: =SUM(C28:AG28) -> 0
A29: Teaching | AH29: =SUM(C29:AG29) -> 0
A30: xxxxx | AH30: =SUM(C30:AG30) -> 0
A31: yyyyy | AH31: =SUM(C31:AG31) -> 0
A32: zzzzz | AH32: =SUM(C32:AG32) -> 0
A33: Total Other Productive Hours | C33: =SUM(C28:C32) -> 0 | D33: =SUM(D28:D32) -> 0 | E33: =SUM(E28:E32) -> 0 | F33: =SUM(F28:F32) -> 0 | G33: =SUM(G28:G32) -> 0 | H33: =SUM(H28:H32) -> 0 | I33: =SUM(I28:I32) -> 0 | J33: =SUM(J28:J32) -> 0 | ... AH33: =SUM(AH28:AH32) -> 0
A35: Total Productive Hours | C35: =C25+C33 -> 0 | D35: =D25+D33 -> 0 | E35: =E25+E33 -> 0 | F35: =F25+F33 -> 0 | G35: =G25+G33 -> 0 | H35: =H25+H33 -> 0 | I35: =I25+I33 -> 0 | J35: =J25+J33 -> 0 | ... AH35: =AH25+AH33 -> 0
A37: Non Productive Hours
A38: Annual Leave | AH38: =SUM(C38:AG38) -> 0
A39: Special Leave | AH39: =SUM(C39:AG39) -> 0
A40: Illness | AH40: =SUM(C40:AG40) -> 0
A41: Training / internal meetings | AH41: =SUM(C41:AG41) -> 0
A42: Total Non-Productive Hours | C42: =SUM(C38:C41) -> 0 | D42: =SUM(D38:D41) -> 0 | E42: =SUM(E38:E41) -> 0 | F42: =SUM(F38:F41) -> 0 | G42: =SUM(G38:G41) -> 0 | H42: =SUM(H38:H41) -> 0 | I42: =SUM(I38:I41) -> 0 | J42: =SUM(J38:J41) -> 0 | ... AH42: =SUM(AH38:AH41) -> 0
AH43: =SUM(C43:AG43) -> 0
A44: Total Hours (Productive + Non Productive) | C44: =C35+C42 -> 0 | D44: =D35+D42 -> 0 | E44: =E35+E42 -> 0 | F44: =F35+F42 -> 0 | G44: =G35+G42 -> 0 | H44: =H35+H42 -> 0 | I44: =I35+I42 -> 0 | J44: =J35+J42 -> 0 | ... AH44: =AH35+AH42 -> 0
A46: Signed: | C46: Date and Signature
A47: ='1'!A47 -> 0 | C47: 06.09.2017
...

Sheet 9
A1: Organisation: | B1: Sabancı University
A2: Person : | B2: =TOTAL!B2 -> 0
A4: Month | B4: September 2017
A6: Date | C6: 1 | D6: 2 | E6: 3 | F6: 4 | G6: 5 | H6: 6 | I6: 7 | J6: 8 | K6: 9 | L6: 10 | M6: 11 | N6: 12 | O6: 13 | P6: 14 | Q6: 15 | R6: 16 | S6: 17 | T6: 18 | U6: 19 | V6: 20 | W6: 21 | X6: 22 | Y6: 23 | Z6: 24 | AA6: 25 | AB6: 26 | AC6: 27 | AD6: 28 | AE6: 29 | AF6: 30 | AG6: Total
A7: Day | C7: F | D7: Sa | E7: Su | F7: Mo | G7: Tu | H7: W | I7: Th | J7: F | K7: Sa | L7: Su | M7: Mo | N7: Tu | O7: W | P7: Th | Q7: F | R7: Sa | S7: Su | T7: Mo | U7: Tu | V7: W | W7: Th | X7: F | Y7: Sa | Z7: Su | AA7: Mo | AB7: Tu | AC7: W | AD7: Th | AE7: F | AF7: Sa
A9: EU-Projects
A10: Project X | C10: =SUM(C11:C16) -> 0 | D10: =SUM(D11:D16) -> 0 | E10: =SUM(E11:E16) -> 0 | F10: =SUM(F11:F16) -> 0 | G10: =SUM(G11:G16) -> 0 | H10: =SUM(H11:H16) -> 0 | I10: =SUM(I11:I16) -> 0 | J10: =SUM(J11:J16) -> 0 | ... AG10: =SUM(AG11:AG16) -> 0
A11: RTD | B11: WP1 | AG11: =SUM(C11:AF11) -> 0
A12: RTD | B12: WP2 | AG12: =SUM(C12:AF12) -> 0
A13: RTD | B13: WP3 | AG13: =SUM(C13:AF13) -> 0
A14: RTD | B14: WP6 | AG14: =SUM(C14:AF14) -> 0
A15: OTH | B15: WP9 | AG15: =SUM(C15:AF15) -> 0
A16: MNGT | B16: WP11 | AG16: =SUM(C16:AF16) -> 0
A17: Project Y | C17: =SUM(C18:C24) -> 0 | D17: =SUM(D18:D24) -> 0 | E17: =SUM(E18:E24) -> 0 | F17: =SUM(F18:F24) -> 0 | G17: =SUM(G18:G24) -> 0 | H17: =SUM(H18:H24) -> 0 | I17: =SUM(I18:I24) -> 0 | J17: =SUM(J18:J24) -> 0 | ... AG17: =SUM(AG18:AG24) -> 0
A18: RTD | B18: WP1 | AG18: =SUM(C18:AF18) -> 0
A19: RTD | B19: WP2 | AG19: =SUM(C19:AF19) -> 0
A20: RTD | B20: WP3 | AG20: =SUM(C20:AF20) -> 0
A21: RTD | B21: WP4 | AG21: =SUM(C21:AF21) -> 0
A22: RTD | B22: WP6 | AG22: =SUM(C22:AF22) -> 0
A23: OTH | B23: WP7 | AG23: =SUM(C23:AF23) -> 0
A24: MNGT | B24: WP8 | AG24: =SUM(C24:AF24) -> 0
A25: Total EU Projects | C25: =C10+C17 -> 0 | D25: =D10+D17 -> 0 | E25: =E10+E17 -> 0 | F25: =F10+F17 -> 0 | G25: =G10+G17 -> 0 | H25: =H10+H17 -> 0 | I25: =I10+I17 -> 0 | J25: =J10+J17 -> 0 | ... AG25: =AG10+AG17 -> 0
A27: Other Productive Hours
A28: Other projects | AG28: =SUM(C28:AF28) -> 0
A29: Teaching | AG29: =SUM(C29:AF29) -> 0
A30: xxxxx | AG30: =SUM(C30:AF30) -> 0
A31: yyyyy | AG31: =SUM(C31:AF31) -> 0
A32: zzzzz | AG32: =SUM(C32:AF32) -> 0
A33: Total Other Productive Hours | C33: =SUM(C28:C32) -> 0 | D33: =SUM(D28:D32) -> 0 | E33: =SUM(E28:E32) -> 0 | F33: =SUM(F28:F32) -> 0 | G33: =SUM(G28:G32) -> 0 | H33: =SUM(H28:H32) -> 0 | I33: =SUM(I28:I32) -> 0 | J33: =SUM(J28:J32) -> 0 | ... AG33: =SUM(AG28:AG32) -> 0
A35: Total Productive Hours | C35: =C25+C33 -> 0 | D35: =D25+D33 -> 0 | E35: =E25+E33 -> 0 | F35: =F25+F33 -> 0 | G35: =G25+G33 -> 0 | H35: =H25+H33 -> 0 | I35: =I25+I33 -> 0 | J35: =J25+J33 -> 0 | ... AG35: =AG25+AG33 -> 0
A37: Non Productive Hours
A38: Annual Leave | AG38: =SUM(C38:AF38) -> 0
A39: Special Leave | AG39: =SUM(C39:AF39) -> 0
A40: Illness | AG40: =SUM(C40:AF40) -> 0
A41: Training / internal meetings | AG41: =SUM(C41:AF41) -> 0
A42: Total Non-Productive Hours | C42: =SUM(C38:C41) -> 0 | D42: =SUM(D38:D41) -> 0 | E42: =SUM(E38:E41) -> 0 | F42: =SUM(F38:F41) -> 0 | G42: =SUM(G38:G41) -> 0 | H42: =SUM(H38:H41) -> 0 | I42: =SUM(I38:I41) -> 0 | J42: =SUM(J38:J41) -> 0 | ... AG42: =SUM(AG38:AG41) -> 0
AG43: =SUM(C43:AF43) -> 0
A44: Total Hours (Productive + Non Productive) | C44: =C35+C42 -> 0 | D44: =D35+D42 -> 0 | E44: =E35+E42 -> 0 | F44: =F35+F42 -> 0 | G44: =G35+G42 -> 0 | H44: =H35+H42 -> 0 | I44: =I35+I42 -> 0 | J44: =J35+J42 -> 0 | ... AG44: =AG35+AG42 -> 0
A46: Signed: | C46: Date and Signature
A47: ='1'!A47 -> 0 | C47: 29/09/2017
...

Sheet 10
A1: Organisation: | B1: Sabancı University
A2: Person : | B2: =TOTAL!B2 -> 0
A4: Month | B4: October 2017
A6: Date | C6: 1 | D6: 2 | E6: 3 | F6: 4 | G6: 5 | H6: 6 | I6: 7 | J6: 8 | K6: 9 | L6: 10 | M6: 11 | N6: 12 | O6: 13 | P6: 14 | Q6: 15 | R6: 16 | S6: 17 | T6: 18 | U6: 19 | V6: 20 | W6: 21 | X6: 22 | Y6: 23 | Z6: 24 | AA6: 25 | AB6: 26 | AC6: 27 | AD6: 28 | AE6: 29 | AF6: 30 | AG6: 31 | AH6: Total
A7: Day | C7: Su | D7: Mo | E7: Tu | F7: W | G7: Th | H7: F | I7: Sa | J7: Su | K7: Mo | L7: Tu | M7: W | N7: Th | O7: F | P7: Sa | Q7: Su | R7: Mo | S7: Tu | T7: W | U7: Th | V7: F | W7: Sa | X7: Su | Y7: Mo | Z7: Tu | AA7: W | AB7: Th | AC7: F | AD7: Sa | AE7: Su | AF7: Mo | AG7: Tu
A9: EU-Projects
A10: Project X | C10: =SUM(C11:C16) -> 0 | D10: =SUM(D11:D16) -> 0 | E10: =SUM(E11:E16) -> 0 | F10: =SUM(F11:F16) -> 0 | G10: =SUM(G11:G16) -> 0 | H10: =SUM(H11:H16) -> 0 | I10: =SUM(I11:I16) -> 0 | J10: =SUM(J11:J16) -> 0 | ... AH10: =SUM(AH11:AH16) -> 0
A11: RTD | B11: WP1 | AH11: =SUM(C11:AG11) -> 0
A12: RTD | B12: WP2 | AH12: =SUM(C12:AG12) -> 0
A13: RTD | B13: WP3 | AH13: =SUM(C13:AG13) -> 0
A14: RTD | B14: WP6 | AH14: =SUM(C14:AG14) -> 0
A15: OTH | B15: WP9 | AH15: =SUM(C15:AG15) -> 0
A16: MNGT | B16: WP11 | AH16: =SUM(C16:AG16) -> 0
A17: Project Y | C17: =SUM(C18:C24) -> 0 | D17: =SUM(D18:D24) -> 0 | E17: =SUM(E18:E24) -> 0 | F17: =SUM(F18:F24) -> 0 | G17: =SUM(G18:G24) -> 0 | H17: =SUM(H18:H24) -> 0 | I17: =SUM(I18:I24) -> 0 | J17: =SUM(J18:J24) -> 0 | ... AH17: =SUM(AH18:AH24) -> 0
A18: RTD | B18: WP1 | AH18: =SUM(C18:AG18) -> 0
A19: RTD | B19: WP2 | AH19: =SUM(C19:AG19) -> 0
A20: RTD | B20: WP3 | AH20: =SUM(C20:AG20) -> 0
A21: RTD | B21: WP4 | AH21: =SUM(C21:AG21) -> 0
A22: RTD | B22: WP6 | AH22: =SUM(C22:AG22) -> 0
A23: OTH | B23: WP7 | AH23: =SUM(C23:AG23) -> 0
A24: MNGT | B24: WP8 | AH24: =SUM(C24:AG24) -> 0
A25: Total EU Projects | C25: =C10+C17 -> 0 | D25: =D10+D17 -> 0 | E25: =E10+E17 -> 0 | F25: =F10+F17 -> 0 | G25: =G10+G17 -> 0 | H25: =H10+H17 -> 0 | I25: =I10+I17 -> 0 | J25: =J10+J17 -> 0 | ... AH25: =AH10+AH17 -> 0
A27: Other Productive Hours
A28: Other projects | AH28: =SUM(C28:AG28) -> 0
A29: Teaching | AH29: =SUM(C29:AG29) -> 0
A30: xxxxx | AH30: =SUM(C30:AG30) -> 0
A31: yyyyy | AH31: =SUM(C31:AG31) -> 0
A32: zzzzz | AH32: =SUM(C32:AG32) -> 0
A33: Total Other Productive Hours | C33: =SUM(C28:C32) -> 0 | D33: =SUM(D28:D32) -> 0 | E33: =SUM(E28:E32) -> 0 | F33: =SUM(F28:F32) -> 0 | G33: =SUM(G28:G32) -> 0 | H33: =SUM(H28:H32) -> 0 | I33: =SUM(I28:I32) -> 0 | J33: =SUM(J28:J32) -> 0 | ... AH33: =SUM(AH28:AH32) -> 0
A35: Total Productive Hours | C35: =C25+C33 -> 0 | D35: =D25+D33 -> 0 | E35: =E25+E33 -> 0 | F35: =F25+F33 -> 0 | G35: =G25+G33 -> 0 | H35: =H25+H33 -> 0 | I35: =I25+I33 -> 0 | J35: =J25+J33 -> 0 | ... AH35: =AH25+AH33 -> 0
A37: Non Productive Hours
A38: Annual Leave | AH38: =SUM(C38:AG38) -> 0
A39: Special Leave | AH39: =SUM(C39:AG39) -> 0
A40: Illness | AH40: =SUM(C40:AG40) -> 0
A41: Training / internal meetings | AH41: =SUM(C41:AG41) -> 0
A42: Total Non-Productive Hours | C42: =SUM(C38:C41) -> 0 | D42: =SUM(D38:D41) -> 0 | E42: =SUM(E38:E41) -> 0 | F42: =SUM(F38:F41) -> 0 | G42: =SUM(G38:G41) -> 0 | H42: =SUM(H38:H41) -> 0 | I42: =SUM(I38:I41) -> 0 | J42: =SUM(J38:J41) -> 0 | ... AH42: =SUM(AH38:AH41) -> 0
AH43: =SUM(C43:AG43) -> 0
A44: Total Hours (Productive + Non Productive) | C44: =C35+C42 -> 0 | D44: =D35+D42 -> 0 | E44: =E35+E42 -> 0 | F44: =F35+F42 -> 0 | G44: =G35+G42 -> 0 | H44: =H35+H42 -> 0 | I44: =I35+I42 -> 0 | J44: =J35+J42 -> 0 | ... AH44: =AH35+AH42 -> 0
A46: Signed: | C46: Date and Signature
A47: ='1'!A47 -> 0 | C47: 31.10.2017
...

Sheet 11
A1: Organisation: | B1: Sabancı University
A2: Person : | B2: =TOTAL!B2 -> 0
A4: Month | B4: November 2017
A6: Date | C6: 1 | D6: 2 | E6: 3 | F6: 4 | G6: 5 | H6: 6 | I6: 7 | J6: 8 | K6: 9 | L6: 10 | M6: 11 | N6: 12 | O6: 13 | P6: 14 | Q6: 15 | R6: 16 | S6: 17 | T6: 18 | U6: 19 | V6: 20 | W6: 21 | X6: 22 | Y6: 23 | Z6: 24 | AA6: 25 | AB6: 26 | AC6: 27 | AD6: 28 | AE6: 29 | AF6: 30 | AG6: Total
A7: Day | C7: W | D7: Th | E7: F | F7: Sa | G7: Su | H7: Mo | I7: Tu | J7: W | K7: Th | L7: F | M7: Sa | N7: Su | O7: Mo | P7: Tu | Q7: W | R7: Th | S7: F | T7: Sa | U7: Su | V7: Mo | W7: Tu | X7: W | Y7: Th | Z7: F | AA7: Sa | AB7: Su | AC7: Mo | AD7: Tu | AE7: W | AF7: Th
A9: EU-Projects
A10: Project X | C10: =SUM(C11:C16) -> 0 | D10: =SUM(D11:D16) -> 0 | E10: =SUM(E11:E16) -> 0 | F10: =SUM(F11:F16) -> 0 | G10: =SUM(G11:G16) -> 0 | H10: =SUM(H11:H16) -> 0 | I10: =SUM(I11:I16) -> 0 | J10: =SUM(J11:J16) -> 0 | ... AG10: =SUM(AG11:AG16) -> 0
A11: RTD | B11: WP1 | AG11: =SUM(C11:AF11) -> 0
A12: RTD | B12: WP2 | AG12: =SUM(C12:AF12) -> 0
A13: RTD | B13: WP3 | AG13: =SUM(C13:AF13) -> 0
A14: RTD | B14: WP6 | AG14: =SUM(C14:AF14) -> 0
A15: OTH | B15: WP9 | AG15: =SUM(C15:AF15) -> 0
A16: MNGT | B16: WP11 | AG16: =SUM(C16:AF16) -> 0
A17: Project Y | D17: =SUM(D18:D24) -> 0 | E17: =SUM(E18:E24) -> 0 | F17: =SUM(F18:F24) -> 0 | G17: =SUM(G18:G24) -> 0 | H17: =SUM(H18:H24) -> 0 | I17: =SUM(I18:I24) -> 0 | J17: =SUM(J18:J24) -> 0 | K17: =SUM(K18:K24) -> 0 | ... AG17: =SUM(AG18:AG24) -> 0
A18: RTD | B18: WP1 | AG18: =SUM(C18:AF18) -> 0
A19: RTD | B19: WP2 | AG19: =SUM(C19:AF19) -> 0
A20: RTD | B20: WP3 | AG20: =SUM(C20:AF20) -> 0
A21: RTD | B21: WP4 | AG21: =SUM(C21:AF21) -> 0
A22: RTD | B22: WP6 | AG22: =SUM(C22:AF22) -> 0
A23: OTH | B23: WP7 | AG23: =SUM(C23:AF23) -> 0
A24: MNGT | B24: WP8 | AG24: =SUM(C24:AF24) -> 0
A25: Total EU Projects | C25: =C10+C17 -> 0 | D25: =D10+D17 -> 0 | E25: =E10+E17 -> 0 | F25: =F10+F17 -> 0 | G25: =G10+G17 -> 0 | H25: =H10+H17 -> 0 | I25: =I10+I17 -> 0 | J25: =J10+J17 -> 0 | ... AG25: =AG10+AG17 -> 0
A27: Other Productive Hours
A28: Other projects | AG28: =SUM(C28:AF28) -> 0
A29: Teaching | AG29: =SUM(C29:AF29) -> 0
A30: xxxxx | AG30: =SUM(C30:AF30) -> 0
A31: yyyyy | AG31: =SUM(C31:AF31) -> 0
A32: zzzzz | AG32: =SUM(C32:AF32) -> 0
A33: Total Other Productive Hours | C33: =SUM(C28:C32) -> 0 | D33: =SUM(D28:D32) -> 0 | E33: =SUM(E28:E32) -> 0 | F33: =SUM(F28:F32) -> 0 | G33: =SUM(G28:G32) -> 0 | H33: =SUM(H28:H32) -> 0 | I33: =SUM(I28:I32) -> 0 | J33: =SUM(J28:J32) -> 0 | ... AG33: =SUM(AG28:AG32) -> 0
A35: Total Productive Hours | C35: =C25+C33 -> 0 | D35: =D25+D33 -> 0 | E35: =E25+E33 -> 0 | F35: =F25+F33 -> 0 | G35: =G25+G33 -> 0 | H35: =H25+H33 -> 0 | I35: =I25+I33 -> 0 | J35: =J25+J33 -> 0 | ... AG35: =AG25+AG33 -> 0
A37: Non Productive Hours
A38: Annual Leave | AG38: =SUM(C38:AF38) -> 0
A39: Special Leave | AG39: =SUM(C39:AF39) -> 0
A40: Illness | AG40: =SUM(C40:AF40) -> 0
A41: Training / internal meetings | AG41: =SUM(C41:AF41) -> 0
A42: Total Non-Productive Hours | C42: =SUM(C38:C41) -> 0 | D42: =SUM(D38:D41) -> 0 | E42: =SUM(E38:E41) -> 0 | F42: =SUM(F38:F41) -> 0 | G42: =SUM(G38:G41) -> 0 | H42: =SUM(H38:H41) -> 0 | I42: =SUM(I38:I41) -> 0 | J42: =SUM(J38:J41) -> 0 | ... AG42: =SUM(AG38:AG41) -> 0
AG43: =SUM(C43:AF43) -> 0
A44: Total Hours (Productive + Non Productive) | C44: =C35+C42 -> 0 | D44: =D35+D42 -> 0 | E44: =E35+E42 -> 0 | F44: =F35+F42 -> 0 | G44: =G35+G42 -> 0 | H44: =H35+H42 -> 0 | I44: =I35+I42 -> 0 | J44: =J35+J42 -> 0 | ... AG44: =AG35+AG42 -> 0
A46: Signed: | C46: Date and Signature
A47: ='1'!A47 -> 0 | C47: 30/11/2017
...

Sheet 12
A1: Organisation: | B1: Sabancı University
A2: Person : | B2: =TOTAL!B2 -> 0
A4: Month | B4: December 2017
A6: Date | C6: 1 | D6: 2 | E6: 3 | F6: 4 | G6: 5 | H6: 6 | I6: 7 | J6: 8 | K6: 9 | L6: 10 | M6: 11 | N6: 12 | O6: 13 | P6: 14 | Q6: 15 | R6: 16 | S6: 17 | T6: 18 | U6: 19 | V6: 20 | W6: 21 | X6: 22 | Y6: 23 | Z6: 24 | AA6: 25 | AB6: 26 | AC6: 27 | AD6: 28 | AE6: 29 | AF6: 30 | AG6: 31 | AH6: Total
A7: Day | C7: F | D7: Sa | E7: Su | F7: Mo | G7: Tu | H7: W | I7: Th | J7: F | K7: Sa | L7: Su | M7: Mo | N7: Tu | O7: W | P7: Th | Q7: F | R7: Sa | S7: Su | T7: Mo | U7: Tu | V7: W | W7: Th | X7: F | Y7: Sa | Z7: Su | AA7: Mo | AB7: Tu | AC7: W | AD7: Th | AE7: F | AF7: Sa | AG7: Su
A9: EU-Projects
A10: Project X | C10: =SUM(C11:C16) -> 0 | D10: =SUM(D11:D16) -> 0 | E10: =SUM(E11:E16) -> 0 | F10: =SUM(F11:F16) -> 0 | G10: =SUM(G11:G16) -> 0 | H10: =SUM(H11:H16) -> 0 | I10: =SUM(I11:I16) -> 0 | J10: =SUM(J11:J16) -> 0 | ... AH10: =SUM(AH11:AH16) -> 0
A11: RTD | B11: WP1 | AH11: =SUM(C11:AG11) -> 0
A12: RTD | B12: WP2 | AH12: =SUM(C12:AG12) -> 0
A13: RTD | B13: WP3 | AH13: =SUM(C13:AG13) -> 0
A14: RTD | B14: WP6 | AH14: =SUM(C14:AG14) -> 0
A15: OTH | B15: WP9 | AH15: =SUM(C15:AG15) -> 0
A16: MNGT | B16: WP11 | AH16: =SUM(C16:AG16) -> 0
A17: Project Y | C17: =SUM(C18:C24) -> 0 | D17: =SUM(D18:D24) -> 0 | E17: =SUM(E18:E24) -> 0 | F17: =SUM(F18:F24) -> 0 | G17: =SUM(G18:G24) -> 0 | H17: =SUM(H18:H24) -> 0 | I17: =SUM(I18:I24) -> 0 | J17: =SUM(J18:J24) -> 0 | ... AH17: =SUM(AH18:AH24) -> 0
A18: RTD | B18: WP1 | AH18: =SUM(C18:AG18) -> 0
A19: RTD | B19: WP2 | AH19: =SUM(C19:AG19) -> 0
A20: RTD | B20: WP3 | AH20: =SUM(C20:AG20) -> 0
A21: RTD | B21: WP4 | AH21: =SUM(C21:AG21) -> 0
A22: RTD | B22: WP6 | AH22: =SUM(C22:AG22) -> 0
A23: OTH | B23: WP7 | AH23: =SUM(C23:AG23) -> 0
A24: MNGT | B24: WP8 | AH24: =SUM(C24:AG24) -> 0
A25: Total EU Projects | C25: =C10+C17 -> 0 | D25: =D10+D17 -> 0 | E25: =E10+E17 -> 0 | F25: =F10+F17 -> 0 | G25: =G10+G17 -> 0 | H25: =H10+H17 -> 0 | I25: =I10+I17 -> 0 | J25: =J10+J17 -> 0 | ... AH25: =AH10+AH17 -> 0
A27: Other Productive Hours
A28: Other projects | AH28: =SUM(C28:AG28) -> 0
A29: Teaching | AH29: =SUM(C29:AG29) -> 0
A30: xxxxx | AH30: =SUM(C30:AG30) -> 0
A31: yyyyy | AH31: =SUM(C31:AG31) -> 0
A32: zzzzz | AH32: =SUM(C32:AG32) -> 0
A33: Total Other Productive Hours | C33: =SUM(C28:C32) -> 0 | D33: =SUM(D28:D32) -> 0 | E33: =SUM(E28:E32) -> 0 | F33: =SUM(F28:F32) -> 0 | G33: =SUM(G28:G32) -> 0 | H33: =SUM(H28:H32) -> 0 | I33: =SUM(I28:I32) -> 0 | J33: =SUM(J28:J32) -> 0 | ... AH33: =SUM(AH28:AH32) -> 0
A35: Total Productive Hours | C35: =C25+C33 -> 0 | D35: =D25+D33 -> 0 | E35: =E25+E33 -> 0 | F35: =F25+F33 -> 0 | G35: =G25+G33 -> 0 | H35: =H25+H33 -> 0 | I35: =I25+I33 -> 0 | J35: =J25+J33 -> 0 | ... AH35: =AH25+AH33 -> 0
A37: Non Productive Hours
A38: Annual Leave | AH38: =SUM(C38:AG38) -> 0
A39: Special Leave | AH39: =SUM(C39:AG39) -> 0
A40: Illness | AH40: =SUM(C40:AG40) -> 0
A41: Training / internal meetings | AH41: =SUM(C41:AG41) -> 0
A42: Total Non-Productive Hours | C42: =SUM(C38:C41) -> 0 | D42: =SUM(D38:D41) -> 0 | E42: =SUM(E38:E41) -> 0 | F42: =SUM(F38:F41) -> 0 | G42: =SUM(G38:G41) -> 0 | H42: =SUM(H38:H41) -> 0 | I42: =SUM(I38:I41) -> 0 | J42: =SUM(J38:J41) -> 0 | ... AH42: =SUM(AH38:AH41) -> 0
AH43: =SUM(C43:AG43) -> 0
A44: Total Hours (Productive + Non Productive) | C44: =C35+C42 -> 0 | D44: =D35+D42 -> 0 | E44: =E35+E42 -> 0 | F44: =F35+F42 -> 0 | G44: =G35+G42 -> 0 | H44: =H35+H42 -> 0 | I44: =I35+I42 -> 0 | J44: =J35+J42 -> 0 | ... AH44: =AH35+AH42 -> 0
A46: Signed: | C46: Date and Signature
A47: ='1'!A47 -> 0 | C47: 03/08/2018
...
