Workbook

Sheet 2020 Eylül
A1: Birim Kodu | B1: Birim Adı | C1: Tür | D1: KA-Klasör | E1: KA-Dosya | F1: BA-Klasör | G1: BA-Dosya | H1: BA-Cilt | I1: Kutu / Koli Sayısı | J1: Karşılanan İstekler (Mail /Telefon) | K1: Yararlanma | L1: Birim Ziyaretleri Devir İşlemleri Gün Sayısı
A2: ALP/PGO | B2: ALP / Araştırma Projeleri Geliştirme Ofisi | C2: Akademik | D2: 0 | E2: 0 | F2: 0 | G2: 0 | H2: 0 | I2: 0 | J2: 0 | K2: 0 | L2: 0
A3: ALP/PYO | B3: ALP / Araştırma Projeleri Yönetim Ofisi | C3: Akademik | D3: 0 | E3: 0 | F3: 0 | G3: 0 | H3: 0 | I3: 0 | J3: 0 | K3: 0 | L3: 0
A4: ALP | B4: ALP / Direktörlük | C4: Akademik | D4: 0 | E4: 0 | F4: 0 | G4: 0 | H4: 0 | I4: 0 | J4: 0 | K4: 0 | L4: 0
A5: ALP/İLO | B5: ALP/Sanayi İşbirlikleri ve Teknoloji Lisanslama Ofisi | C5: Akademik | D5: 0 | E5: 0 | F5: 0 | G5: 0 | H5: 0 | I5: 0 | J5: 0 | K5: 0 | L5: 0
A6: APG | B6: Araştırma Süreci Planlama ve Politika Geliştirme Ofisi | C6: Akademik | D6: 0 | E6: 0 | F6: 0 | G6: 0 | H6: 0 | I6: 0 | J6: 0 | K6: 0 | L6: 0
A7: BAGEM | B7: Bireysel Ve Akademik Gelişim Merkezi | C7: Akademik | D7: 0 | E7: 0 | F7: 0 | G7: 0 | H7: 0 | I7: 0 | J7: 0 | K7: 0 | L7: 0
A8: BM | B8: Bilgi Merkezi | C8: İdari | D8: 0 | E8: 0 | F8: 0 | G8: 0 | H8: 0 | I8: 0 | J8: 0 | K8: 0 | L8: 0
A9: BT | B9: Bilgi Teknolojisi | C9: İdari | D9: 0 | E9: 0 | F9: 0 | G9: 0 | H9: 0 | I9: 0 | J9: 0 | K9: 0 | L9: 0
A10: DO | B10: Diller okulu | C10: Akademik | D10: 0 | E10: 0 | F10: 0 | G10: 0 | H10: 0 | I10: 0 | J10: 0 | K10: 0 | L10: 0
A11: ERG | B11: Eğitim Reformu Girişimi | C11: Akademik | D11: 0 | E11: 0 | F11: 0 | G11: 0 | H11: 0 | I11: 0 | J11: 0 | K11: 0 | L11: 0
A12: GS | B12: Genel Sekreterlik | C12: İdari | D12: 0 | E12: 0 | F12: 0 | G12: 0 | H12: 0 | I12: 0 | J12: 0 | K12: 0 | L12: 0
A13: HZ/HG | B13: Hizmetler Güvenlik | C13: İdari | D13: 0 | E13: 0 | F13: 0 | G13: 0 | H13: 0 | I13: 0 | J13: 0 | K13: 0 | L13: 0
... A43: YBF | B43: Yönetim Bilimleri Fakültesi | C43: Fakülteler | D43: 0 | E43: 0 | F43: 0 | G43: 0 | H43: 0 | I43: 0 | J43: 0 | K43: 0 | L43: 0
C44: Toplam | D44: =SUM(D1:D43) -> 0 | E44: =SUM(E1:E43) -> 0 | F44: =SUM(F1:F43) -> 0 | G44: =SUM(G1:G43) -> 0 | H44: 0 | I44: 0 | J44: 0 | K44: 0 | L44: 0
C45: Genel Toplam | D45: =D44+E44 -> 0 | F45: =SUM(F44,G44,H44) -> 0
C46: Son Envanter
C47: Fark

Sheet 2020 Ekim
A1: Birim Kodu | B1: Birim Adı | C1: Tür | D1: KA-Klasör | E1: KA-Dosya | F1: BA-Klasör | G1: BA-Dosya | H1: BA-Cilt | I1: Kutu / Koli Sayısı | J1: Karşılanan İstekler (Mail /Telefon) | K1: Yararlanma | L1: Birim Ziyaretleri Devir İşlemleri Gün Sayısı
A2: ALP/PGO | B2: ALP / Araştırma Projeleri Geliştirme Ofisi | C2: Akademik | D2: 0 | E2: 0 | F2: 0 | G2: 0 | H2: 0 | I2: 0 | J2: 0 | K2: 0 | L2: 0
A3: ALP/PYO | B3: ALP / Araştırma Projeleri Yönetim Ofisi | C3: Akademik | D3: 0 | E3: 0 | F3: 0 | G3: 0 | H3: 0 | I3: 0 | J3: 0 | K3: 0 | L3: 0
A4: ALP | B4: ALP / Direktörlük | C4: Akademik | D4: 0 | E4: 0 | F4: 0 | G4: 0 | H4: 0 | I4: 0 | J4: 0 | K4: 0 | L4: 0
A5: ALP/İLO | B5: ALP/Sanayi İşbirlikleri ve Teknoloji Lisanslama Ofisi | C5: Akademik | D5: 0 | E5: 0 | F5: 0 | G5: 0 | H5: 0 | I5: 0 | J5: 0 | K5: 0 | L5: 0
A6: APG | B6: Araştırma Süreci Planlama ve Politika Geliştirme Ofisi | C6: Akademik | D6: 0 | E6: 0 | F6: 0 | G6: 0 | H6: 0 | I6: 0 | J6: 0 | K6: 0 | L6: 0
A7: BAGEM | B7: Bireysel Ve Akademik Gelişim Merkezi | C7: Akademik | D7: 0 | E7: 0 | F7: 0 | G7: 0 | H7: 0 | I7: 0 | J7: 0 | K7: 0 | L7: 0
A8: BM | B8: Bilgi Merkezi | C8: İdari | D8: 0 | E8: 0 | F8: 0 | G8: 0 | H8: 0 | I8: 0 | J8: 0 | K8: 0 | L8: 0
A9: BT | B9: Bilgi Teknolojisi | C9: İdari | D9: 0 | E9: 0 | F9: 0 | G9: 0 | H9: 0 | I9: 0 | J9: 0 | K9: 0 | L9: 0
A10: DO | B10: Diller okulu | C10: Akademik | D10: 0 | E10: 0 | F10: 0 | G10: 0 | H10: 0 | I10: 0 | J10: 0 | K10: 0 | L10: 0
A11: ERG | B11: Eğitim Reformu Girişimi | C11: Akademik | D11: 0 | E11: 0 | F11: 0 | G11: 0 | H11: 0 | I11: 0 | J11: 0 | K11: 0 | L11: 0
A12: GS | B12: Genel Sekreterlik | C12: İdari | D12: 0 | E12: 0 | F12: 0 | G12: 0 | H12: 0 | I12: 0 | J12: 0 | K12: 0 | L12: 0
A13: HZ/HG | B13: Hizmetler Güvenlik | C13: İdari | D13: 0 | E13: 0 | F13: 0 | G13: 0 | H13: 0 | I13: 0 | J13: 0 | K13: 0 | L13: 0
... A43: YBF | B43: Yönetim Bilimleri Fakültesi | C43: Fakülteler | D43: 0 | E43: 0 | F43: 0 | G43: 0 | H43: 0 | I43: 0 | J43: 0 | K43: 0 | L43: 0
C44: Toplam | D44: =SUM(D1:D43) -> 0 | E44: =SUM(E1:E43) -> 0 | F44: =SUM(F1:F43) -> 0 | G44: =SUM(G1:G43) -> 0 | H44: 0 | I44: 0 | J44: 0 | K44: 0 | L44: 0
C45: Genel Toplam | D45: =D44+E44 -> 0 | F45: =SUM(F44,G44,H44) -> 0
C46: Son Envanter
C47: Fark

Sheet 2020 Kasım
A1: Birim Kodu | B1: Birim Adı | C1: Tür | D1: KA-Klasör | E1: KA-Dosya | F1: BA-Klasör | G1: BA-Dosya | H1: BA-Cilt | I1: Kutu / Koli Sayısı | J1: Karşılanan İstekler (Mail /Telefon) | K1: Yararlanma | L1: Birim Ziyaretleri Devir İşlemleri Gün Sayısı
A2: ALP/PGO | B2: ALP / Araştırma Projeleri Geliştirme Ofisi | C2: Akademik | D2: 0 | E2: 0 | F2: 0 | G2: 0 | H2: 0 | I2: 0 | J2: 0 | K2: 0 | L2: 0
A3: ALP/PYO | B3: ALP / Araştırma Projeleri Yönetim Ofisi | C3: Akademik | D3: 0 | E3: 0 | F3: 0 | G3: 0 | H3: 0 | I3: 0 | J3: 0 | K3: 0 | L3: 0
A4: ALP | B4: ALP / Direktörlük | C4: Akademik | D4: 0 | E4: 0 | F4: 0 | G4: 0 | H4: 0 | I4: 0 | J4: 0 | K4: 0 | L4: 0
A5: ALP/İLO | B5: ALP/Sanayi İşbirlikleri ve Teknoloji Lisanslama Ofisi | C5: Akademik | D5: 0 | E5: 0 | F5: 0 | G5: 0 | H5: 0 | I5: 0 | J5: 0 | K5: 0 | L5: 0
A6: APG | B6: Araştırma Süreci Planlama ve Politika Geliştirme Ofisi | C6: Akademik | D6: 0 | E6: 0 | F6: 0 | G6: 0 | H6: 0 | I6: 0 | J6: 0 | K6: 0 | L6: 0
A7: BAGEM | B7: Bireysel Ve Akademik Gelişim Merkezi | C7: Akademik | D7: 0 | E7: 0 | F7: 0 | G7: 0 | H7: 0 | I7: 0 | J7: 0 | K7: 0 | L7: 0
A8: BM | B8: Bilgi Merkezi | C8: İdari | D8: 0 | E8: 0 | F8: 0 | G8: 0 | H8: 0 | I8: 0 | J8: 0 | K8: 0 | L8: 0
A9: BT | B9: Bilgi Teknolojisi | C9: İdari | D9: 0 | E9: 0 | F9: 0 | G9: 0 | H9: 0 | I9: 0 | J9: 0 | K9: 0 | L9: 0
A10: DO | B10: Diller okulu | C10: Akademik | D10: 0 | E10: 0 | F10: 0 | G10: 0 | H10: 0 | I10: 0 | J10: 0 | K10: 0 | L10: 0
A11: ERG | B11: Eğitim Reformu Girişimi | C11: Akademik | D11: 0 | E11: 0 | F11: 0 | G11: 0 | H11: 0 | I11: 0 | J11: 0 | K11: 0 | L11: 0
A12: GS | B12: Genel Sekreterlik | C12: İdari | D12: 0 | E12: 0 | F12: 0 | G12: 0 | H12: 0 | I12: 0 | J12: 0 | K12: 0 | L12: 0
A13: HZ/HG | B13: Hizmetler Güvenlik | C13: İdari | D13: 0 | E13: 0 | F13: 0 | G13: 0 | H13: 0 | I13: 0 | J13: 0 | K13: 0 | L13: 0
... A43: YBF | B43: Yönetim Bilimleri Fakültesi | C43: Fakülteler | D43: 0 | E43: 0 | F43: 0 | G43: 0 | H43: 0 | I43: 0 | J43: 0 | K43: 0 | L43: 0
C44: Toplam | D44: =SUM(D1:D43) -> 0 | E44: =SUM(E1:E43) -> 0 | F44: =SUM(F1:F43) -> 0 | G44: =SUM(G1:G43) -> 0 | H44: 0 | I44: 0 | J44: 0 | K44: 0 | L44: 0
C45: Genel Toplam | D45: =D44+E44 -> 0 | F45: =SUM(F44,G44,H44) -> 0
C46: Son Envanter
C47: Fark

Sheet 2020 Aralık
A1: Birim Kodu | B1: Birim Adı | C1: Tür | D1: KA-Klasör | E1: KA-Dosya | F1: BA-Klasör | G1: BA-Dosya | H1: BA-Cilt | I1: Kutu / Koli Sayısı | J1: Karşılanan İstekler (Mail /Telefon) | K1: Yararlanma | L1: Birim Ziyaretleri Devir İşlemleri Gün Sayısı
A2: ALP/PGO | B2: ALP / Araştırma Projeleri Geliştirme Ofisi | C2: Akademik | D2: 0 | E2: 0 | F2: 0 | G2: 0 | H2: 0 | I2: 0 | J2: 0 | K2: 0 | L2: 0
A3: ALP/PYO | B3: ALP / Araştırma Projeleri Yönetim Ofisi | C3: Akademik | D3: 0 | E3: 0 | F3: 0 | G3: 0 | H3: 0 | I3: 0 | J3: 0 | K3: 0 | L3: 0
A4: ALP | B4: ALP / Direktörlük | C4: Akademik | D4: 0 | E4: 0 | F4: 0 | G4: 0 | H4: 0 | I4: 0 | J4: 0 | K4: 0 | L4: 0
A5: ALP/İLO | B5: ALP/Sanayi İşbirlikleri ve Teknoloji Lisanslama Ofisi | C5: Akademik | D5: 0 | E5: 0 | F5: 0 | G5: 0 | H5: 0 | I5: 0 | J5: 0 | K5: 0 | L5: 0
A6: APG | B6: Araştırma Süreci Planlama ve Politika Geliştirme Ofisi | C6: Akademik | D6: 0 | E6: 0 | F6: 0 | G6: 0 | H6: 0 | I6: 0 | J6: 0 | K6: 0 | L6: 0
A7: BAGEM | B7: Bireysel Ve Akademik Gelişim Merkezi | C7: Akademik | D7: 0 | E7: 0 | F7: 0 | G7: 0 | H7: 0 | I7: 0 | J7: 0 | K7: 0 | L7: 0
A8: BM | B8: Bilgi Merkezi | C8: İdari | D8: 0 | E8: 0 | F8: 0 | G8: 0 | H8: 0 | I8: 0 | J8: 0 | K8: 0 | L8: 0
A9: BT | B9: Bilgi Teknolojisi | C9: İdari | D9: 0 | E9: 0 | F9: 0 | G9: 0 | H9: 0 | I9: 0 | J9: 0 | K9: 0 | L9: 0
A10: DO | B10: Diller okulu | C10: Akademik | D10: 0 | E10: 0 | F10: 0 | G10: 0 | H10: 0 | I10: 0 | J10: 0 | K10: 0 | L10: 0
A11: ERG | B11: Eğitim Reformu Girişimi | C11: Akademik | D11: 0 | E11: 0 | F11: 0 | G11: 0 | H11: 0 | I11: 0 | J11: 0 | K11: 0 | L11: 0
A12: GS | B12: Genel Sekreterlik | C12: İdari | D12: 0 | E12: 0 | F12: 0 | G12: 0 | H12: 0 | I12: 0 | J12: 0 | K12: 0 | L12: 0
A13: HZ/HG | B13: Hizmetler Güvenlik | C13: İdari | D13: 0 | E13: 0 | F13: 0 | G13: 0 | H13: 0 | I13: 0 | J13: 0 | K13: 0 | L13: 0
... A43: YBF | B43: Yönetim Bilimleri Fakültesi | C43: Fakülteler | D43: 0 | E43: 0 | F43: 0 | G43: 0 | H43: 0 | I43: 0 | J43: 0 | K43: 0 | L43: 0
C44: Toplam | D44: =SUM(D1:D43) -> 0 | E44: =SUM(E1:E43) -> 0 | F44: =SUM(F1:F43) -> 0 | G44: =SUM(G1:G43) -> 0 | H44: 0 | I44: 0 | J44: 0 | K44: 0 | L44: 0
C45: Genel Toplam | D45: =D44+E44 -> 0 | F45: =SUM(F44,G44,H44) -> 0
C46: Son Envanter
C47: Fark

Sheet 2021 Ocak
A1: Birim Kodu | B1: Birim Adı | C1: Tür | D1: KA-Klasör | E1: KA-Dosya | F1: BA-Klasör | G1: BA-Dosya | H1: BA-Cilt | I1: Kutu / Koli Sayısı | J1: Karşılanan İstekler (Mail /Telefon) | K1: Yararlanma | L1: Birim Ziyaretleri Devir İşlemleri Gün Sayısı
A2: ALP/PGO | B2: ALP / Araştırma Projeleri Geliştirme Ofisi | C2: Akademik | D2: 0 | E2: 0 | F2: 0 | G2: 0 | H2: 0 | I2: 0 | J2: 0 | K2: 0 | L2: 0
A3: ALP/PYO | B3: ALP / Araştırma Projeleri Yönetim Ofisi | C3: Akademik | D3: 0 | E3: 0 | F3: 0 | G3: 0 | H3: 0 | I3: 0 | J3: 0 | K3: 0 | L3: 0
A4: ALP | B4: ALP / Direktörlük | C4: Akademik | D4: 0 | E4: 0 | F4: 0 | G4: 0 | H4: 0 | I4: 0 | J4: 0 | K4: 0 | L4: 0
A5: ALP/İLO | B5: ALP/Sanayi İşbirlikleri ve Teknoloji Lisanslama Ofisi | C5: Akademik | D5: 0 | E5: 0 | F5: 0 | G5: 0 | H5: 0 | I5: 0 | J5: 0 | K5: 0 | L5: 0
A6: APG | B6: Araştırma Süreci Planlama ve Politika Geliştirme Ofisi | C6: Akademik | D6: 0 | E6: 0 | F6: 0 | G6: 0 | H6: 0 | I6: 0 | J6: 0 | K6: 0 | L6: 0
A7: BAGEM | B7: Bireysel Ve Akademik Gelişim Merkezi | C7: Akademik | D7: 0 | E7: 0 | F7: 0 | G7: 0 | H7: 0 | I7: 0 | J7: 0 | K7: 0 | L7: 0
A8: BM | B8: Bilgi Merkezi | C8: İdari | D8: 0 | E8: 0 | F8: 0 | G8: 0 | H8: 0 | I8: 0 | J8: 0 | K8: 0 | L8: 0
A9: BT | B9: Bilgi Teknolojisi | C9: İdari | D9: 0 | E9: 0 | F9: 0 | G9: 0 | H9: 0 | I9: 0 | J9: 0 | K9: 0 | L9: 0
A10: DO | B10: Diller okulu | C10: Akademik | D10: 0 | E10: 0 | F10: 0 | G10: 0 | H10: 0 | I10: 0 | J10: 0 | K10: 0 | L10: 0
A11: ERG | B11: Eğitim Reformu Girişimi | C11: Akademik | D11: 0 | E11: 0 | F11: 0 | G11: 0 | H11: 0 | I11: 0 | J11: 0 | K11: 0 | L11: 0
A12: GS | B12: Genel Sekreterlik | C12: İdari | D12: 0 | E12: 0 | F12: 0 | G12: 0 | H12: 0 | I12: 0 | J12: 0 | K12: 0 | L12: 0
A13: HZ/HG | B13: Hizmetler Güvenlik | C13: İdari | D13: 0 | E13: 0 | F13: 0 | G13: 0 | H13: 0 | I13: 0 | J13: 0 | K13: 0 | L13: 0
... A43: YBF | B43: Yönetim Bilimleri Fakültesi | C43: Fakülteler | D43: 0 | E43: 0 | F43: 0 | G43: 0 | H43: 0 | I43: 0 | J43: 0 | K43: 0 | L43: 0
C44: Toplam | D44: =SUM(D1:D43) -> 0 | E44: =SUM(E1:E43) -> 0 | F44: =SUM(F1:F43) -> 0 | G44: =SUM(G1:G43) -> 0 | H44: 0 | I44: 0 | J44: 0 | K44: 0 | L44: 0
C45: Genel Toplam | D45: =D44+E44 -> 0 | F45: =SUM(F44,G44,H44) -> 0
C46: Son Envanter
C47: Fark

Sheet 2021 Şubat
A1: Birim Kodu | B1: Birim Adı | C1: Tür | D1: KA-Klasör | E1: KA-Dosya | F1: BA-Klasör | G1: BA-Dosya | H1: BA-Cilt | I1: Kutu / Koli Sayısı | J1: Karşılanan İstekler (Mail /Telefon) | K1: Yararlanma | L1: Birim Ziyaretleri Devir İşlemleri Gün Sayısı
A2: ALP/PGO | B2: ALP / Araştırma Projeleri Geliştirme Ofisi | C2: Akademik | D2: 0 | E2: 0 | F2: 0 | G2: 0 | H2: 0 | I2: 0 | J2: 0 | K2: 0 | L2: 0
A3: ALP/PYO | B3: ALP / Araştırma Projeleri Yönetim Ofisi | C3: Akademik | D3: 0 | E3: 0 | F3: 0 | G3: 0 | H3: 0 | I3: 0 | J3: 0 | K3: 0 | L3: 0
A4: ALP | B4: ALP / Direktörlük | C4: Akademik | D4: 0 | E4: 0 | F4: 0 | G4: 0 | H4: 0 | I4: 0 | J4: 0 | K4: 0 | L4: 0
A5: ALP/İLO | B5: ALP/Sanayi İşbirlikleri ve Teknoloji Lisanslama Ofisi | C5: Akademik | D5: 0 | E5: 0 | F5: 0 | G5: 0 | H5: 0 | I5: 0 | J5: 0 | K5: 0 | L5: 0
A6: APG | B6: Araştırma Süreci Planlama ve Politika Geliştirme Ofisi | C6: Akademik | D6: 0 | E6: 0 | F6: 0 | G6: 0 | H6: 0 | I6: 0 | J6: 0 | K6: 0 | L6: 0
A7: BAGEM | B7: Bireysel Ve Akademik Gelişim Merkezi | C7: Akademik | D7: 0 | E7: 0 | F7: 0 | G7: 0 | H7: 0 | I7: 0 | J7: 0 | K7: 0 | L7: 0
A8: BM | B8: Bilgi Merkezi | C8: İdari | D8: 0 | E8: 0 | F8: 0 | G8: 0 | H8: 0 | I8: 0 | J8: 0 | K8: 0 | L8: 0
A9: BT | B9: Bilgi Teknolojisi | C9: İdari | D9: 0 | E9: 0 | F9: 0 | G9: 0 | H9: 0 | I9: 0 | J9: 0 | K9: 0 | L9: 0
A10: DO | B10: Diller okulu | C10: Akademik | D10: 0 | E10: 0 | F10: 0 | G10: 0 | H10: 0 | I10: 0 | J10: 0 | K10: 0 | L10: 0
A11: ERG | B11: Eğitim Reformu Girişimi | C11: Akademik | D11: 0 | E11: 0 | F11: 0 | G11: 0 | H11: 0 | I11: 0 | J11: 0 | K11: 0 | L11: 0
A12: GS | B12: Genel Sekreterlik | C12: İdari | D12: 0 | E12: 0 | F12: 0 | G12: 0 | H12: 0 | I12: 0 | J12: 0 | K12: 0 | L12: 0
A13: HZ/HG | B13: Hizmetler Güvenlik | C13: İdari | D13: 0 | E13: 0 | F13: 0 | G13: 0 | H13: 0 | I13: 0 | J13: 0 | K13: 0 | L13: 0
... A43: YBF | B43: Yönetim Bilimleri Fakültesi | C43: Fakülteler | D43: 0 | E43: 0 | F43: 0 | G43: 0 | H43: 0 | I43: 0 | J43: 0 | K43: 0 | L43: 0
C44: Toplam | D44: =SUM(D1:D43) -> 0 | E44: =SUM(E1:E43) -> 0 | F44: =SUM(F1:F43) -> 0 | G44: =SUM(G1:G43) -> 0 | H44: 0 | I44: 0 | J44: 0 | K44: 0 | L44: 0
C45: Genel Toplam | D45: =D44+E44 -> 0 | F45: =SUM(F44,G44,H44) -> 0
C46: Son Envanter
C47: Fark

Sheet 2021 Mart
A1: Birim Kodu | B1: Birim Adı | C1: Tür | D1: KA-Klasör | E1: KA-Dosya | F1: BA-Klasör | G1: BA-Dosya | H1: BA-Cilt | I1: Kutu / Koli Sayısı | J1: Karşılanan İstekler (Mail /Telefon) | K1: Yararlanma | L1: Birim Ziyaretleri Devir İşlemleri Gün Sayısı
A2: ALP/PGO | B2: ALP / Araştırma Projeleri Geliştirme Ofisi | C2: Akademik | D2: 0 | E2: 0 | F2: 0 | G2: 0 | H2: 0 | I2: 0 | J2: 0 | K2: 0 | L2: 0
A3: ALP/PYO | B3: ALP / Araştırma Projeleri Yönetim Ofisi | C3: Akademik | D3: 0 | E3: 0 | F3: 0 | G3: 0 | H3: 0 | I3: 0 | J3: 0 | K3: 0 | L3: 0
A4: ALP | B4: ALP / Direktörlük | C4: Akademik | D4: 0 | E4: 0 | F4: 0 | G4: 0 | H4: 0 | I4: 0 | J4: 0 | K4: 0 | L4: 0
A5: ALP/İLO | B5: ALP/Sanayi İşbirlikleri ve Teknoloji Lisanslama Ofisi | C5: Akademik | D5: 0 | E5: 0 | F5: 0 | G5: 0 | H5: 0 | I5: 0 | J5: 0 | K5: 0 | L5: 0
A6: APG | B6: Araştırma Süreci Planlama ve Politika Geliştirme Ofisi | C6: Akademik | D6: 0 | E6: 0 | F6: 0 | G6: 0 | H6: 0 | I6: 0 | J6: 0 | K6: 0 | L6: 0
A7: BAGEM | B7: Bireysel Ve Akademik Gelişim Merkezi | C7: Akademik | D7: 0 | E7: 0 | F7: 0 | G7: 0 | H7: 0 | I7: 0 | J7: 0 | K7: 0 | L7: 0
A8: BM | B8: Bilgi Merkezi | C8: İdari | D8: 0 | E8: 0 | F8: 0 | G8: 0 | H8: 0 | I8: 0 | J8: 0 | K8: 0 | L8: 0
A9: BT | B9: Bilgi Teknolojisi | C9: İdari | D9: 0 | E9: 0 | F9: 0 | G9: 0 | H9: 0 | I9: 0 | J9: 0 | K9: 0 | L9: 0
A10: DO | B10: Diller okulu | C10: Akademik | D10: 0 | E10: 0 | F10: 0 | G10: 0 | H10: 0 | I10: 0 | J10: 0 | K10: 0 | L10: 0
A11: ERG | B11: Eğitim Reformu Girişimi | C11: Akademik | D11: 0 | E11: 0 | F11: 0 | G11: 0 | H11: 0 | I11: 0 | J11: 0 | K11: 0 | L11: 0
A12: GS | B12: Genel Sekreterlik | C12: İdari | D12: 0 | E12: 0 | F12: 0 | G12: 0 | H12: 0 | I12: 0 | J12: 0 | K12: 0 | L12: 0
A13: HZ/HG | B13: Hizmetler Güvenlik | C13: İdari | D13: 0 | E13: 0 | F13: 0 | G13: 0 | H13: 0 | I13: 0 | J13: 0 | K13: 0 | L13: 0
... A43: YBF | B43: Yönetim Bilimleri Fakültesi | C43: Fakülteler | D43: 0 | E43: 0 | F43: 0 | G43: 0 | H43: 0 | I43: 0 | J43: 0 | K43: 0 | L43: 0
C44: Toplam | D44: =SUM(D1:D43) -> 0 | E44: =SUM(E1:E43) -> 0 | F44: =SUM(F1:F43) -> 0 | G44: =SUM(G1:G43) -> 0 | H44: 0 | I44: 0 | J44: 0 | K44: 0 | L44: 0
C45: Genel Toplam | D45: =D44+E44 -> 0 | F45: =SUM(F44,G44,H44) -> 0
C46: Son Envanter
C47: Fark

Sheet 2021 Nisan
A1: Birim Kodu | B1: Birim Adı | C1: Tür | D1: KA-Klasör | E1: KA-Dosya | F1: BA-Klasör | G1: BA-Dosya | H1: BA-Cilt | I1: Kutu / Koli Sayısı | J1: Karşılanan İstekler (Mail /Telefon) | K1: Yararlanma | L1: Birim Ziyaretleri Devir İşlemleri Gün Sayısı
A2: ALP/PGO | B2: ALP / Araştırma Projeleri Geliştirme Ofisi | C2: Akademik | D2: 0 | E2: 0 | F2: 0 | G2: 0 | H2: 0 | I2: 0 | J2: 0 | K2: 0 | L2: 0
A3: ALP/PYO | B3: ALP / Araştırma Projeleri Yönetim Ofisi | C3: Akademik | D3: 0 | E3: 0 | F3: 0 | G3: 0 | H3: 0 | I3: 0 | J3: 0 | K3: 0 | L3: 0
A4: ALP | B4: ALP / Direktörlük | C4: Akademik | D4: 0 | E4: 0 | F4: 0 | G4: 0 | H4: 0 | I4: 0 | J4: 0 | K4: 0 | L4: 0
A5: ALP/İLO | B5: ALP/Sanayi İşbirlikleri ve Teknoloji Lisanslama Ofisi | C5: Akademik | D5: 0 | E5: 0 | F5: 0 | G5: 0 | H5: 0 | I5: 0 | J5: 0 | K5: 0 | L5: 0
A6: APG | B6: Araştırma Süreci Planlama ve Politika Geliştirme Ofisi | C6: Akademik | D6: 0 | E6: 0 | F6: 0 | G6: 0 | H6: 0 | I6: 0 | J6: 0 | K6: 0 | L6: 0
A7: BAGEM | B7: Bireysel Ve Akademik Gelişim Merkezi | C7: Akademik | D7: 0 | E7: 0 | F7: 0 | G7: 0 | H7: 0 | I7: 0 | J7: 0 | K7: 0 | L7: 0
A8: BM | B8: Bilgi Merkezi | C8: İdari | D8: 0 | E8: 0 | F8: 0 | G8: 0 | H8: 0 | I8: 0 | J8: 0 | K8: 0 | L8: 0
A9: BT | B9: Bilgi Teknolojisi | C9: İdari | D9: 0 | E9: 0 | F9: 0 | G9: 0 | H9: 0 | I9: 0 | J9: 0 | K9: 0 | L9: 0
A10: DO | B10: Diller okulu | C10: Akademik | D10: 0 | E10: 0 | F10: 0 | G10: 0 | H10: 0 | I10: 0 | J10: 0 | K10: 0 | L10: 0
A11: ERG | B11: Eğitim Reformu Girişimi | C11: Akademik | D11: 0 | E11: 0 | F11: 0 | G11: 0 | H11: 0 | I11: 0 | J11: 0 | K11: 0 | L11: 0
A12: GS | B12: Genel Sekreterlik | C12: İdari | D12: 0 | E12: 0 | F12: 0 | G12: 0 | H12: 0 | I12: 0 | J12: 0 | K12: 0 | L12: 0
A13: HZ/HG | B13: Hizmetler Güvenlik | C13: İdari | D13: 0 | E13: 0 | F13: 0 | G13: 0 | H13: 0 | I13: 0 | J13: 0 | K13: 0 | L13: 0
... A43: YBF | B43: Yönetim Bilimleri Fakültesi | C43: Fakülteler | D43: 0 | E43: 0 | F43: 0 | G43: 0 | H43: 0 | I43: 0 | J43: 0 | K43: 0 | L43: 0
C44: Toplam | D44: =SUM(D1:D43) -> 0 | E44: =SUM(E1:E43) -> 0 | F44: =SUM(F1:F43) -> 0 | G44: =SUM(G1:G43) -> 0 | H44: 0 | I44: 0 | J44: 0 | K44: 0 | L44: 0
C45: Genel Toplam | D45: =D44+E44 -> 0 | F45: =SUM(F44,G44,H44) -> 0
C46: Son Envanter
C47: Fark

Sheet 2021 Mayıs
A1: Birim Kodu | B1: Birim Adı | C1: Tür | D1: KA-Klasör | E1: KA-Dosya | F1: BA-Klasör | G1: BA-Dosya | H1: BA-Cilt | I1: Kutu / Koli Sayısı | J1: Karşılanan İstekler (Mail /Telefon) | K1: Yararlanma | L1: Birim Ziyaretleri Devir İşlemleri Gün Sayısı
A2: ALP/PGO | B2: ALP / Araştırma Projeleri Geliştirme Ofisi | C2: Akademik | D2: 0 | E2: 0 | F2: 0 | G2: 0 | H2: 0 | I2: 0 | J2: 0 | K2: 0 | L2: 0
A3: ALP/PYO | B3: ALP / Araştırma Projeleri Yönetim Ofisi | C3: Akademik | D3: 0 | E3: 0 | F3: 0 | G3: 0 | H3: 0 | I3: 0 | J3: 0 | K3: 0 | L3: 0
A4: ALP | B4: ALP / Direktörlük | C4: Akademik | D4: 0 | E4: 0 | F4: 0 | G4: 0 | H4: 0 | I4: 0 | J4: 0 | K4: 0 | L4: 0
A5: ALP/İLO | B5: ALP/Sanayi İşbirlikleri ve Teknoloji Lisanslama Ofisi | C5: Akademik | D5: 0 | E5: 0 | F5: 0 | G5: 0 | H5: 0 | I5: 0 | J5: 0 | K5: 0 | L5: 0
A6: APG | B6: Araştırma Süreci Planlama ve Politika Geliştirme Ofisi | C6: Akademik | D6: 0 | E6: 0 | F6: 0 | G6: 0 | H6: 0 | I6: 0 | J6: 0 | K6: 0 | L6: 0
A7: BAGEM | B7: Bireysel Ve Akademik Gelişim Merkezi | C7: Akademik | D7: 0 | E7: 0 | F7: 0 | G7: 0 | H7: 0 | I7: 0 | J7: 0 | K7: 0 | L7: 0
A8: BM | B8: Bilgi Merkezi | C8: İdari | D8: 0 | E8: 0 | F8: 0 | G8: 0 | H8: 0 | I8: 0 | J8: 0 | K8: 0 | L8: 0
A9: BT | B9: Bilgi Teknolojisi | C9: İdari | D9: 0 | E9: 0 | F9: 0 | G9: 0 | H9: 0 | I9: 0 | J9: 0 | K9: 0 | L9: 0
A10: DO | B10: Diller okulu | C10: Akademik | D10: 0 | E10: 0 | F10: 0 | G10: 0 | H10: 0 | I10: 0 | J10: 0 | K10: 0 | L10: 0
A11: ERG | B11: Eğitim Reformu Girişimi | C11: Akademik | D11: 0 | E11: 0 | F11: 0 | G11: 0 | H11: 0 | I11: 0 | J11: 0 | K11: 0 | L11: 0
A12: GS | B12: Genel Sekreterlik | C12: İdari | D12: 0 | E12: 0 | F12: 0 | G12: 0 | H12: 0 | I12: 0 | J12: 0 | K12: 0 | L12: 0
A13: HZ/HG | B13: Hizmetler Güvenlik | C13: İdari | D13: 0 | E13: 0 | F13: 0 | G13: 0 | H13: 0 | I13: 0 | J13: 0 | K13: 0 | L13: 0
... A43: YBF | B43: Yönetim Bilimleri Fakültesi | C43: Fakülteler | D43: 0 | E43: 0 | F43: 0 | G43: 0 | H43: 0 | I43: 0 | J43: 0 | K43: 0 | L43: 0
C44: Toplam | D44: =SUM(D1:D43) -> 0 | E44: =SUM(E1:E43) -> 0 | F44: =SUM(F1:F43) -> 0 | G44: =SUM(G1:G43) -> 0 | H44: 0 | I44: 0 | J44: 0 | K44: 0 | L44: 0
C45: Genel Toplam | D45: =D44+E44 -> 0 | F45: =SUM(F44,G44,H44) -> 0
C46: Son Envanter
C47: Fark

Sheet 2021 Haziran
A1: Birim Kodu | B1: Birim Adı | C1: Tür | D1: KA-Klasör | E1: KA-Dosya | F1: BA-Klasör | G1: BA-Dosya | H1: BA-Cilt | I1: Kutu / Koli Sayısı | J1: Karşılanan İstekler (Mail /Telefon) | K1: Yararlanma | L1: Birim Ziyaretleri Devir İşlemleri Gün Sayısı
A2: ALP/PGO | B2: ALP / Araştırma Projeleri Geliştirme Ofisi | C2: Akademik | D2: 0 | E2: 0 | F2: 0 | G2: 0 | H2: 0 | I2: 0 | J2: 0 | K2: 0 | L2: 0
A3: ALP/PYO | B3: ALP / Araştırma Projeleri Yönetim Ofisi | C3: Akademik | D3: 0 | E3: 0 | F3: 0 | G3: 0 | H3: 0 | I3: 0 | J3: 0 | K3: 0 | L3: 0
A4: ALP | B4: ALP / Direktörlük | C4: Akademik | D4: 0 | E4: 0 | F4: 0 | G4: 0 | H4: 0 | I4: 0 | J4: 0 | K4: 0 | L4: 0
A5: ALP/İLO | B5: ALP/Sanayi İşbirlikleri ve Teknoloji Lisanslama Ofisi | C5: Akademik | D5: 0 | E5: 0 | F5: 0 | G5: 0 | H5: 0 | I5: 0 | J5: 0 | K5: 0 | L5: 0
A6: APG | B6: Araştırma Süreci Planlama ve Politika Geliştirme Ofisi | C6: Akademik | D6: 0 | E6: 0 | F6: 0 | G6: 0 | H6: 0 | I6: 0 | J6: 0 | K6: 0 | L6: 0
A7: BAGEM | B7: Bireysel Ve Akademik Gelişim Merkezi | C7: Akademik | D7: 0 | E7: 0 | F7: 0 | G7: 0 | H7: 0 | I7: 0 | J7: 0 | K7: 0 | L7: 0
A8: BM | B8: Bilgi Merkezi | C8: İdari | D8: 0 | E8: 0 | F8: 0 | G8: 0 | H8: 0 | I8: 0 | J8: 0 | K8: 0 | L8: 0
A9: BT | B9: Bilgi Teknolojisi | C9: İdari | D9: 0 | E9: 0 | F9: 0 | G9: 0 | H9: 0 | I9: 0 | J9: 0 | K9: 0 | L9: 0
A10: DO | B10: Diller okulu | C10: Akademik | D10: 0 | E10: 0 | F10: 0 | G10: 0 | H10: 0 | I10: 0 | J10: 0 | K10: 0 | L10: 0
A11: ERG | B11: Eğitim Reformu Girişimi | C11: Akademik | D11: 0 | E11: 0 | F11: 0 | G11: 0 | H11: 0 | I11: 0 | J11: 0 | K11: 0 | L11: 0
A12: GS | B12: Genel Sekreterlik | C12: İdari | D12: 0 | E12: 0 | F12: 0 | G12: 0 | H12: 0 | I12: 0 | J12: 0 | K12: 0 | L12: 0
A13: HZ/HG | B13: Hizmetler Güvenlik | C13: İdari | D13: 0 | E13: 0 | F13: 0 | G13: 0 | H13: 0 | I13: 0 | J13: 0 | K13: 0 | L13: 0
... A43: YBF | B43: Yönetim Bilimleri Fakültesi | C43: Fakülteler | D43: 0 | E43: 0 | F43: 0 | G43: 0 | H43: 0 | I43: 0 | J43: 0 | K43: 0 | L43: 0
C44: Toplam | D44: =SUM(D1:D43) -> 0 | E44: =SUM(E1:E43) -> 0 | F44: =SUM(F1:F43) -> 0 | G44: =SUM(G1:G43) -> 0 | H44: 0 | I44: 0 | J44: 0 | K44: 0 | L44: 0
C45: Genel Toplam | D45: =D44+E44 -> 0 | F45: =SUM(F44,G44,H44) -> 0
C46: Son Envanter
C47: Fark

Sheet 2021 Temmuz
A1: Birim Kodu | B1: Birim Adı | C1: Tür | D1: KA-Klasör | E1: KA-Dosya | F1: BA-Klasör | G1: BA-Dosya | H1: BA-Cilt | I1: Kutu / Koli Sayısı | J1: Karşılanan İstekler (Mail /Telefon) | K1: Yararlanma | L1: Birim Ziyaretleri Devir İşlemleri Gün Sayısı
A2: ALP/PGO | B2: ALP / Araştırma Projeleri Geliştirme Ofisi | C2: Akademik | D2: 0 | E2: 0 | F2: 0 | G2: 0 | H2: 0 | I2: 0 | J2: 0 | K2: 0 | L2: 0
A3: ALP/PYO | B3: ALP / Araştırma Projeleri Yönetim Ofisi | C3: Akademik | D3: 0 | E3: 0 | F3: 0 | G3: 0 | H3: 0 | I3: 0 | J3: 0 | K3: 0 | L3: 0
A4: ALP | B4: ALP / Direktörlük | C4: Akademik | D4: 0 | E4: 0 | F4: 0 | G4: 0 | H4: 0 | I4: 0 | J4: 0 | K4: 0 | L4: 0
A5: ALP/İLO | B5: ALP/Sanayi İşbirlikleri ve Teknoloji Lisanslama Ofisi | C5: Akademik | D5: 0 | E5: 0 | F5: 0 | G5: 0 | H5: 0 | I5: 0 | J5: 0 | K5: 0 | L5: 0
A6: APG | B6: Araştırma Süreci Planlama ve Politika Geliştirme Ofisi | C6: Akademik | D6: 0 | E6: 0 | F6: 0 | G6: 0 | H6: 0 | I6: 0 | J6: 0 | K6: 0 | L6: 0
A7: BAGEM | B7: Bireysel Ve Akademik Gelişim Merkezi | C7: Akademik | D7: 0 | E7: 0 | F7: 0 | G7: 0 | H7: 0 | I7: 0 | J7: 0 | K7: 0 | L7: 0
A8: BM | B8: Bilgi Merkezi | C8: İdari | D8: 0 | E8: 0 | F8: 0 | G8: 0 | H8: 0 | I8: 0 | J8: 0 | K8: 0 | L8: 0
A9: BT | B9: Bilgi Teknolojisi | C9: İdari | D9: 0 | E9: 0 | F9: 0 | G9: 0 | H9: 0 | I9: 0 | J9: 0 | K9: 0 | L9: 0
A10: DO | B10: Diller okulu | C10: Akademik | D10: 0 | E10: 0 | F10: 0 | G10: 0 | H10: 0 | I10: 0 | J10: 0 | K10: 0 | L10: 0
A11: ERG | B11: Eğitim Reformu Girişimi | C11: Akademik | D11: 0 | E11: 0 | F11: 0 | G11: 0 | H11: 0 | I11: 0 | J11: 0 | K11: 0 | L11: 0
A12: GS | B12: Genel Sekreterlik | C12: İdari | D12: 0 | E12: 0 | F12: 0 | G12: 0 | H12: 0 | I12: 0 | J12: 0 | K12: 0 | L12: 0
A13: HZ/HG | B13: Hizmetler Güvenlik | C13: İdari | D13: 0 | E13: 0 | F13: 0 | G13: 0 | H13: 0 | I13: 0 | J13: 0 | K13: 0 | L13: 0
... A43: YBF | B43: Yönetim Bilimleri Fakültesi | C43: Fakülteler | D43: 0 | E43: 0 | F43: 0 | G43: 0 | H43: 0 | I43: 0 | J43: 0 | K43: 0 | L43: 0
C44: Toplam | D44: =SUM(D1:D43) -> 0 | E44: =SUM(E1:E43) -> 0 | F44: =SUM(F1:F43) -> 0 | G44: =SUM(G1:G43) -> 0 | H44: 0 | I44: 0 | J44: 0 | K44: 0 | L44: 0
C45: Genel Toplam | D45: =D44+E44 -> 0 | F45: =SUM(F44,G44,H44) -> 0
C46: Son Envanter
C47: Fark

Sheet 2021 Ağustos
A1: Birim Kodu | B1: Birim Adı | C1: Tür | D1: KA-Klasör | E1: KA-Dosya | F1: BA-Klasör | G1: BA-Dosya | H1: BA-Cilt | I1: Kutu / Koli Sayısı | J1: Karşılanan İstekler (Mail /Telefon) | K1: Yararlanma | L1: Birim Ziyaretleri Devir İşlemleri Gün Sayısı
A2: ALP/PGO | B2: ALP / Araştırma Projeleri Geliştirme Ofisi | C2: Akademik | D2: 0 | E2: 0 | F2: 0 | G2: 0 | H2: 0 | I2: 0 | J2: 0 | K2: 0 | L2: 0
A3: ALP/PYO | B3: ALP / Araştırma Projeleri Yönetim Ofisi | C3: Akademik | D3: 0 | E3: 0 | F3: 0 | G3: 0 | H3: 0 | I3: 0 | J3: 0 | K3: 0 | L3: 0
A4: ALP | B4: ALP / Direktörlük | C4: Akademik | D4: 0 | E4: 0 | F4: 0 | G4: 0 | H4: 0 | I4: 0 | J4: 0 | K4: 0 | L4: 0
A5: ALP/İLO | B5: ALP/Sanayi İşbirlikleri ve Teknoloji Lisanslama Ofisi | C5: Akademik | D5: 0 | E5: 0 | F5: 0 | G5: 0 | H5: 0 | I5: 0 | J5: 0 | K5: 0 | L5: 0
A6: APG | B6: Araştırma Süreci Planlama ve Politika Geliştirme Ofisi | C6: Akademik | D6: 0 | E6: 0 | F6: 0 | G6: 0 | H6: 0 | I6: 0 | J6: 0 | K6: 0 | L6: 0
A7: BAGEM | B7: Bireysel Ve Akademik Gelişim Merkezi | C7: Akademik | D7: 0 | E7: 0 | F7: 0 | G7: 0 | H7: 0 | I7: 0 | J7: 0 | K7: 0 | L7: 0
A8: BM | B8: Bilgi Merkezi | C8: İdari | D8: 0 | E8: 0 | F8: 0 | G8: 0 | H8: 0 | I8: 0 | J8: 0 | K8: 0 | L8: 0
A9: BT | B9: Bilgi Teknolojisi | C9: İdari | D9: 0 | E9: 0 | F9: 0 | G9: 0 | H9: 0 | I9: 0 | J9: 0 | K9: 0 | L9: 0
A10: DO | B10: Diller okulu | C10: Akademik | D10: 0 | E10: 0 | F10: 0 | G10: 0 | H10: 0 | I10: 0 | J10: 0 | K10: 0 | L10: 0
A11: ERG | B11: Eğitim Reformu Girişimi | C11: Akademik | D11: 0 | E11: 0 | F11: 0 | G11: 0 | H11: 0 | I11: 0 | J11: 0 | K11: 0 | L11: 0
A12: GS | B12: Genel Sekreterlik | C12: İdari | D12: 0 | E12: 0 | F12: 0 | G12: 0 | H12: 0 | I12: 0 | J12: 0 | K12: 0 | L12: 0
A13: HZ/HG | B13: Hizmetler Güvenlik | C13: İdari | D13: 0 | E13: 0 | F13: 0 | G13: 0 | H13: 0 | I13: 0 | J13: 0 | K13: 0 | L13: 0
... A43: YBF | B43: Yönetim Bilimleri Fakültesi | C43: Fakülteler | D43: 0 | E43: 0 | F43: 0 | G43: 0 | H43: 0 | I43: 0 | J43: 0 | K43: 0 | L43: 0
C44: Toplam | D44: =SUM(D1:D43) -> 0 | E44: =SUM(E1:E43) -> 0 | F44: =SUM(F1:F43) -> 0 | G44: =SUM(G1:G43) -> 0 | H44: 0 | I44: 0 | J44: 0 | K44: 0 | L44: 0
C45: Genel Toplam | D45: =D44+E44 -> 0 | F45: =SUM(F44,G44,H44) -> 0
C46: Son Envanter
C47: Fark

Sheet 2021 Eylül
A1: Birim Kodu | B1: Birim Adı | C1: Tür | D1: KA-Klasör | E1: KA-Dosya | F1: BA-Klasör | G1: BA-Dosya | H1: BA-Cilt | I1: Kutu / Koli Sayısı | J1: Karşılanan İstekler (Mail /Telefon) | K1: Yararlanma | L1: Birim Ziyaretleri Devir İşlemleri Gün Sayısı
A2: ALP/PGO | B2: ALP / Araştırma Projeleri Geliştirme Ofisi | C2: Akademik | D2: 0 | E2: 0 | F2: 0 | G2: 0 | H2: 0 | I2: 0 | J2: 0 | K2: 0 | L2: 0
A3: ALP/PYO | B3: ALP / Araştırma Projeleri Yönetim Ofisi | C3: Akademik | D3: 0 | E3: 0 | F3: 0 | G3: 0 | H3: 0 | I3: 0 | J3: 0 | K3: 0 | L3: 0
A4: ALP | B4: ALP / Direktörlük | C4: Akademik | D4: 0 | E4: 0 | F4: 0 | G4: 0 | H4: 0 | I4: 0 | J4: 0 | K4: 0 | L4: 0
A5: ALP/İLO | B5: ALP/Sanayi İşbirlikleri ve Teknoloji Lisanslama Ofisi | C5: Akademik | D5: 0 | E5: 0 | F5: 0 | G5: 0 | H5: 0 | I5: 0 | J5: 0 | K5: 0 | L5: 0
A6: APG | B6: Araştırma Süreci Planlama ve Politika Geliştirme Ofisi | C6: Akademik | D6: 0 | E6: 0 | F6: 0 | G6: 0 | H6: 0 | I6: 0 | J6: 0 | K6: 0 | L6: 0
A7: BAGEM | B7: Bireysel Ve Akademik Gelişim Merkezi | C7: Akademik | D7: 0 | E7: 0 | F7: 0 | G7: 0 | H7: 0 | I7: 0 | J7: 0 | K7: 0 | L7: 0
A8: BM | B8: Bilgi Merkezi | C8: İdari | D8: 0 | E8: 0 | F8: 0 | G8: 0 | H8: 0 | I8: 0 | J8: 0 | K8: 0 | L8: 0
A9: BT | B9: Bilgi Teknolojisi | C9: İdari | D9: 0 | E9: 0 | F9: 0 | G9: 0 | H9: 0 | I9: 0 | J9: 0 | K9: 0 | L9: 0
A10: DO | B10: Diller okulu | C10: Akademik | D10: 0 | E10: 0 | F10: 0 | G10: 0 | H10: 0 | I10: 0 | J10: 0 | K10: 0 | L10: 0
A11: ERG | B11: Eğitim Reformu Girişimi | C11: Akademik | D11: 0 | E11: 0 | F11: 0 | G11: 0 | H11: 0 | I11: 0 | J11: 0 | K11: 0 | L11: 0
A12: GS | B12: Genel Sekreterlik | C12: İdari | D12: 0 | E12: 0 | F12: 0 | G12: 0 | H12: 0 | I12: 0 | J12: 0 | K12: 0 | L12: 0
A13: HZ/HG | B13: Hizmetler Güvenlik | C13: İdari | D13: 0 | E13: 0 | F13: 0 | G13: 0 | H13: 0 | I13: 0 | J13: 0 | K13: 0 | L13: 0
... A43: YBF | B43: Yönetim Bilimleri Fakültesi | C43: Fakülteler | D43: 0 | E43: 0 | F43: 0 | G43: 0 | H43: 0 | I43: 0 | J43: 0 | K43: 0 | L43: 0
C44: Toplam | D44: =SUM(D1:D43) -> 0 | E44: =SUM(E1:E43) -> 0 | F44: =SUM(F1:F43) -> 0 | G44: =SUM(G1:G43) -> 0 | H44: 0 | I44: 0 | J44: 0 | K44: 0 | L44: 0
C45: Genel Toplam | D45: =D44+E44 -> 0 | F45: =SUM(F44,G44,H44) -> 0
C46: Son Envanter
C47: Fark

Sheet 2021 Ekim
A1: Birim Kodu | B1: Birim Adı | C1: Tür | D1: KA-Klasör | E1: KA-Dosya | F1: BA-Klasör | G1: BA-Dosya | H1: BA-Cilt | I1: Kutu / Koli Sayısı | J1: Karşılanan İstekler (Mail /Telefon) | K1: Yararlanma | L1: Birim Ziyaretleri Devir İşlemleri Gün Sayısı
A2: ALP/PGO | B2: ALP / Araştırma Projeleri Geliştirme Ofisi | C2: Akademik | D2: 0 | E2: 0 | F2: 0 | G2: 0 | H2: 0 | I2: 0 | J2: 0 | K2: 0 | L2: 0
A3: ALP/PYO | B3: ALP / Araştırma Projeleri Yönetim Ofisi | C3: Akademik | D3: 0 | E3: 0 | F3: 0 | G3: 0 | H3: 0 | I3: 0 | J3: 0 | K3: 0 | L3: 0
A4: ALP | B4: ALP / Direktörlük | C4: Akademik | D4: 0 | E4: 0 | F4: 0 | G4: 0 | H4: 0 | I4: 0 | J4: 0 | K4: 0 | L4: 0
A5: ALP/İLO | B5: ALP/Sanayi İşbirlikleri ve Teknoloji Lisanslama Ofisi | C5: Akademik | D5: 0 | E5: 0 | F5: 0 | G5: 0 | H5: 0 | I5: 0 | J5: 0 | K5: 0 | L5: 0
A6: APG | B6: Araştırma Süreci Planlama ve Politika Geliştirme Ofisi | C6: Akademik | D6: 0 | E6: 0 | F6: 0 | G6: 0 | H6: 0 | I6: 0 | J6: 0 | K6: 0 | L6: 0
A7: BAGEM | B7: Bireysel Ve Akademik Gelişim Merkezi | C7: Akademik | D7: 0 | E7: 0 | F7: 0 | G7: 0 | H7: 0 | I7: 0 | J7: 0 | K7: 0 | L7: 0
A8: BM | B8: Bilgi Merkezi | C8: İdari | D8: 0 | E8: 0 | F8: 0 | G8: 0 | H8: 0 | I8: 0 | J8: 0 | K8: 0 | L8: 0
A9: BT | B9: Bilgi Teknolojisi | C9: İdari | D9: 0 | E9: 0 | F9: 0 | G9: 0 | H9: 0 | I9: 0 | J9: 0 | K9: 0 | L9: 0
A10: DO | B10: Diller okulu | C10: Akademik | D10: 0 | E10: 0 | F10: 0 | G10: 0 | H10: 0 | I10: 0 | J10: 0 | K10: 0 | L10: 0
A11: ERG | B11: Eğitim Reformu Girişimi | C11: Akademik | D11: 0 | E11: 0 | F11: 0 | G11: 0 | H11: 0 | I11: 0 | J11: 0 | K11: 0 | L11: 0
A12: GS | B12: Genel Sekreterlik | C12: İdari | D12: 0 | E12: 0 | F12: 0 | G12: 0 | H12: 0 | I12: 0 | J12: 0 | K12: 0 | L12: 0
A13: HZ/HG | B13: Hizmetler Güvenlik | C13: İdari | D13: 0 | E13: 0 | F13: 0 | G13: 0 | H13: 0 | I13: 0 | J13: 0 | K13: 0 | L13: 0
... A43: YBF | B43: Yönetim Bilimleri Fakültesi | C43: Fakülteler | D43: 0 | E43: 0 | F43: 0 | G43: 0 | H43: 0 | I43: 0 | J43: 0 | K43: 0 | L43: 0
C44: Toplam | D44: =SUM(D1:D43) -> 0 | E44: =SUM(E1:E43) -> 0 | F44: =SUM(F1:F43) -> 0 | G44: =SUM(G1:G43) -> 0 | H44: 0 | I44: 0 | J44: 0 | K44: 0 | L44: 0
C45: Genel Toplam | D45: =D44+E44 -> 0 | F45: =SUM(F44,G44,H44) -> 0
C46: Son Envanter
C47: Fark

Sheet 2021 Kasım
A1: Birim Kodu | B1: Birim Adı | C1: Tür | D1: KA-Klasör | E1: KA-Dosya | F1: BA-Klasör | G1: BA-Dosya | H1: BA-Cilt | I1: Kutu / Koli Sayısı | J1: Karşılanan İstekler (Mail /Telefon) | K1: Yararlanma | L1: Birim Ziyaretleri Devir İşlemleri Gün Sayısı
A2: ALP/PGO | B2: ALP / Araştırma Projeleri Geliştirme Ofisi | C2: Akademik | D2: 0 | E2: 0 | F2: 0 | G2: 0 | H2: 0 | I2: 0 | J2: 0 | K2: 0 | L2: 0
A3: ALP/PYO | B3: ALP / Araştırma Projeleri Yönetim Ofisi | C3: Akademik | D3: 0 | E3: 0 | F3: 0 | G3: 0 | H3: 0 | I3: 0 | J3: 0 | K3: 0 | L3: 0
A4: ALP | B4: ALP / Direktörlük | C4: Akademik | D4: 0 | E4: 0 | F4: 0 | G4: 0 | H4: 0 | I4: 0 | J4: 0 | K4: 0 | L4: 0
A5: ALP/İLO | B5: ALP/Sanayi İşbirlikleri ve Teknoloji Lisanslama Ofisi | C5: Akademik | D5: 0 | E5: 0 | F5: 0 | G5: 0 | H5: 0 | I5: 0 | J5: 0 | K5: 0 | L5: 0
A6: APG | B6: Araştırma Süreci Planlama ve Politika Geliştirme Ofisi | C6: Akademik | D6: 0 | E6: 0 | F6: 0 | G6: 0 | H6: 0 | I6: 0 | J6: 0 | K6: 0 | L6: 0
A7: BAGEM | B7: Bireysel Ve Akademik Gelişim Merkezi | C7: Akademik | D7: 0 | E7: 0 | F7: 0 | G7: 0 | H7: 0 | I7: 0 | J7: 0 | K7: 0 | L7: 0
A8: BM | B8: Bilgi Merkezi | C8: İdari | D8: 0 | E8: 0 | F8: 0 | G8: 0 | H8: 0 | I8: 0 | J8: 0 | K8: 0 | L8: 0
A9: BT | B9: Bilgi Teknolojisi | C9: İdari | D9: 0 | E9: 0 | F9: 0 | G9: 0 | H9: 0 | I9: 0 | J9: 0 | K9: 0 | L9: 0
A10: DO | B10: Diller okulu | C10: Akademik | D10: 0 | E10: 0 | F10: 0 | G10: 0 | H10: 0 | I10: 0 | J10: 0 | K10: 0 | L10: 0
A11: ERG | B11: Eğitim Reformu Girişimi | C11: Akademik | D11: 0 | E11: 0 | F11: 0 | G11: 0 | H11: 0 | I11: 0 | J11: 0 | K11: 0 | L11: 0
A12: GS | B12: Genel Sekreterlik | C12: İdari | D12: 0 | E12: 0 | F12: 0 | G12: 0 | H12: 0 | I12: 0 | J12: 0 | K12: 0 | L12: 0
A13: HZ/HG | B13: Hizmetler Güvenlik | C13: İdari | D13: 0 | E13: 0 | F13: 0 | G13: 0 | H13: 0 | I13: 0 | J13: 0 | K13: 0 | L13: 0
... A43: YBF | B43: Yönetim Bilimleri Fakültesi | C43: Fakülteler | D43: 0 | E43: 0 | F43: 0 | G43: 0 | H43: 0 | I43: 0 | J43: 0 | K43: 0 | L43: 0
C44: Toplam | D44: =SUM(D1:D43) -> 0 | E44: =SUM(E1:E43) -> 0 | F44: =SUM(F1:F43) -> 0 | G44: =SUM(G1:G43) -> 0 | H44: 0 | I44: 0 | J44: 0 | K44: 0 | L44: 0
C45: Genel Toplam | D45: =D44+E44 -> 0 | F45: =SUM(F44,G44,H44) -> 0
C46: Son Envanter
C47: Fark

Sheet 2021 Aralık
A1: Birim Kodu | B1: Birim Adı | C1: Tür | D1: KA-Klasör | E1: KA-Dosya | F1: BA-Klasör | G1: BA-Dosya | H1: BA-Cilt | I1: Kutu / Koli Sayısı | J1: Karşılanan İstekler (Mail /Telefon) | K1: Yararlanma | L1: Birim Ziyaretleri Devir İşlemleri Gün Sayısı
A2: ALP/PGO | B2: ALP / Araştırma Projeleri Geliştirme Ofisi | C2: Akademik | D2: 0 | E2: 0 | F2: 0 | G2: 0 | H2: 0 | I2: 0 | J2: 0 | K2: 0 | L2: 0
A3: ALP/PYO | B3: ALP / Araştırma Projeleri Yönetim Ofisi | C3: Akademik | D3: 0 | E3: 0 | F3: 0 | G3: 0 | H3: 0 | I3: 0 | J3: 0 | K3: 0 | L3: 0
A4: ALP | B4: ALP / Direktörlük | C4: Akademik | D4: 0 | E4: 0 | F4: 0 | G4: 0 | H4: 0 | I4: 0 | J4: 0 | K4: 0 | L4: 0
A5: ALP/İLO | B5: ALP/Sanayi İşbirlikleri ve Teknoloji Lisanslama Ofisi | C5: Akademik | D5: 0 | E5: 0 | F5: 0 | G5: 0 | H5: 0 | I5: 0 | J5: 0 | K5: 0 | L5: 0
A6: APG | B6: Araştırma Süreci Planlama ve Politika Geliştirme Ofisi | C6: Akademik | D6: 0 | E6: 0 | F6: 0 | G6: 0 | H6: 0 | I6: 0 | J6: 0 | K6: 0 | L6: 0
A7: BAGEM | B7: Bireysel Ve Akademik Gelişim Merkezi | C7: Akademik | D7: 0 | E7: 0 | F7: 0 | G7: 0 | H7: 0 | I7: 0 | J7: 0 | K7: 0 | L7: 0
A8: BM | B8: Bilgi Merkezi | C8: İdari | D8: 0 | E8: 0 | F8: 0 | G8: 0 | H8: 0 | I8: 0 | J8: 0 | K8: 0 | L8: 0
A9: BT | B9: Bilgi Teknolojisi | C9: İdari | D9: 0 | E9: 0 | F9: 0 | G9: 0 | H9: 0 | I9: 0 | J9: 0 | K9: 0 | L9: 0
A10: DO | B10: Diller okulu | C10: Akademik | D10: 0 | E10: 0 | F10: 0 | G10: 0 | H10: 0 | I10: 0 | J10: 0 | K10: 0 | L10: 0
A11: ERG | B11: Eğitim Reformu Girişimi | C11: Akademik | D11: 0 | E11: 0 | F11: 0 | G11: 0 | H11: 0 | I11: 0 | J11: 0 | K11: 0 | L11: 0
A12: GS | B12: Genel Sekreterlik | C12: İdari | D12: 0 | E12: 0 | F12: 0 | G12: 0 | H12: 0 | I12: 0 | J12: 0 | K12: 0 | L12: 0
A13: HZ/HG | B13: Hizmetler Güvenlik | C13: İdari | D13: 0 | E13: 0 | F13: 0 | G13: 0 | H13: 0 | I13: 0 | J13: 0 | K13: 0 | L13: 0
... A43: YBF | B43: Yönetim Bilimleri Fakültesi | C43: Fakülteler | D43: 0 | E43: 0 | F43: 0 | G43: 0 | H43: 0 | I43: 0 | J43: 0 | K43: 0 | L43: 0
C44: Toplam | D44: =SUM(D1:D43) -> 0 | E44: =SUM(E1:E43) -> 0 | F44: =SUM(F1:F43) -> 0 | G44: =SUM(G1:G43) -> 0 | H44: 0 | I44: 0 | J44: 0 | K44: 0 | L44: 0
C45: Genel Toplam | D45: =D44+E44 -> 0 | F45: =SUM(F44,G44,H44) -> 0
C46: Son Envanter
C47: Fark

Sheet Toplam
A1: Birim Kodu | B1: Birim Adı | C1: Tür | D1: KA-Klasör | E1: KA-Dosya | F1: BA-Klasör | G1: BA-Dosya | H1: BA-Cilt | I1: Kutu / Koli Sayısı | J1: Karşılanan İstekler (Mail /Telefon) | K1: Yararlanma | L1: Birim Ziyaretleri Devir İşlemleri Gün Sayısı
A2: ALP/PGO | B2: ALP / Araştırma Projeleri Geliştirme Ofisi | C2: Akademik | D2: ='2020 Eylül'!D2+'2020 Ekim'!D2+'2020 Kasım'!D2+'2020 Aralık'!D2+'2021 Ocak'!D2+'2021 Şubat'!D2+'2021 Mart'!D2+'2021 Nisan'!D2+'2021 Mayıs'!D2+'2021 Haziran'!D2+'2021 Temmuz'!D2+'2021 Ağustos'!D2+'2021 Eylül'!D2+'2021 Ekim'!D2+'2021 Kasım'!D2+'2021 Aralık'!D2 -> 0 | E2: ='2020 Eylül'!E2+'2020 Ekim'!E2+'2020 Kasım'!E2+'2020 Aralık'!E2+'2021 Ocak'!E2+'2021 Şubat'!E2+'2021 Mart'!E2+'2021 Nisan'!E2+'2021 Mayıs'!E2+'2021 Haziran'!E2+'2021 Temmuz'!E2+'2021 Ağustos'!E2+'2021 Eylül'!E2+'2021 Ekim'!E2+'2021 Kasım'!E2+'2021 Aralık'!E2 -> 0 | F2: ='2020 Eylül'!F2+'2020 Ekim'!F2+'2020 Kasım'!F2+'2020 Aralık'!F2+'2021 Ocak'!F2+'2021 Şubat'!F2+'2021 Mart'!F2+'2021 Nisan'!F2+'2021 Mayıs'!F2+'2021 Haziran'!F2+'2021 Temmuz'!F2+'2021 Ağustos'!F2+'2021 Eylül'!F2+'2021 Ekim'!F2+'2021 Kasım'!F2+'2021 Aralık'!F2 -> 0 | G2: ='2020 Eylül'!G2+'2020 Ekim'!G2+'2020 Kasım'!G2+'2020 Aralık'!G2+'2021 Ocak'!G2+'2021 Şubat'!G2+'2021 Mart'!G2+'2021 Nisan'!G2+'2021 Mayıs'!G2+'2021 Haziran'!G2+'2021 Temmuz'!G2+'2021 Ağustos'!G2+'2021 Eylül'!G2+'2021 Ekim'!G2+'2021 Kasım'!G2+'2021 Aralık'!G2 -> 0 | H2: ='2020 Eylül'!H2+'2020 Ekim'!H2+'2020 Kasım'!H2+'2020 Aralık'!H2+'2021 Ocak'!H2+'2021 Şubat'!H2+'2021 Mart'!H2+'2021 Nisan'!H2+'2021 Mayıs'!H2+'2021 Haziran'!H2+'2021 Temmuz'!H2+'2021 Ağustos'!H2+'2021 Eylül'!H2+'2021 Ekim'!H2+'2021 Kasım'!H2+'2021 Aralık'!H2 -> 0 | I2: ='2020 Eylül'!I2+'2020 Ekim'!I2+'2020 Kasım'!I2+'2020 Aralık'!I2+'2021 Ocak'!I2+'2021 Şubat'!I2+'2021 Mart'!I2+'2021 Nisan'!I2+'2021 Mayıs'!I2+'2021 Haziran'!I2+'2021 Temmuz'!I2+'2021 Ağustos'!I2+'2021 Eylül'!I2+'2021 Ekim'!I2+'2021 Kasım'!I2+'2021 Aralık'!I2 -> 0 | J2: ='2020 Eylül'!J2+'2020 Ekim'!J2+'2020 Kasım'!J2+'2020 Aralık'!J2+'2021 Ocak'!J2+'2021 Şubat'!J2+'2021 Mart'!J2+'2021 Nisan'!J2+'2021 Mayıs'!J2+'2021 Haziran'!J2+'2021 Temmuz'!J2+'2021 Ağustos'!J2+'2021 Eylül'!J2+'2021 Ekim'!J2+'2021 Kasım'!J2+'2021 Aralık'!J2 -> 0 | K2: ='2020 Eylül'!K2+'2020 Ekim'!K2+'2020 Kasım'!K2+'2020 Aralık'!K2+'2021 Ocak'!K2+'2021 Şubat'!K2+'2021 Mart'!K2+'2021 Nisan'!K2+'2021 Mayıs'!K2+'2021 Haziran'!K2+'2021 Temmuz'!K2+'2021 Ağustos'!K2+'2021 Eylül'!K2+'2021 Ekim'!K2+'2021 Kasım'!K2+'2021 Aralık'!K2 -> 0 | L2: ='2020 Eylül'!L2+'2020 Ekim'!L2+'2020 Kasım'!L2+'2020 Aralık'!L2+'2021 Ocak'!L2+'2021 Şubat'!L2+'2021 Mart'!L2+'2021 Nisan'!L2+'2021 Mayıs'!L2+'2021 Haziran'!L2+'2021 Temmuz'!L2+'2021 Ağustos'!L2+'2021 Eylül'!L2+'2021 Ekim'!L2+'2021 Kasım'!L2+'2021 Aralık'!L2 -> 0
A3: ALP/PYO | B3: ALP / Araştırma Projeleri Yönetim Ofisi | C3: Akademik | D3: ='2020 Eylül'!D3+'2020 Ekim'!D3+'2020 Kasım'!D3+'2020 Aralık'!D3+'2021 Ocak'!D3+'2021 Şubat'!D3+'2021 Mart'!D3+'2021 Nisan'!D3+'2021 Mayıs'!D3+'2021 Haziran'!D3+'2021 Temmuz'!D3+'2021 Ağustos'!D3+'2021 Eylül'!D3+'2021 Ekim'!D3+'2021 Kasım'!D3+'2021 Aralık'!D3 -> 0 | E3: ='2020 Eylül'!E3+'2020 Ekim'!E3+'2020 Kasım'!E3+'2020 Aralık'!E3+'2021 Ocak'!E3+'2021 Şubat'!E3+'2021 Mart'!E3+'2021 Nisan'!E3+'2021 Mayıs'!E3+'2021 Haziran'!E3+'2021 Temmuz'!E3+'2021 Ağustos'!E3+'2021 Eylül'!E3+'2021 Ekim'!E3+'2021 Kasım'!E3+'2021 Aralık'!E3 -> 0 | F3: ='2020 Eylül'!F3+'2020 Ekim'!F3+'2020 Kasım'!F3+'2020 Aralık'!F3+'2021 Ocak'!F3+'2021 Şubat'!F3+'2021 Mart'!F3+'2021 Nisan'!F3+'2021 Mayıs'!F3+'2021 Haziran'!F3+'2021 Temmuz'!F3+'2021 Ağustos'!F3+'2021 Eylül'!F3+'2021 Ekim'!F3+'2021 Kasım'!F3+'2021 Aralık'!F3 -> 0 | G3: ='2020 Eylül'!G3+'2020 Ekim'!G3+'2020 Kasım'!G3+'2020 Aralık'!G3+'2021 Ocak'!G3+'2021 Şubat'!G3+'2021 Mart'!G3+'2021 Nisan'!G3+'2021 Mayıs'!G3+'2021 Haziran'!G3+'2021 Temmuz'!G3+'2021 Ağustos'!G3+'2021 Eylül'!G3+'2021 Ekim'!G3+'2021 Kasım'!G3+'2021 Aralık'!G3 -> 0 | H3: ='2020 Eylül'!H3+'2020 Ekim'!H3+'2020 Kasım'!H3+'2020 Aralık'!H3+'2021 Ocak'!H3+'2021 Şubat'!H3+'2021 Mart'!H3+'2021 Nisan'!H3+'2021 Mayıs'!H3+'2021 Haziran'!H3+'2021 Temmuz'!H3+'2021 Ağustos'!H3+'2021 Eylül'!H3+'2021 Ekim'!H3+'2021 Kasım'!H3+'2021 Aralık'!H3 -> 0 | I3: ='2020 Eylül'!I3+'2020 Ekim'!I3+'2020 Kasım'!I3+'2020 Aralık'!I3+'2021 Ocak'!I3+'2021 Şubat'!I3+'2021 Mart'!I3+'2021 Nisan'!I3+'2021 Mayıs'!I3+'2021 Haziran'!I3+'2021 Temmuz'!I3+'2021 Ağustos'!I3+'2021 Eylül'!I3+'2021 Ekim'!I3+'2021 Kasım'!I3+'2021 Aralık'!I3 -> 0 | J3: ='2020 Eylül'!J3+'2020 Ekim'!J3+'2020 Kasım'!J3+'2020 Aralık'!J3+'2021 Ocak'!J3+'2021 Şubat'!J3+'2021 Mart'!J3+'2021 Nisan'!J3+'2021 Mayıs'!J3+'2021 Haziran'!J3+'2021 Temmuz'!J3+'2021 Ağustos'!J3+'2021 Eylül'!J3+'2021 Ekim'!J3+'2021 Kasım'!J3+'2021 Aralık'!J3 -> 0 | K3: ='2020 Eylül'!K3+'2020 Ekim'!K3+'2020 Kasım'!K3+'2020 Aralık'!K3+'2021 Ocak'!K3+'2021 Şubat'!K3+'2021 Mart'!K3+'2021 Nisan'!K3+'2021 Mayıs'!K3+'2021 Haziran'!K3+'2021 Temmuz'!K3+'2021 Ağustos'!K3+'2021 Eylül'!K3+'2021 Ekim'!K3+'2021 Kasım'!K3+'2021 Aralık'!K3 -> 0 | L3: ='2020 Eylül'!L3+'2020 Ekim'!L3+'2020 Kasım'!L3+'2020 Aralık'!L3+'2021 Ocak'!L3+'2021 Şubat'!L3+'2021 Mart'!L3+'2021 Nisan'!L3+'2021 Mayıs'!L3+'2021 Haziran'!L3+'2021 Temmuz'!L3+'2021 Ağustos'!L3+'2021 Eylül'!L3+'2021 Ekim'!L3+'2021 Kasım'!L3+'2021 Aralık'!L3 -> 0
A4: ALP | B4: ALP / Direktörlük | C4: Akademik | D4: ='2020 Eylül'!D4+'2020 Ekim'!D4+'2020 Kasım'!D4+'2020 Aralık'!D4+'2021 Ocak'!D4+'2021 Şubat'!D4+'2021 Mart'!D4+'2021 Nisan'!D4+'2021 Mayıs'!D4+'2021 Haziran'!D4+'2021 Temmuz'!D4+'2021 Ağustos'!D4+'2021 Eylül'!D4+'2021 Ekim'!D4+'2021 Kasım'!D4+'2021 Aralık'!D4 -> 0 | E4: ='2020 Eylül'!E4+'2020 Ekim'!E4+'2020 Kasım'!E4+'2020 Aralık'!E4+'2021 Ocak'!E4+'2021 Şubat'!E4+'2021 Mart'!E4+'2021 Nisan'!E4+'2021 Mayıs'!E4+'2021 Haziran'!E4+'2021 Temmuz'!E4+'2021 Ağustos'!E4+'2021 Eylül'!E4+'2021 Ekim'!E4+'2021 Kasım'!E4+'2021 Aralık'!E4 -> 0 | F4: ='2020 Eylül'!F4+'2020 Ekim'!F4+'2020 Kasım'!F4+'2020 Aralık'!F4+'2021 Ocak'!F4+'2021 Şubat'!F4+'2021 Mart'!F4+'2021 Nisan'!F4+'2021 Mayıs'!F4+'2021 Haziran'!F4+'2021 Temmuz'!F4+'2021 Ağustos'!F4+'2021 Eylül'!F4+'2021 Ekim'!F4+'2021 Kasım'!F4+'2021 Aralık'!F4 -> 0 | G4: ='2020 Eylül'!G4+'2020 Ekim'!G4+'2020 Kasım'!G4+'2020 Aralık'!G4+'2021 Ocak'!G4+'2021 Şubat'!G4+'2021 Mart'!G4+'2021 Nisan'!G4+'2021 Mayıs'!G4+'2021 Haziran'!G4+'2021 Temmuz'!G4+'2021 Ağustos'!G4+'2021 Eylül'!G4+'2021 Ekim'!G4+'2021 Kasım'!G4+'2021 Aralık'!G4 -> 0 | H4: ='2020 Eylül'!H4+'2020 Ekim'!H4+'2020 Kasım'!H4+'2020 Aralık'!H4+'2021 Ocak'!H4+'2021 Şubat'!H4+'2021 Mart'!H4+'2021 Nisan'!H4+'2021 Mayıs'!H4+'2021 Haziran'!H4+'2021 Temmuz'!H4+'2021 Ağustos'!H4+'2021 Eylül'!H4+'2021 Ekim'!H4+'2021 Kasım'!H4+'2021 Aralık'!H4 -> 0 | I4: ='2020 Eylül'!I4+'2020 Ekim'!I4+'2020 Kasım'!I4+'2020 Aralık'!I4+'2021 Ocak'!I4+'2021 Şubat'!I4+'2021 Mart'!I4+'2021 Nisan'!I4+'2021 Mayıs'!I4+'2021 Haziran'!I4+'2021 Temmuz'!I4+'2021 Ağustos'!I4+'2021 Eylül'!I4+'2021 Ekim'!I4+'2021 Kasım'!I4+'2021 Aralık'!I4 -> 0 | J4: ='2020 Eylül'!J4+'2020 Ekim'!J4+'2020 Kasım'!J4+'2020 Aralık'!J4+'2021 Ocak'!J4+'2021 Şubat'!J4+'2021 Mart'!J4+'2021 Nisan'!J4+'2021 Mayıs'!J4+'2021 Haziran'!J4+'2021 Temmuz'!J4+'2021 Ağustos'!J4+'2021 Eylül'!J4+'2021 Ekim'!J4+'2021 Kasım'!J4+'2021 Aralık'!J4 -> 0 | K4: ='2020 Eylül'!K4+'2020 Ekim'!K4+'2020 Kasım'!K4+'2020 Aralık'!K4+'2021 Ocak'!K4+'2021 Şubat'!K4+'2021 Mart'!K4+'2021 Nisan'!K4+'2021 Mayıs'!K4+'2021 Haziran'!K4+'2021 Temmuz'!K4+'2021 Ağustos'!K4+'2021 Eylül'!K4+'2021 Ekim'!K4+'2021 Kasım'!K4+'2021 Aralık'!K4 -> 0 | L4: ='2020 Eylül'!L4+'2020 Ekim'!L4+'2020 Kasım'!L4+'2020 Aralık'!L4+'2021 Ocak'!L4+'2021 Şubat'!L4+'2021 Mart'!L4+'2021 Nisan'!L4+'2021 Mayıs'!L4+'2021 Haziran'!L4+'2021 Temmuz'!L4+'2021 Ağustos'!L4+'2021 Eylül'!L4+'2021 Ekim'!L4+'2021 Kasım'!L4+'2021 Aralık'!L4 -> 0
A5: ALP/İLO | B5: ALP/Sanayi İşbirlikleri ve Teknoloji Lisanslama Ofisi | C5: Akademik | D5: ='2020 Eylül'!D5+'2020 Ekim'!D5+'2020 Kasım'!D5+'2020 Aralık'!D5+'2021 Ocak'!D5+'2021 Şubat'!D5+'2021 Mart'!D5+'2021 Nisan'!D5+'2021 Mayıs'!D5+'2021 Haziran'!D5+'2021 Temmuz'!D5+'2021 Ağustos'!D5+'2021 Eylül'!D5+'2021 Ekim'!D5+'2021 Kasım'!D5+'2021 Aralık'!D5 -> 0 | E5: ='2020 Eylül'!E5+'2020 Ekim'!E5+'2020 Kasım'!E5+'2020 Aralık'!E5+'2021 Ocak'!E5+'2021 Şubat'!E5+'2021 Mart'!E5+'2021 Nisan'!E5+'2021 Mayıs'!E5+'2021 Haziran'!E5+'2021 Temmuz'!E5+'2021 Ağustos'!E5+'2021 Eylül'!E5+'2021 Ekim'!E5+'2021 Kasım'!E5+'2021 Aralık'!E5 -> 0 | F5: ='2020 Eylül'!F5+'2020 Ekim'!F5+'2020 Kasım'!F5+'2020 Aralık'!F5+'2021 Ocak'!F5+'2021 Şubat'!F5+'2021 Mart'!F5+'2021 Nisan'!F5+'2021 Mayıs'!F5+'2021 Haziran'!F5+'2021 Temmuz'!F5+'2021 Ağustos'!F5+'2021 Eylül'!F5+'2021 Ekim'!F5+'2021 Kasım'!F5+'2021 Aralık'!F5 -> 0 | G5: ='2020 Eylül'!G5+'2020 Ekim'!G5+'2020 Kasım'!G5+'2020 Aralık'!G5+'2021 Ocak'!G5+'2021 Şubat'!G5+'2021 Mart'!G5+'2021 Nisan'!G5+'2021 Mayıs'!G5+'2021 Haziran'!G5+'2021 Temmuz'!G5+'2021 Ağustos'!G5+'2021 Eylül'!G5+'2021 Ekim'!G5+'2021 Kasım'!G5+'2021 Aralık'!G5 -> 0 | H5: ='2020 Eylül'!H5+'2020 Ekim'!H5+'2020 Kasım'!H5+'2020 Aralık'!H5+'2021 Ocak'!H5+'2021 Şubat'!H5+'2021 Mart'!H5+'2021 Nisan'!H5+'2021 Mayıs'!H5+'2021 Haziran'!H5+'2021 Temmuz'!H5+'2021 Ağustos'!H5+'2021 Eylül'!H5+'2021 Ekim'!H5+'2021 Kasım'!H5+'2021 Aralık'!H5 -> 0 | I5: ='2020 Eylül'!I5+'2020 Ekim'!I5+'2020 Kasım'!I5+'2020 Aralık'!I5+'2021 Ocak'!I5+'2021 Şubat'!I5+'2021 Mart'!I5+'2021 Nisan'!I5+'2021 Mayıs'!I5+'2021 Haziran'!I5+'2021 Temmuz'!I5+'2021 Ağustos'!I5+'2021 Eylül'!I5+'2021 Ekim'!I5+'2021 Kasım'!I5+'2021 Aralık'!I5 -> 0 | J5: ='2020 Eylül'!J5+'2020 Ekim'!J5+'2020 Kasım'!J5+'2020 Aralık'!J5+'2021 Ocak'!J5+'2021 Şubat'!J5+'2021 Mart'!J5+'2021 Nisan'!J5+'2021 Mayıs'!J5+'2021 Haziran'!J5+'2021 Temmuz'!J5+'2021 Ağustos'!J5+'2021 Eylül'!J5+'2021 Ekim'!J5+'2021 Kasım'!J5+'2021 Aralık'!J5 -> 0 | K5: ='2020 Eylül'!K5+'2020 Ekim'!K5+'2020 Kasım'!K5+'2020 Aralık'!K5+'2021 Ocak'!K5+'2021 Şubat'!K5+'2021 Mart'!K5+'2021 Nisan'!K5+'2021 Mayıs'!K5+'2021 Haziran'!K5+'2021 Temmuz'!K5+'2021 Ağustos'!K5+'2021 Eylül'!K5+'2021 Ekim'!K5+'2021 Kasım'!K5+'2021 Aralık'!K5 -> 0 | L5: ='2020 Eylül'!L5+'2020 Ekim'!L5+'2020 Kasım'!L5+'2020 Aralık'!L5+'2021 Ocak'!L5+'2021 Şubat'!L5+'2021 Mart'!L5+'2021 Nisan'!L5+'2021 Mayıs'!L5+'2021 Haziran'!L5+'2021 Temmuz'!L5+'2021 Ağustos'!L5+'2021 Eylül'!L5+'2021 Ekim'!L5+'2021 Kasım'!L5+'2021 Aralık'!L5 -> 0
A6: APG | B6: Araştırma Süreci Planlama ve Politika Geliştirme Ofisi | C6: Akademik | D6: ='2020 Eylül'!D6+'2020 Ekim'!D6+'2020 Kasım'!D6+'2020 Aralık'!D6+'2021 Ocak'!D6+'2021 Şubat'!D6+'2021 Mart'!D6+'2021 Nisan'!D6+'2021 Mayıs'!D6+'2021 Haziran'!D6+'2021 Temmuz'!D6+'2021 Ağustos'!D6+'2021 Eylül'!D6+'2021 Ekim'!D6+'2021 Kasım'!D6+'2021 Aralık'!D6 -> 0 | E6: ='2020 Eylül'!E6+'2020 Ekim'!E6+'2020 Kasım'!E6+'2020 Aralık'!E6+'2021 Ocak'!E6+'2021 Şubat'!E6+'2021 Mart'!E6+'2021 Nisan'!E6+'2021 Mayıs'!E6+'2021 Haziran'!E6+'2021 Temmuz'!E6+'2021 Ağustos'!E6+'2021 Eylül'!E6+'2021 Ekim'!E6+'2021 Kasım'!E6+'2021 Aralık'!E6 -> 0 | F6: ='2020 Eylül'!F6+'2020 Ekim'!F6+'2020 Kasım'!F6+'2020 Aralık'!F6+'2021 Ocak'!F6+'2021 Şubat'!F6+'2021 Mart'!F6+'2021 Nisan'!F6+'2021 Mayıs'!F6+'2021 Haziran'!F6+'2021 Temmuz'!F6+'2021 Ağustos'!F6+'2021 Eylül'!F6+'2021 Ekim'!F6+'2021 Kasım'!F6+'2021 Aralık'!F6 -> 0 | G6: ='2020 Eylül'!G6+'2020 Ekim'!G6+'2020 Kasım'!G6+'2020 Aralık'!G6+'2021 Ocak'!G6+'2021 Şubat'!G6+'2021 Mart'!G6+'2021 Nisan'!G6+'2021 Mayıs'!G6+'2021 Haziran'!G6+'2021 Temmuz'!G6+'2021 Ağustos'!G6+'2021 Eylül'!G6+'2021 Ekim'!G6+'2021 Kasım'!G6+'2021 Aralık'!G6 -> 0 | H6: ='2020 Eylül'!H6+'2020 Ekim'!H6+'2020 Kasım'!H6+'2020 Aralık'!H6+'2021 Ocak'!H6+'2021 Şubat'!H6+'2021 Mart'!H6+'2021 Nisan'!H6+'2021 Mayıs'!H6+'2021 Haziran'!H6+'2021 Temmuz'!H6+'2021 Ağustos'!H6+'2021 Eylül'!H6+'2021 Ekim'!H6+'2021 Kasım'!H6+'2021 Aralık'!H6 -> 0 | I6: ='2020 Eylül'!I6+'2020 Ekim'!I6+'2020 Kasım'!I6+'2020 Aralık'!I6+'2021 Ocak'!I6+'2021 Şubat'!I6+'2021 Mart'!I6+'2021 Nisan'!I6+'2021 Mayıs'!I6+'2021 Haziran'!I6+'2021 Temmuz'!I6+'2021 Ağustos'!I6+'2021 Eylül'!I6+'2021 Ekim'!I6+'2021 Kasım'!I6+'2021 Aralık'!I6 -> 0 | J6: ='2020 Eylül'!J6+'2020 Ekim'!J6+'2020 Kasım'!J6+'2020 Aralık'!J6+'2021 Ocak'!J6+'2021 Şubat'!J6+'2021 Mart'!J6+'2021 Nisan'!J6+'2021 Mayıs'!J6+'2021 Haziran'!J6+'2021 Temmuz'!J6+'2021 Ağustos'!J6+'2021 Eylül'!J6+'2021 Ekim'!J6+'2021 Kasım'!J6+'2021 Aralık'!J6 -> 0 | K6: ='2020 Eylül'!K6+'2020 Ekim'!K6+'2020 Kasım'!K6+'2020 Aralık'!K6+'2021 Ocak'!K6+'2021 Şubat'!K6+'2021 Mart'!K6+'2021 Nisan'!K6+'2021 Mayıs'!K6+'2021 Haziran'!K6+'2021 Temmuz'!K6+'2021 Ağustos'!K6+'2021 Eylül'!K6+'2021 Ekim'!K6+'2021 Kasım'!K6+'2021 Aralık'!K6 -> 0 | L6: ='2020 Eylül'!L6+'2020 Ekim'!L6+'2020 Kasım'!L6+'2020 Aralık'!L6+'2021 Ocak'!L6+'2021 Şubat'!L6+'2021 Mart'!L6+'2021 Nisan'!L6+'2021 Mayıs'!L6+'2021 Haziran'!L6+'2021 Temmuz'!L6+'2021 Ağustos'!L6+'2021 Eylül'!L6+'2021 Ekim'!L6+'2021 Kasım'!L6+'2021 Aralık'!L6 -> 0
A7: BAGEM | B7: Bireysel Ve Akademik Gelişim Merkezi | C7: Akademik | D7: ='2020 Eylül'!D7+'2020 Ekim'!D7+'2020 Kasım'!D7+'2020 Aralık'!D7+'2021 Ocak'!D7+'2021 Şubat'!D7+'2021 Mart'!D7+'2021 Nisan'!D7+'2021 Mayıs'!D7+'2021 Haziran'!D7+'2021 Temmuz'!D7+'2021 Ağustos'!D7+'2021 Eylül'!D7+'2021 Ekim'!D7+'2021 Kasım'!D7+'2021 Aralık'!D7 -> 0 | E7: ='2020 Eylül'!E7+'2020 Ekim'!E7+'2020 Kasım'!E7+'2020 Aralık'!E7+'2021 Ocak'!E7+'2021 Şubat'!E7+'2021 Mart'!E7+'2021 Nisan'!E7+'2021 Mayıs'!E7+'2021 Haziran'!E7+'2021 Temmuz'!E7+'2021 Ağustos'!E7+'2021 Eylül'!E7+'2021 Ekim'!E7+'2021 Kasım'!E7+'2021 Aralık'!E7 -> 0 | F7: ='2020 Eylül'!F7+'2020 Ekim'!F7+'2020 Kasım'!F7+'2020 Aralık'!F7+'2021 Ocak'!F7+'2021 Şubat'!F7+'2021 Mart'!F7+'2021 Nisan'!F7+'2021 Mayıs'!F7+'2021 Haziran'!F7+'2021 Temmuz'!F7+'2021 Ağustos'!F7+'2021 Eylül'!F7+'2021 Ekim'!F7+'2021 Kasım'!F7+'2021 Aralık'!F7 -> 0 | G7: ='2020 Eylül'!G7+'2020 Ekim'!G7+'2020 Kasım'!G7+'2020 Aralık'!G7+'2021 Ocak'!G7+'2021 Şubat'!G7+'2021 Mart'!G7+'2021 Nisan'!G7+'2021 Mayıs'!G7+'2021 Haziran'!G7+'2021 Temmuz'!G7+'2021 Ağustos'!G7+'2021 Eylül'!G7+'2021 Ekim'!G7+'2021 Kasım'!G7+'2021 Aralık'!G7 -> 0 | H7: ='2020 Eylül'!H7+'2020 Ekim'!H7+'2020 Kasım'!H7+'2020 Aralık'!H7+'2021 Ocak'!H7+'2021 Şubat'!H7+'2021 Mart'!H7+'2021 Nisan'!H7+'2021 Mayıs'!H7+'2021 Haziran'!H7+'2021 Temmuz'!H7+'2021 Ağustos'!H7+'2021 Eylül'!H7+'2021 Ekim'!H7+'2021 Kasım'!H7+'2021 Aralık'!H7 -> 0 | I7: ='2020 Eylül'!I7+'2020 Ekim'!I7+'2020 Kasım'!I7+'2020 Aralık'!I7+'2021 Ocak'!I7+'2021 Şubat'!I7+'2021 Mart'!I7+'2021 Nisan'!I7+'2021 Mayıs'!I7+'2021 Haziran'!I7+'2021 Temmuz'!I7+'2021 Ağustos'!I7+'2021 Eylül'!I7+'2021 Ekim'!I7+'2021 Kasım'!I7+'2021 Aralık'!I7 -> 0 | J7: ='2020 Eylül'!J7+'2020 Ekim'!J7+'2020 Kasım'!J7+'2020 Aralık'!J7+'2021 Ocak'!J7+'2021 Şubat'!J7+'2021 Mart'!J7+'2021 Nisan'!J7+'2021 Mayıs'!J7+'2021 Haziran'!J7+'2021 Temmuz'!J7+'2021 Ağustos'!J7+'2021 Eylül'!J7+'2021 Ekim'!J7+'2021 Kasım'!J7+'2021 Aralık'!J7 -> 0 | K7: ='2020 Eylül'!K7+'2020 Ekim'!K7+'2020 Kasım'!K7+'2020 Aralık'!K7+'2021 Ocak'!K7+'2021 Şubat'!K7+'2021 Mart'!K7+'2021 Nisan'!K7+'2021 Mayıs'!K7+'2021 Haziran'!K7+'2021 Temmuz'!K7+'2021 Ağustos'!K7+'2021 Eylül'!K7+'2021 Ekim'!K7+'2021 Kasım'!K7+'2021 Aralık'!K7 -> 0 | L7: ='2020 Eylül'!L7+'2020 Ekim'!L7+'2020 Kasım'!L7+'2020 Aralık'!L7+'2021 Ocak'!L7+'2021 Şubat'!L7+'2021 Mart'!L7+'2021 Nisan'!L7+'2021 Mayıs'!L7+'2021 Haziran'!L7+'2021 Temmuz'!L7+'2021 Ağustos'!L7+'2021 Eylül'!L7+'2021 Ekim'!L7+'2021 Kasım'!L7+'2021 Aralık'!L7 -> 0
A8: BM | B8: Bilgi Merkezi | C8: İdari | D8: ='2020 Eylül'!D8+'2020 Ekim'!D8+'2020 Kasım'!D8+'2020 Aralık'!D8+'2021 Ocak'!D8+'2021 Şubat'!D8+'2021 Mart'!D8+'2021 Nisan'!D8+'2021 Mayıs'!D8+'2021 Haziran'!D8+'2021 Temmuz'!D8+'2021 Ağustos'!D8+'2021 Eylül'!D8+'2021 Ekim'!D8+'2021 Kasım'!D8+'2021 Aralık'!D8 -> 0 | E8: ='2020 Eylül'!E8+'2020 Ekim'!E8+'2020 Kasım'!E8+'2020 Aralık'!E8+'2021 Ocak'!E8+'2021 Şubat'!E8+'2021 Mart'!E8+'2021 Nisan'!E8+'2021 Mayıs'!E8+'2021 Haziran'!E8+'2021 Temmuz'!E8+'2021 Ağustos'!E8+'2021 Eylül'!E8+'2021 Ekim'!E8+'2021 Kasım'!E8+'2021 Aralık'!E8 -> 0 | F8: ='2020 Eylül'!F8+'2020 Ekim'!F8+'2020 Kasım'!F8+'2020 Aralık'!F8+'2021 Ocak'!F8+'2021 Şubat'!F8+'2021 Mart'!F8+'2021 Nisan'!F8+'2021 Mayıs'!F8+'2021 Haziran'!F8+'2021 Temmuz'!F8+'2021 Ağustos'!F8+'2021 Eylül'!F8+'2021 Ekim'!F8+'2021 Kasım'!F8+'2021 Aralık'!F8 -> 0 | G8: ='2020 Eylül'!G8+'2020 Ekim'!G8+'2020 Kasım'!G8+'2020 Aralık'!G8+'2021 Ocak'!G8+'2021 Şubat'!G8+'2021 Mart'!G8+'2021 Nisan'!G8+'2021 Mayıs'!G8+'2021 Haziran'!G8+'2021 Temmuz'!G8+'2021 Ağustos'!G8+'2021 Eylül'!G8+'2021 Ekim'!G8+'2021 Kasım'!G8+'2021 Aralık'!G8 -> 0 | H8: ='2020 Eylül'!H8+'2020 Ekim'!H8+'2020 Kasım'!H8+'2020 Aralık'!H8+'2021 Ocak'!H8+'2021 Şubat'!H8+'2021 Mart'!H8+'2021 Nisan'!H8+'2021 Mayıs'!H8+'2021 Haziran'!H8+'2021 Temmuz'!H8+'2021 Ağustos'!H8+'2021 Eylül'!H8+'2021 Ekim'!H8+'2021 Kasım'!H8+'2021 Aralık'!H8 -> 0 | I8: ='2020 Eylül'!I8+'2020 Ekim'!I8+'2020 Kasım'!I8+'2020 Aralık'!I8+'2021 Ocak'!I8+'2021 Şubat'!I8+'2021 Mart'!I8+'2021 Nisan'!I8+'2021 Mayıs'!I8+'2021 Haziran'!I8+'2021 Temmuz'!I8+'2021 Ağustos'!I8+'2021 Eylül'!I8+'2021 Ekim'!I8+'2021 Kasım'!I8+'2021 Aralık'!I8 -> 0 | J8: ='2020 Eylül'!J8+'2020 Ekim'!J8+'2020 Kasım'!J8+'2020 Aralık'!J8+'2021 Ocak'!J8+'2021 Şubat'!J8+'2021 Mart'!J8+'2021 Nisan'!J8+'2021 Mayıs'!J8+'2021 Haziran'!J8+'2021 Temmuz'!J8+'2021 Ağustos'!J8+'2021 Eylül'!J8+'2021 Ekim'!J8+'2021 Kasım'!J8+'2021 Aralık'!J8 -> 0 | K8: ='2020 Eylül'!K8+'2020 Ekim'!K8+'2020 Kasım'!K8+'2020 Aralık'!K8+'2021 Ocak'!K8+'2021 Şubat'!K8+'2021 Mart'!K8+'2021 Nisan'!K8+'2021 Mayıs'!K8+'2021 Haziran'!K8+'2021 Temmuz'!K8+'2021 Ağustos'!K8+'2021 Eylül'!K8+'2021 Ekim'!K8+'2021 Kasım'!K8+'2021 Aralık'!K8 -> 0 | L8: ='2020 Eylül'!L8+'2020 Ekim'!L8+'2020 Kasım'!L8+'2020 Aralık'!L8+'2021 Ocak'!L8+'2021 Şubat'!L8+'2021 Mart'!L8+'2021 Nisan'!L8+'2021 Mayıs'!L8+'2021 Haziran'!L8+'2021 Temmuz'!L8+'2021 Ağustos'!L8+'2021 Eylül'!L8+'2021 Ekim'!L8+'2021 Kasım'!L8+'2021 Aralık'!L8 -> 0
A9: BT | B9: Bilgi Teknolojisi | C9: İdari | D9: ='2020 Eylül'!D9+'2020 Ekim'!D9+'2020 Kasım'!D9+'2020 Aralık'!D9+'2021 Ocak'!D9+'2021 Şubat'!D9+'2021 Mart'!D9+'2021 Nisan'!D9+'2021 Mayıs'!D9+'2021 Haziran'!D9+'2021 Temmuz'!D9+'2021 Ağustos'!D9+'2021 Eylül'!D9+'2021 Ekim'!D9+'2021 Kasım'!D9+'2021 Aralık'!D9 -> 0 | E9: ='2020 Eylül'!E9+'2020 Ekim'!E9+'2020 Kasım'!E9+'2020 Aralık'!E9+'2021 Ocak'!E9+'2021 Şubat'!E9+'2021 Mart'!E9+'2021 Nisan'!E9+'2021 Mayıs'!E9+'2021 Haziran'!E9+'2021 Temmuz'!E9+'2021 Ağustos'!E9+'2021 Eylül'!E9+'2021 Ekim'!E9+'2021 Kasım'!E9+'2021 Aralık'!E9 -> 0 | F9: ='2020 Eylül'!F9+'2020 Ekim'!F9+'2020 Kasım'!F9+'2020 Aralık'!F9+'2021 Ocak'!F9+'2021 Şubat'!F9+'2021 Mart'!F9+'2021 Nisan'!F9+'2021 Mayıs'!F9+'2021 Haziran'!F9+'2021 Temmuz'!F9+'2021 Ağustos'!F9+'2021 Eylül'!F9+'2021 Ekim'!F9+'2021 Kasım'!F9+'2021 Aralık'!F9 -> 0 | G9: ='2020 Eylül'!G9+'2020 Ekim'!G9+'2020 Kasım'!G9+'2020 Aralık'!G9+'2021 Ocak'!G9+'2021 Şubat'!G9+'2021 Mart'!G9+'2021 Nisan'!G9+'2021 Mayıs'!G9+'2021 Haziran'!G9+'2021 Temmuz'!G9+'2021 Ağustos'!G9+'2021 Eylül'!G9+'2021 Ekim'!G9+'2021 Kasım'!G9+'2021 Aralık'!G9 -> 0 | H9: ='2020 Eylül'!H9+'2020 Ekim'!H9+'2020 Kasım'!H9+'2020 Aralık'!H9+'2021 Ocak'!H9+'2021 Şubat'!H9+'2021 Mart'!H9+'2021 Nisan'!H9+'2021 Mayıs'!H9+'2021 Haziran'!H9+'2021 Temmuz'!H9+'2021 Ağustos'!H9+'2021 Eylül'!H9+'2021 Ekim'!H9+'2021 Kasım'!H9+'2021 Aralık'!H9 -> 0 | I9: ='2020 Eylül'!I9+'2020 Ekim'!I9+'2020 Kasım'!I9+'2020 Aralık'!I9+'2021 Ocak'!I9+'2021 Şubat'!I9+'2021 Mart'!I9+'2021 Nisan'!I9+'2021 Mayıs'!I9+'2021 Haziran'!I9+'2021 Temmuz'!I9+'2021 Ağustos'!I9+'2021 Eylül'!I9+'2021 Ekim'!I9+'2021 Kasım'!I9+'2021 Aralık'!I9 -> 0 | J9: ='2020 Eylül'!J9+'2020 Ekim'!J9+'2020 Kasım'!J9+'2020 Aralık'!J9+'2021 Ocak'!J9+'2021 Şubat'!J9+'2021 Mart'!J9+'2021 Nisan'!J9+'2021 Mayıs'!J9+'2021 Haziran'!J9+'2021 Temmuz'!J9+'2021 Ağustos'!J9+'2021 Eylül'!J9+'2021 Ekim'!J9+'2021 Kasım'!J9+'2021 Aralık'!J9 -> 0 | K9: ='2020 Eylül'!K9+'2020 Ekim'!K9+'2020 Kasım'!K9+'2020 Aralık'!K9+'2021 Ocak'!K9+'2021 Şubat'!K9+'2021 Mart'!K9+'2021 Nisan'!K9+'2021 Mayıs'!K9+'2021 Haziran'!K9+'2021 Temmuz'!K9+'2021 Ağustos'!K9+'2021 Eylül'!K9+'2021 Ekim'!K9+'2021 Kasım'!K9+'2021 Aralık'!K9 -> 0 | L9: ='2020 Eylül'!L9+'2020 Ekim'!L9+'2020 Kasım'!L9+'2020 Aralık'!L9+'2021 Ocak'!L9+'2021 Şubat'!L9+'2021 Mart'!L9+'2021 Nisan'!L9+'2021 Mayıs'!L9+'2021 Haziran'!L9+'2021 Temmuz'!L9+'2021 Ağustos'!L9+'2021 Eylül'!L9+'2021 Ekim'!L9+'2021 Kasım'!L9+'2021 Aralık'!L9 -> 0
A10: DO | B10: Diller okulu | C10: Akademik | D10: ='2020 Eylül'!D10+'2020 Ekim'!D10+'2020 Kasım'!D10+'2020 Aralık'!D10+'2021 Ocak'!D10+'2021 Şubat'!D10+'2021 Mart'!D10+'2021 Nisan'!D10+'2021 Mayıs'!D10+'2021 Haziran'!D10+'2021 Temmuz'!D10+'2021 Ağustos'!D10+'2021 Eylül'!D10+'2021 Ekim'!D10+'2021 Kasım'!D10+'2021 Aralık'!D10 -> 0 | E10: ='2020 Eylül'!E10+'2020 Ekim'!E10+'2020 Kasım'!E10+'2020 Aralık'!E10+'2021 Ocak'!E10+'2021 Şubat'!E10+'2021 Mart'!E10+'2021 Nisan'!E10+'2021 Mayıs'!E10+'2021 Haziran'!E10+'2021 Temmuz'!E10+'2021 Ağustos'!E10+'2021 Eylül'!E10+'2021 Ekim'!E10+'2021 Kasım'!E10+'2021 Aralık'!E10 -> 0 | F10: ='2020 Eylül'!F10+'2020 Ekim'!F10+'2020 Kasım'!F10+'2020 Aralık'!F10+'2021 Ocak'!F10+'2021 Şubat'!F10+'2021 Mart'!F10+'2021 Nisan'!F10+'2021 Mayıs'!F10+'2021 Haziran'!F10+'2021 Temmuz'!F10+'2021 Ağustos'!F10+'2021 Eylül'!F10+'2021 Ekim'!F10+'2021 Kasım'!F10+'2021 Aralık'!F10 -> 0 | G10: ='2020 Eylül'!G10+'2020 Ekim'!G10+'2020 Kasım'!G10+'2020 Aralık'!G10+'2021 Ocak'!G10+'2021 Şubat'!G10+'2021 Mart'!G10+'2021 Nisan'!G10+'2021 Mayıs'!G10+'2021 Haziran'!G10+'2021 Temmuz'!G10+'2021 Ağustos'!G10+'2021 Eylül'!G10+'2021 Ekim'!G10+'2021 Kasım'!G10+'2021 Aralık'!G10 -> 0 | H10: ='2020 Eylül'!H10+'2020 Ekim'!H10+'2020 Kasım'!H10+'2020 Aralık'!H10+'2021 Ocak'!H10+'2021 Şubat'!H10+'2021 Mart'!H10+'2021 Nisan'!H10+'2021 Mayıs'!H10+'2021 Haziran'!H10+'2021 Temmuz'!H10+'2021 Ağustos'!H10+'2021 Eylül'!H10+'2021 Ekim'!H10+'2021 Kasım'!H10+'2021 Aralık'!H10 -> 0 | I10: ='2020 Eylül'!I10+'2020 Ekim'!I10+'2020 Kasım'!I10+'2020 Aralık'!I10+'2021 Ocak'!I10+'2021 Şubat'!I10+'2021 Mart'!I10+'2021 Nisan'!I10+'2021 Mayıs'!I10+'2021 Haziran'!I10+'2021 Temmuz'!I10+'2021 Ağustos'!I10+'2021 Eylül'!I10+'2021 Ekim'!I10+'2021 Kasım'!I10+'2021 Aralık'!I10 -> 0 | J10: ='2020 Eylül'!J10+'2020 Ekim'!J10+'2020 Kasım'!J10+'2020 Aralık'!J10+'2021 Ocak'!J10+'2021 Şubat'!J10+'2021 Mart'!J10+'2021 Nisan'!J10+'2021 Mayıs'!J10+'2021 Haziran'!J10+'2021 Temmuz'!J10+'2021 Ağustos'!J10+'2021 Eylül'!J10+'2021 Ekim'!J10+'2021 Kasım'!J10+'2021 Aralık'!J10 -> 0 | K10: ='2020 Eylül'!K10+'2020 Ekim'!K10+'2020 Kasım'!K10+'2020 Aralık'!K10+'2021 Ocak'!K10+'2021 Şubat'!K10+'2021 Mart'!K10+'2021 Nisan'!K10+'2021 Mayıs'!K10+'2021 Haziran'!K10+'2021 Temmuz'!K10+'2021 Ağustos'!K10+'2021 Eylül'!K10+'2021 Ekim'!K10+'2021 Kasım'!K10+'2021 Aralık'!K10 -> 0 | L10: ='2020 Eylül'!L10+'2020 Ekim'!L10+'2020 Kasım'!L10+'2020 Aralık'!L10+'2021 Ocak'!L10+'2021 Şubat'!L10+'2021 Mart'!L10+'2021 Nisan'!L10+'2021 Mayıs'!L10+'2021 Haziran'!L10+'2021 Temmuz'!L10+'2021 Ağustos'!L10+'2021 Eylül'!L10+'2021 Ekim'!L10+'2021 Kasım'!L10+'2021 Aralık'!L10 -> 0
